[2025-03-31 13:07:07] [INFO] [logger:65] - Modelo cargado correctamente desde: C:\Users\nicol\Documentos\GitHub\PdM-Manager\Modelo\modeloRNN_multiclase_v3_finetuned.h5
[2025-03-31 13:07:07] [INFO] [logger:65] - Escalador cargado correctamente con joblib desde: C:\Users\nicol\Documentos\GitHub\PdM-Manager\Scaler\scaler_RNN_joblib.pkl
[2025-03-31 13:07:07] [INFO] [logger:65] - Límites de vibración ya existentes en la base de datos
[2025-03-31 13:07:07] [INFO] [logger:65] - Valores actuales X: -2.36/2.18/-3.5/3.32
[2025-03-31 13:07:07] [INFO] [logger:65] - Valores actuales Y: 7.18/12.09/5.95/13.32
[2025-03-31 13:07:07] [INFO] [logger:65] - Valores actuales Z: -2.39/1.11/-3.26/1.98
[2025-03-31 13:07:07] [INFO] [logger:65] - Iniciando aplicación PdM-Manager API
[2025-03-31 13:07:11] [INFO] [logger:65] - Solicitud GET / desde 127.0.0.1
[2025-03-31 13:07:11] [INFO] [logger:65] - Respuesta 200 para GET / procesada en 0.0676s
[2025-03-31 13:07:11] [INFO] [logger:65] - Solicitud GET /static/css/style.css desde 127.0.0.1
[2025-03-31 13:07:11] [INFO] [logger:65] - Solicitud GET /static/js/utils.js desde 127.0.0.1
[2025-03-31 13:07:11] [INFO] [logger:65] - Respuesta 304 para GET /static/css/style.css procesada en 0.0050s
[2025-03-31 13:07:11] [INFO] [logger:65] - Respuesta 304 para GET /static/js/utils.js procesada en 0.0050s
[2025-03-31 13:07:11] [INFO] [logger:65] - Solicitud GET /static/js/navigation.js desde 127.0.0.1
[2025-03-31 13:07:11] [INFO] [logger:65] - Solicitud GET /static/js/realtime-updates.js desde 127.0.0.1
[2025-03-31 13:07:11] [INFO] [logger:65] - Solicitud GET /static/js/dashboard.js desde 127.0.0.1
[2025-03-31 13:07:11] [INFO] [logger:65] - Solicitud GET /static/js/charts.js desde 127.0.0.1
[2025-03-31 13:07:11] [INFO] [logger:65] - Solicitud GET /static/js/config.js desde 127.0.0.1
[2025-03-31 13:07:11] [INFO] [logger:65] - Solicitud GET /static/js/app.js desde 127.0.0.1
[2025-03-31 13:07:11] [INFO] [logger:65] - Respuesta 304 para GET /static/js/navigation.js procesada en 0.0120s
[2025-03-31 13:07:11] [INFO] [logger:65] - Respuesta 304 para GET /static/js/realtime-updates.js procesada en 0.0120s
[2025-03-31 13:07:11] [INFO] [logger:65] - Respuesta 304 para GET /static/js/charts.js procesada en 0.0090s
[2025-03-31 13:07:11] [INFO] [logger:65] - Respuesta 304 para GET /static/js/dashboard.js procesada en 0.0110s
[2025-03-31 13:07:11] [INFO] [logger:65] - Respuesta 304 para GET /static/js/config.js procesada en 0.0100s
[2025-03-31 13:07:11] [INFO] [logger:65] - Respuesta 304 para GET /static/js/app.js procesada en 0.0100s
[2025-03-31 13:07:11] [INFO] [logger:65] - Solicitud GET /api/config/limits desde 127.0.0.1
[2025-03-31 13:07:11] [INFO] [logger:65] - Respuesta 404 para GET /api/config/limits procesada en 0.0010s
[2025-03-31 13:07:11] [INFO] [logger:65] - Solicitud GET /static/favicon.ico desde 127.0.0.1
[2025-03-31 13:07:11] [INFO] [logger:65] - Respuesta 304 para GET /static/favicon.ico procesada en 0.0020s
[2025-03-31 13:07:17] [INFO] [logger:65] - Solicitud GET /api/sensors desde 127.0.0.1
[2025-03-31 13:07:17] [INFO] [logger:65] - Solicitud GET /api/config/limits desde 127.0.0.1
[2025-03-31 13:07:17] [INFO] [logger:65] - Solicitud GET /api/models desde 127.0.0.1
[2025-03-31 13:07:17] [INFO] [logger:65] - Obteniendo lista de sensores: skip=0, limit=100
[2025-03-31 13:07:17] [INFO] [logger:65] - Respuesta 404 para GET /api/config/limits procesada en 0.0030s
[2025-03-31 13:07:17] [INFO] [logger:65] - Respuesta 200 para GET /api/sensors procesada en 0.0100s
[2025-03-31 13:07:17] [INFO] [logger:65] - Solicitud GET /api/sensors desde 127.0.0.1
[2025-03-31 13:07:17] [INFO] [logger:65] - Obteniendo lista de sensores: skip=0, limit=100
[2025-03-31 13:07:17] [INFO] [logger:65] - Respuesta 200 para GET /api/sensors procesada en 0.0060s
[2025-03-31 13:07:17] [INFO] [logger:65] - Respuesta 200 para GET /api/models procesada en 0.0638s
[2025-03-31 13:07:17] [INFO] [logger:65] - Solicitud GET /api/models desde 127.0.0.1
[2025-03-31 13:07:17] [INFO] [logger:65] - Solicitud GET /api/sensors desde 127.0.0.1
[2025-03-31 13:07:17] [INFO] [logger:65] - Obteniendo lista de sensores: skip=0, limit=100
[2025-03-31 13:07:17] [INFO] [logger:65] - Respuesta 200 para GET /api/models procesada en 0.0060s
[2025-03-31 13:07:17] [INFO] [logger:65] - Respuesta 200 para GET /api/sensors procesada en 0.0070s
[2025-03-31 13:07:17] [INFO] [logger:65] - Solicitud GET /api/models desde 127.0.0.1
[2025-03-31 13:07:17] [INFO] [logger:65] - Respuesta 200 para GET /api/models procesada en 0.0021s
[2025-03-31 13:07:36] [INFO] [logger:65] - Solicitud POST /api/models desde 127.0.0.1
[2025-03-31 13:07:36] [INFO] [logger:65] - Respuesta 200 para POST /api/models procesada en 0.0197s
[2025-03-31 13:07:36] [INFO] [logger:65] - Solicitud GET /api/models desde 127.0.0.1
[2025-03-31 13:07:36] [INFO] [logger:65] - Respuesta 200 para GET /api/models procesada en 0.0020s
[2025-03-31 13:07:46] [INFO] [logger:65] - Solicitud POST /api/sensors desde 127.0.0.1
[2025-03-31 13:07:46] [INFO] [logger:65] - Respuesta 200 para POST /api/sensors procesada en 0.0100s
[2025-03-31 13:07:46] [INFO] [logger:65] - Solicitud GET /api/sensors desde 127.0.0.1
[2025-03-31 13:07:46] [INFO] [logger:65] - Solicitud GET /api/models desde 127.0.0.1
[2025-03-31 13:07:46] [INFO] [logger:65] - Obteniendo lista de sensores: skip=0, limit=100
[2025-03-31 13:07:46] [INFO] [logger:65] - Respuesta 200 para GET /api/models procesada en 0.0030s
[2025-03-31 13:07:46] [INFO] [logger:65] - Respuesta 200 para GET /api/sensors procesada en 0.0070s
[2025-03-31 13:07:46] [INFO] [logger:65] - Solicitud GET /api/sensors desde 127.0.0.1
[2025-03-31 13:07:46] [INFO] [logger:65] - Obteniendo lista de sensores: skip=0, limit=100
[2025-03-31 13:07:46] [INFO] [logger:65] - Respuesta 200 para GET /api/sensors procesada en 0.0040s
[2025-03-31 16:22:33] [INFO] [logger:65] - Modelo cargado correctamente desde: C:\Users\LENOVO\Desktop\PdM-Manager\Modelo\modeloRNN_multiclase_v3_finetuned.h5
[2025-03-31 16:22:33] [INFO] [logger:65] - Escalador cargado correctamente con joblib desde: C:\Users\LENOVO\Desktop\PdM-Manager\Scaler\scaler_RNN_joblib.pkl
[2025-03-31 16:22:34] [INFO] [logger:65] - Límites de vibración ya existentes en la base de datos
[2025-03-31 16:22:34] [INFO] [logger:65] - Valores actuales X: -2.36/2.18/-3.5/3.32
[2025-03-31 16:22:34] [INFO] [logger:65] - Valores actuales Y: 7.18/12.09/5.95/13.32
[2025-03-31 16:22:34] [INFO] [logger:65] - Valores actuales Z: -2.39/1.11/-3.26/1.98
[2025-03-31 16:22:34] [INFO] [logger:65] - Iniciando aplicación PdM-Manager API
[2025-03-31 16:22:34] [INFO] [logger:65] - Solicitud GET /static/css/style.css desde 127.0.0.1
[2025-03-31 16:22:34] [INFO] [logger:65] - Respuesta 200 para GET /static/css/style.css procesada en 0.0570s
[2025-03-31 16:22:34] [INFO] [logger:65] - Solicitud GET /static/js/realtime-updates.js desde 127.0.0.1
[2025-03-31 16:22:34] [INFO] [logger:65] - Respuesta 200 para GET /static/js/realtime-updates.js procesada en 0.0024s
[2025-03-31 16:22:34] [INFO] [logger:65] - Solicitud GET /static/js/dashboard.js desde 127.0.0.1
[2025-03-31 16:22:34] [INFO] [logger:65] - Respuesta 200 para GET /static/js/dashboard.js procesada en 0.0032s
[2025-03-31 16:22:34] [INFO] [logger:65] - Solicitud GET /static/js/config.js desde 127.0.0.1
[2025-03-31 16:22:34] [INFO] [logger:65] - Respuesta 200 para GET /static/js/config.js procesada en 0.0013s
[2025-03-31 16:22:34] [INFO] [logger:65] - Solicitud GET /api/config/limits desde 127.0.0.1
[2025-03-31 16:22:34] [INFO] [logger:65] - Respuesta 404 para GET /api/config/limits procesada en 0.0020s
[2025-03-31 16:22:39] [INFO] [logger:65] - Solicitud GET /api/sensors desde 127.0.0.1
[2025-03-31 16:22:39] [INFO] [logger:65] - Solicitud GET /api/models desde 127.0.0.1
[2025-03-31 16:22:39] [INFO] [logger:65] - Solicitud GET /api/config/limits desde 127.0.0.1
[2025-03-31 16:22:39] [INFO] [logger:65] - Respuesta 404 para GET /api/config/limits procesada en 0.0015s
[2025-03-31 16:22:39] [INFO] [logger:65] - Obteniendo lista de sensores: skip=0, limit=100
[2025-03-31 16:22:39] [INFO] [logger:65] - Respuesta 200 para GET /api/models procesada en 0.0088s
[2025-03-31 16:22:39] [INFO] [logger:65] - Solicitud GET /api/models desde 127.0.0.1
[2025-03-31 16:22:39] [INFO] [logger:65] - Respuesta 200 para GET /api/models procesada en 0.0044s
[2025-03-31 16:22:39] [INFO] [logger:65] - Solicitud GET /api/models desde 127.0.0.1
[2025-03-31 16:22:39] [INFO] [logger:65] - Respuesta 200 para GET /api/models procesada en 0.0044s
[2025-03-31 16:22:39] [INFO] [logger:65] - Respuesta 200 para GET /api/sensors procesada en 0.0687s
[2025-03-31 16:22:39] [INFO] [logger:65] - Solicitud GET /api/sensors desde 127.0.0.1
[2025-03-31 16:22:39] [INFO] [logger:65] - Obteniendo lista de sensores: skip=0, limit=100
[2025-03-31 16:22:39] [INFO] [logger:65] - Respuesta 200 para GET /api/sensors procesada en 0.0040s
[2025-03-31 16:22:39] [INFO] [logger:65] - Solicitud GET /api/sensors desde 127.0.0.1
[2025-03-31 16:22:39] [INFO] [logger:65] - Obteniendo lista de sensores: skip=0, limit=100
[2025-03-31 16:22:39] [INFO] [logger:65] - Respuesta 200 para GET /api/sensors procesada en 0.0030s
[2025-03-31 16:37:32] [INFO] [logger:65] - Solicitud GET / desde 127.0.0.1
[2025-03-31 16:37:32] [INFO] [logger:65] - Respuesta 200 para GET / procesada en 0.0023s
[2025-03-31 16:37:32] [INFO] [logger:65] - Solicitud GET /static/css/style.css desde 127.0.0.1
[2025-03-31 16:37:32] [INFO] [logger:65] - Respuesta 304 para GET /static/css/style.css procesada en 0.0030s
[2025-03-31 16:37:33] [INFO] [logger:65] - Solicitud GET /static/js/utils.js desde 127.0.0.1
[2025-03-31 16:37:33] [INFO] [logger:65] - Solicitud GET /static/js/app-logger.js desde 127.0.0.1
[2025-03-31 16:37:33] [INFO] [logger:65] - Respuesta 304 para GET /static/js/utils.js procesada en 0.0061s
[2025-03-31 16:37:33] [INFO] [logger:65] - Solicitud GET /static/js/realtime-updates.js desde 127.0.0.1
[2025-03-31 16:37:33] [INFO] [logger:65] - Solicitud GET /static/js/navigation.js desde 127.0.0.1
[2025-03-31 16:37:33] [INFO] [logger:65] - Solicitud GET /static/js/dashboard.js desde 127.0.0.1
[2025-03-31 16:37:33] [INFO] [logger:65] - Solicitud GET /static/js/config.js desde 127.0.0.1
[2025-03-31 16:37:33] [INFO] [logger:65] - Respuesta 304 para GET /static/js/app-logger.js procesada en 0.0089s
[2025-03-31 16:37:33] [INFO] [logger:65] - Solicitud GET /static/js/logs-ui.js desde 127.0.0.1
[2025-03-31 16:37:33] [INFO] [logger:65] - Respuesta 200 para GET /static/js/realtime-updates.js procesada en 0.0127s
[2025-03-31 16:37:33] [INFO] [logger:65] - Respuesta 304 para GET /static/js/navigation.js procesada en 0.0138s
[2025-03-31 16:37:33] [INFO] [logger:65] - Respuesta 304 para GET /static/js/dashboard.js procesada en 0.0125s
[2025-03-31 16:37:33] [INFO] [logger:65] - Solicitud GET /static/js/charts.js desde 127.0.0.1
[2025-03-31 16:37:33] [INFO] [logger:65] - Respuesta 200 para GET /static/js/config.js procesada en 0.0158s
[2025-03-31 16:37:33] [INFO] [logger:65] - Respuesta 304 para GET /static/js/logs-ui.js procesada en 0.0133s
[2025-03-31 16:37:33] [INFO] [logger:65] - Solicitud GET /static/js/app.js desde 127.0.0.1
[2025-03-31 16:37:33] [INFO] [logger:65] - Respuesta 304 para GET /static/js/charts.js procesada en 0.0120s
[2025-03-31 16:37:33] [INFO] [logger:65] - Respuesta 200 para GET /static/js/app.js procesada en 0.0065s
[2025-03-31 16:37:35] [INFO] [logger:65] - Solicitud GET /api/sensors desde 127.0.0.1
[2025-03-31 16:37:35] [INFO] [logger:65] - Solicitud GET /api/models desde 127.0.0.1
[2025-03-31 16:37:35] [INFO] [logger:65] - Solicitud GET /api/config/limits desde 127.0.0.1
[2025-03-31 16:37:35] [INFO] [logger:65] - Obteniendo lista de sensores: skip=0, limit=100
[2025-03-31 16:37:35] [INFO] [logger:65] - Respuesta 404 para GET /api/config/limits procesada en 0.0016s
[2025-03-31 16:37:35] [INFO] [logger:65] - Respuesta 200 para GET /api/models procesada en 0.0049s
[2025-03-31 16:37:35] [INFO] [logger:65] - Respuesta 200 para GET /api/sensors procesada en 0.0069s
[2025-03-31 16:37:35] [INFO] [logger:65] - Solicitud GET /api/models desde 127.0.0.1
[2025-03-31 16:37:35] [INFO] [logger:65] - Solicitud GET /api/sensors desde 127.0.0.1
[2025-03-31 16:37:35] [INFO] [logger:65] - Respuesta 200 para GET /api/models procesada en 0.0055s
[2025-03-31 16:37:35] [INFO] [logger:65] - Obteniendo lista de sensores: skip=0, limit=100
[2025-03-31 16:37:35] [INFO] [logger:65] - Solicitud GET /api/models desde 127.0.0.1
[2025-03-31 16:37:35] [INFO] [logger:65] - Respuesta 200 para GET /api/sensors procesada en 0.0068s
[2025-03-31 16:37:35] [INFO] [logger:65] - Solicitud GET /api/machines desde 127.0.0.1
[2025-03-31 16:37:35] [INFO] [logger:65] - Solicitud GET /api/sensors desde 127.0.0.1
[2025-03-31 16:37:35] [INFO] [logger:65] - Respuesta 200 para GET /api/models procesada en 0.0060s
[2025-03-31 16:37:35] [INFO] [logger:65] - Obteniendo lista de sensores: skip=0, limit=100
[2025-03-31 16:37:35] [INFO] [logger:65] - Respuesta 200 para GET /api/machines procesada en 0.0093s
[2025-03-31 16:37:36] [INFO] [logger:65] - Respuesta 200 para GET /api/sensors procesada en 0.0645s
[2025-03-31 16:37:50] [INFO] [logger:65] - Solicitud POST /api/sensors desde 127.0.0.1
[2025-03-31 16:37:50] [INFO] [logger:65] - Respuesta 200 para POST /api/sensors procesada en 0.0183s
[2025-03-31 16:37:50] [INFO] [logger:65] - Solicitud GET /api/sensors desde 127.0.0.1
[2025-03-31 16:37:50] [INFO] [logger:65] - Solicitud GET /api/models desde 127.0.0.1
[2025-03-31 16:37:50] [INFO] [logger:65] - Obteniendo lista de sensores: skip=0, limit=100
[2025-03-31 16:37:50] [INFO] [logger:65] - Respuesta 200 para GET /api/sensors procesada en 0.0052s
[2025-03-31 16:37:50] [INFO] [logger:65] - Respuesta 200 para GET /api/models procesada en 0.0062s
[2025-03-31 16:37:50] [INFO] [logger:65] - Solicitud GET /api/sensors desde 127.0.0.1
[2025-03-31 16:37:50] [INFO] [logger:65] - Obteniendo lista de sensores: skip=0, limit=100
[2025-03-31 16:37:50] [INFO] [logger:65] - Respuesta 200 para GET /api/sensors procesada en 0.0032s
[2025-03-31 16:38:36] [INFO] [logger:65] - Solicitud POST /api/machines desde 127.0.0.1
[2025-03-31 16:38:36] [ERROR] [logger:50] - ERROR: name 'Machine' is not defined
CONTEXTO: Error al crear máquina
TRACEBACK: Traceback (most recent call last):
  File "C:\Users\LENOVO\Desktop\PdM-Manager\app\main.py", line 1922, in create_machine_endpoint
    machine = Machine(
              ^^^^^^^
NameError: name 'Machine' is not defined

[2025-03-31 16:38:36] [ERROR] [logger:50] - ERROR: 
CONTEXTO: {'endpoint': '/api/machines', 'método': 'POST'}
TRACEBACK: Traceback (most recent call last):
  File "C:\Users\LENOVO\Desktop\PdM-Manager\app\main.py", line 1922, in create_machine_endpoint
    machine = Machine(
              ^^^^^^^
NameError: name 'Machine' is not defined

During handling of the above exception, another exception occurred:

Traceback (most recent call last):
  File "C:\Users\LENOVO\Desktop\PdM-Manager\venv\Lib\site-packages\starlette\middleware\exceptions.py", line 68, in __call__
    await self.app(scope, receive, sender)
  File "C:\Users\LENOVO\Desktop\PdM-Manager\venv\Lib\site-packages\fastapi\middleware\asyncexitstack.py", line 20, in __call__
    raise e
  File "C:\Users\LENOVO\Desktop\PdM-Manager\venv\Lib\site-packages\fastapi\middleware\asyncexitstack.py", line 17, in __call__
    await self.app(scope, receive, send)
  File "C:\Users\LENOVO\Desktop\PdM-Manager\venv\Lib\site-packages\starlette\routing.py", line 718, in __call__
    await route.handle(scope, receive, send)
  File "C:\Users\LENOVO\Desktop\PdM-Manager\venv\Lib\site-packages\starlette\routing.py", line 276, in handle
    await self.app(scope, receive, send)
  File "C:\Users\LENOVO\Desktop\PdM-Manager\venv\Lib\site-packages\starlette\routing.py", line 66, in app
    response = await func(request)
               ^^^^^^^^^^^^^^^^^^^
  File "C:\Users\LENOVO\Desktop\PdM-Manager\venv\Lib\site-packages\fastapi\routing.py", line 274, in app
    raw_response = await run_endpoint_function(
                   ^^^^^^^^^^^^^^^^^^^^^^^^^^^^
  File "C:\Users\LENOVO\Desktop\PdM-Manager\venv\Lib\site-packages\fastapi\routing.py", line 191, in run_endpoint_function
    return await dependant.call(**values)
           ^^^^^^^^^^^^^^^^^^^^^^^^^^^^^^
  File "C:\Users\LENOVO\Desktop\PdM-Manager\app\main.py", line 1939, in create_machine_endpoint
    raise HTTPException(status_code=500, detail=str(e))
fastapi.exceptions.HTTPException

[2025-03-31 16:38:36] [INFO] [logger:65] - Respuesta 500 para POST /api/machines procesada en 0.0127s
[2025-03-31 16:38:51] [INFO] [logger:65] - Solicitud POST /api/machines desde 127.0.0.1
[2025-03-31 16:38:51] [ERROR] [logger:50] - ERROR: name 'Machine' is not defined
CONTEXTO: Error al crear máquina
TRACEBACK: Traceback (most recent call last):
  File "C:\Users\LENOVO\Desktop\PdM-Manager\app\main.py", line 1922, in create_machine_endpoint
    machine = Machine(
              ^^^^^^^
NameError: name 'Machine' is not defined

[2025-03-31 16:38:51] [ERROR] [logger:50] - ERROR: 
CONTEXTO: {'endpoint': '/api/machines', 'método': 'POST'}
TRACEBACK: Traceback (most recent call last):
  File "C:\Users\LENOVO\Desktop\PdM-Manager\app\main.py", line 1922, in create_machine_endpoint
    machine = Machine(
              ^^^^^^^
NameError: name 'Machine' is not defined

During handling of the above exception, another exception occurred:

Traceback (most recent call last):
  File "C:\Users\LENOVO\Desktop\PdM-Manager\venv\Lib\site-packages\starlette\middleware\exceptions.py", line 68, in __call__
    await self.app(scope, receive, sender)
  File "C:\Users\LENOVO\Desktop\PdM-Manager\venv\Lib\site-packages\fastapi\middleware\asyncexitstack.py", line 20, in __call__
    raise e
  File "C:\Users\LENOVO\Desktop\PdM-Manager\venv\Lib\site-packages\fastapi\middleware\asyncexitstack.py", line 17, in __call__
    await self.app(scope, receive, send)
  File "C:\Users\LENOVO\Desktop\PdM-Manager\venv\Lib\site-packages\starlette\routing.py", line 718, in __call__
    await route.handle(scope, receive, send)
  File "C:\Users\LENOVO\Desktop\PdM-Manager\venv\Lib\site-packages\starlette\routing.py", line 276, in handle
    await self.app(scope, receive, send)
  File "C:\Users\LENOVO\Desktop\PdM-Manager\venv\Lib\site-packages\starlette\routing.py", line 66, in app
    response = await func(request)
               ^^^^^^^^^^^^^^^^^^^
  File "C:\Users\LENOVO\Desktop\PdM-Manager\venv\Lib\site-packages\fastapi\routing.py", line 274, in app
    raw_response = await run_endpoint_function(
                   ^^^^^^^^^^^^^^^^^^^^^^^^^^^^
  File "C:\Users\LENOVO\Desktop\PdM-Manager\venv\Lib\site-packages\fastapi\routing.py", line 191, in run_endpoint_function
    return await dependant.call(**values)
           ^^^^^^^^^^^^^^^^^^^^^^^^^^^^^^
  File "C:\Users\LENOVO\Desktop\PdM-Manager\app\main.py", line 1939, in create_machine_endpoint
    raise HTTPException(status_code=500, detail=str(e))
fastapi.exceptions.HTTPException

[2025-03-31 16:38:51] [INFO] [logger:65] - Respuesta 500 para POST /api/machines procesada en 0.0101s
[2025-03-31 16:38:51] [INFO] [logger:65] - Solicitud POST /api/machines desde 127.0.0.1
[2025-03-31 16:38:51] [ERROR] [logger:50] - ERROR: name 'Machine' is not defined
CONTEXTO: Error al crear máquina
TRACEBACK: Traceback (most recent call last):
  File "C:\Users\LENOVO\Desktop\PdM-Manager\app\main.py", line 1922, in create_machine_endpoint
    machine = Machine(
              ^^^^^^^
NameError: name 'Machine' is not defined

[2025-03-31 16:38:51] [ERROR] [logger:50] - ERROR: 
CONTEXTO: {'endpoint': '/api/machines', 'método': 'POST'}
TRACEBACK: Traceback (most recent call last):
  File "C:\Users\LENOVO\Desktop\PdM-Manager\app\main.py", line 1922, in create_machine_endpoint
    machine = Machine(
              ^^^^^^^
NameError: name 'Machine' is not defined

During handling of the above exception, another exception occurred:

Traceback (most recent call last):
  File "C:\Users\LENOVO\Desktop\PdM-Manager\venv\Lib\site-packages\starlette\middleware\exceptions.py", line 68, in __call__
    await self.app(scope, receive, sender)
  File "C:\Users\LENOVO\Desktop\PdM-Manager\venv\Lib\site-packages\fastapi\middleware\asyncexitstack.py", line 20, in __call__
    raise e
  File "C:\Users\LENOVO\Desktop\PdM-Manager\venv\Lib\site-packages\fastapi\middleware\asyncexitstack.py", line 17, in __call__
    await self.app(scope, receive, send)
  File "C:\Users\LENOVO\Desktop\PdM-Manager\venv\Lib\site-packages\starlette\routing.py", line 718, in __call__
    await route.handle(scope, receive, send)
  File "C:\Users\LENOVO\Desktop\PdM-Manager\venv\Lib\site-packages\starlette\routing.py", line 276, in handle
    await self.app(scope, receive, send)
  File "C:\Users\LENOVO\Desktop\PdM-Manager\venv\Lib\site-packages\starlette\routing.py", line 66, in app
    response = await func(request)
               ^^^^^^^^^^^^^^^^^^^
  File "C:\Users\LENOVO\Desktop\PdM-Manager\venv\Lib\site-packages\fastapi\routing.py", line 274, in app
    raw_response = await run_endpoint_function(
                   ^^^^^^^^^^^^^^^^^^^^^^^^^^^^
  File "C:\Users\LENOVO\Desktop\PdM-Manager\venv\Lib\site-packages\fastapi\routing.py", line 191, in run_endpoint_function
    return await dependant.call(**values)
           ^^^^^^^^^^^^^^^^^^^^^^^^^^^^^^
  File "C:\Users\LENOVO\Desktop\PdM-Manager\app\main.py", line 1939, in create_machine_endpoint
    raise HTTPException(status_code=500, detail=str(e))
fastapi.exceptions.HTTPException

[2025-03-31 16:38:51] [INFO] [logger:65] - Respuesta 500 para POST /api/machines procesada en 0.0081s
[2025-03-31 16:38:51] [INFO] [logger:65] - Solicitud POST /api/machines desde 127.0.0.1
[2025-03-31 16:38:51] [ERROR] [logger:50] - ERROR: name 'Machine' is not defined
CONTEXTO: Error al crear máquina
TRACEBACK: Traceback (most recent call last):
  File "C:\Users\LENOVO\Desktop\PdM-Manager\app\main.py", line 1922, in create_machine_endpoint
    machine = Machine(
              ^^^^^^^
NameError: name 'Machine' is not defined

[2025-03-31 16:38:51] [ERROR] [logger:50] - ERROR: 
CONTEXTO: {'endpoint': '/api/machines', 'método': 'POST'}
TRACEBACK: Traceback (most recent call last):
  File "C:\Users\LENOVO\Desktop\PdM-Manager\app\main.py", line 1922, in create_machine_endpoint
    machine = Machine(
              ^^^^^^^
NameError: name 'Machine' is not defined

During handling of the above exception, another exception occurred:

Traceback (most recent call last):
  File "C:\Users\LENOVO\Desktop\PdM-Manager\venv\Lib\site-packages\starlette\middleware\exceptions.py", line 68, in __call__
    await self.app(scope, receive, sender)
  File "C:\Users\LENOVO\Desktop\PdM-Manager\venv\Lib\site-packages\fastapi\middleware\asyncexitstack.py", line 20, in __call__
    raise e
  File "C:\Users\LENOVO\Desktop\PdM-Manager\venv\Lib\site-packages\fastapi\middleware\asyncexitstack.py", line 17, in __call__
    await self.app(scope, receive, send)
  File "C:\Users\LENOVO\Desktop\PdM-Manager\venv\Lib\site-packages\starlette\routing.py", line 718, in __call__
    await route.handle(scope, receive, send)
  File "C:\Users\LENOVO\Desktop\PdM-Manager\venv\Lib\site-packages\starlette\routing.py", line 276, in handle
    await self.app(scope, receive, send)
  File "C:\Users\LENOVO\Desktop\PdM-Manager\venv\Lib\site-packages\starlette\routing.py", line 66, in app
    response = await func(request)
               ^^^^^^^^^^^^^^^^^^^
  File "C:\Users\LENOVO\Desktop\PdM-Manager\venv\Lib\site-packages\fastapi\routing.py", line 274, in app
    raw_response = await run_endpoint_function(
                   ^^^^^^^^^^^^^^^^^^^^^^^^^^^^
  File "C:\Users\LENOVO\Desktop\PdM-Manager\venv\Lib\site-packages\fastapi\routing.py", line 191, in run_endpoint_function
    return await dependant.call(**values)
           ^^^^^^^^^^^^^^^^^^^^^^^^^^^^^^
  File "C:\Users\LENOVO\Desktop\PdM-Manager\app\main.py", line 1939, in create_machine_endpoint
    raise HTTPException(status_code=500, detail=str(e))
fastapi.exceptions.HTTPException

[2025-03-31 16:38:51] [INFO] [logger:65] - Respuesta 500 para POST /api/machines procesada en 0.0090s
[2025-03-31 16:38:51] [INFO] [logger:65] - Solicitud POST /api/machines desde 127.0.0.1
[2025-03-31 16:38:51] [ERROR] [logger:50] - ERROR: name 'Machine' is not defined
CONTEXTO: Error al crear máquina
TRACEBACK: Traceback (most recent call last):
  File "C:\Users\LENOVO\Desktop\PdM-Manager\app\main.py", line 1922, in create_machine_endpoint
    machine = Machine(
              ^^^^^^^
NameError: name 'Machine' is not defined

[2025-03-31 16:38:51] [ERROR] [logger:50] - ERROR: 
CONTEXTO: {'endpoint': '/api/machines', 'método': 'POST'}
TRACEBACK: Traceback (most recent call last):
  File "C:\Users\LENOVO\Desktop\PdM-Manager\app\main.py", line 1922, in create_machine_endpoint
    machine = Machine(
              ^^^^^^^
NameError: name 'Machine' is not defined

During handling of the above exception, another exception occurred:

Traceback (most recent call last):
  File "C:\Users\LENOVO\Desktop\PdM-Manager\venv\Lib\site-packages\starlette\middleware\exceptions.py", line 68, in __call__
    await self.app(scope, receive, sender)
  File "C:\Users\LENOVO\Desktop\PdM-Manager\venv\Lib\site-packages\fastapi\middleware\asyncexitstack.py", line 20, in __call__
    raise e
  File "C:\Users\LENOVO\Desktop\PdM-Manager\venv\Lib\site-packages\fastapi\middleware\asyncexitstack.py", line 17, in __call__
    await self.app(scope, receive, send)
  File "C:\Users\LENOVO\Desktop\PdM-Manager\venv\Lib\site-packages\starlette\routing.py", line 718, in __call__
    await route.handle(scope, receive, send)
  File "C:\Users\LENOVO\Desktop\PdM-Manager\venv\Lib\site-packages\starlette\routing.py", line 276, in handle
    await self.app(scope, receive, send)
  File "C:\Users\LENOVO\Desktop\PdM-Manager\venv\Lib\site-packages\starlette\routing.py", line 66, in app
    response = await func(request)
               ^^^^^^^^^^^^^^^^^^^
  File "C:\Users\LENOVO\Desktop\PdM-Manager\venv\Lib\site-packages\fastapi\routing.py", line 274, in app
    raw_response = await run_endpoint_function(
                   ^^^^^^^^^^^^^^^^^^^^^^^^^^^^
  File "C:\Users\LENOVO\Desktop\PdM-Manager\venv\Lib\site-packages\fastapi\routing.py", line 191, in run_endpoint_function
    return await dependant.call(**values)
           ^^^^^^^^^^^^^^^^^^^^^^^^^^^^^^
  File "C:\Users\LENOVO\Desktop\PdM-Manager\app\main.py", line 1939, in create_machine_endpoint
    raise HTTPException(status_code=500, detail=str(e))
fastapi.exceptions.HTTPException

[2025-03-31 16:38:51] [INFO] [logger:65] - Respuesta 500 para POST /api/machines procesada en 0.0076s
[2025-03-31 16:38:52] [INFO] [logger:65] - Solicitud POST /api/machines desde 127.0.0.1
[2025-03-31 16:38:52] [ERROR] [logger:50] - ERROR: name 'Machine' is not defined
CONTEXTO: Error al crear máquina
TRACEBACK: Traceback (most recent call last):
  File "C:\Users\LENOVO\Desktop\PdM-Manager\app\main.py", line 1922, in create_machine_endpoint
    machine = Machine(
              ^^^^^^^
NameError: name 'Machine' is not defined

[2025-03-31 16:38:52] [ERROR] [logger:50] - ERROR: 
CONTEXTO: {'endpoint': '/api/machines', 'método': 'POST'}
TRACEBACK: Traceback (most recent call last):
  File "C:\Users\LENOVO\Desktop\PdM-Manager\app\main.py", line 1922, in create_machine_endpoint
    machine = Machine(
              ^^^^^^^
NameError: name 'Machine' is not defined

During handling of the above exception, another exception occurred:

Traceback (most recent call last):
  File "C:\Users\LENOVO\Desktop\PdM-Manager\venv\Lib\site-packages\starlette\middleware\exceptions.py", line 68, in __call__
    await self.app(scope, receive, sender)
  File "C:\Users\LENOVO\Desktop\PdM-Manager\venv\Lib\site-packages\fastapi\middleware\asyncexitstack.py", line 20, in __call__
    raise e
  File "C:\Users\LENOVO\Desktop\PdM-Manager\venv\Lib\site-packages\fastapi\middleware\asyncexitstack.py", line 17, in __call__
    await self.app(scope, receive, send)
  File "C:\Users\LENOVO\Desktop\PdM-Manager\venv\Lib\site-packages\starlette\routing.py", line 718, in __call__
    await route.handle(scope, receive, send)
  File "C:\Users\LENOVO\Desktop\PdM-Manager\venv\Lib\site-packages\starlette\routing.py", line 276, in handle
    await self.app(scope, receive, send)
  File "C:\Users\LENOVO\Desktop\PdM-Manager\venv\Lib\site-packages\starlette\routing.py", line 66, in app
    response = await func(request)
               ^^^^^^^^^^^^^^^^^^^
  File "C:\Users\LENOVO\Desktop\PdM-Manager\venv\Lib\site-packages\fastapi\routing.py", line 274, in app
    raw_response = await run_endpoint_function(
                   ^^^^^^^^^^^^^^^^^^^^^^^^^^^^
  File "C:\Users\LENOVO\Desktop\PdM-Manager\venv\Lib\site-packages\fastapi\routing.py", line 191, in run_endpoint_function
    return await dependant.call(**values)
           ^^^^^^^^^^^^^^^^^^^^^^^^^^^^^^
  File "C:\Users\LENOVO\Desktop\PdM-Manager\app\main.py", line 1939, in create_machine_endpoint
    raise HTTPException(status_code=500, detail=str(e))
fastapi.exceptions.HTTPException

[2025-03-31 16:38:52] [INFO] [logger:65] - Respuesta 500 para POST /api/machines procesada en 0.0080s
[2025-03-31 16:38:52] [INFO] [logger:65] - Solicitud POST /api/machines desde 127.0.0.1
[2025-03-31 16:38:52] [ERROR] [logger:50] - ERROR: name 'Machine' is not defined
CONTEXTO: Error al crear máquina
TRACEBACK: Traceback (most recent call last):
  File "C:\Users\LENOVO\Desktop\PdM-Manager\app\main.py", line 1922, in create_machine_endpoint
    machine = Machine(
              ^^^^^^^
NameError: name 'Machine' is not defined

[2025-03-31 16:38:52] [ERROR] [logger:50] - ERROR: 
CONTEXTO: {'endpoint': '/api/machines', 'método': 'POST'}
TRACEBACK: Traceback (most recent call last):
  File "C:\Users\LENOVO\Desktop\PdM-Manager\app\main.py", line 1922, in create_machine_endpoint
    machine = Machine(
              ^^^^^^^
NameError: name 'Machine' is not defined

During handling of the above exception, another exception occurred:

Traceback (most recent call last):
  File "C:\Users\LENOVO\Desktop\PdM-Manager\venv\Lib\site-packages\starlette\middleware\exceptions.py", line 68, in __call__
    await self.app(scope, receive, sender)
  File "C:\Users\LENOVO\Desktop\PdM-Manager\venv\Lib\site-packages\fastapi\middleware\asyncexitstack.py", line 20, in __call__
    raise e
  File "C:\Users\LENOVO\Desktop\PdM-Manager\venv\Lib\site-packages\fastapi\middleware\asyncexitstack.py", line 17, in __call__
    await self.app(scope, receive, send)
  File "C:\Users\LENOVO\Desktop\PdM-Manager\venv\Lib\site-packages\starlette\routing.py", line 718, in __call__
    await route.handle(scope, receive, send)
  File "C:\Users\LENOVO\Desktop\PdM-Manager\venv\Lib\site-packages\starlette\routing.py", line 276, in handle
    await self.app(scope, receive, send)
  File "C:\Users\LENOVO\Desktop\PdM-Manager\venv\Lib\site-packages\starlette\routing.py", line 66, in app
    response = await func(request)
               ^^^^^^^^^^^^^^^^^^^
  File "C:\Users\LENOVO\Desktop\PdM-Manager\venv\Lib\site-packages\fastapi\routing.py", line 274, in app
    raw_response = await run_endpoint_function(
                   ^^^^^^^^^^^^^^^^^^^^^^^^^^^^
  File "C:\Users\LENOVO\Desktop\PdM-Manager\venv\Lib\site-packages\fastapi\routing.py", line 191, in run_endpoint_function
    return await dependant.call(**values)
           ^^^^^^^^^^^^^^^^^^^^^^^^^^^^^^
  File "C:\Users\LENOVO\Desktop\PdM-Manager\app\main.py", line 1939, in create_machine_endpoint
    raise HTTPException(status_code=500, detail=str(e))
fastapi.exceptions.HTTPException

[2025-03-31 16:38:52] [INFO] [logger:65] - Respuesta 500 para POST /api/machines procesada en 0.0083s
[2025-03-31 16:38:53] [INFO] [logger:65] - Solicitud POST /api/machines desde 127.0.0.1
[2025-03-31 16:38:53] [ERROR] [logger:50] - ERROR: name 'Machine' is not defined
CONTEXTO: Error al crear máquina
TRACEBACK: Traceback (most recent call last):
  File "C:\Users\LENOVO\Desktop\PdM-Manager\app\main.py", line 1922, in create_machine_endpoint
    machine = Machine(
              ^^^^^^^
NameError: name 'Machine' is not defined

[2025-03-31 16:38:53] [ERROR] [logger:50] - ERROR: 
CONTEXTO: {'endpoint': '/api/machines', 'método': 'POST'}
TRACEBACK: Traceback (most recent call last):
  File "C:\Users\LENOVO\Desktop\PdM-Manager\app\main.py", line 1922, in create_machine_endpoint
    machine = Machine(
              ^^^^^^^
NameError: name 'Machine' is not defined

During handling of the above exception, another exception occurred:

Traceback (most recent call last):
  File "C:\Users\LENOVO\Desktop\PdM-Manager\venv\Lib\site-packages\starlette\middleware\exceptions.py", line 68, in __call__
    await self.app(scope, receive, sender)
  File "C:\Users\LENOVO\Desktop\PdM-Manager\venv\Lib\site-packages\fastapi\middleware\asyncexitstack.py", line 20, in __call__
    raise e
  File "C:\Users\LENOVO\Desktop\PdM-Manager\venv\Lib\site-packages\fastapi\middleware\asyncexitstack.py", line 17, in __call__
    await self.app(scope, receive, send)
  File "C:\Users\LENOVO\Desktop\PdM-Manager\venv\Lib\site-packages\starlette\routing.py", line 718, in __call__
    await route.handle(scope, receive, send)
  File "C:\Users\LENOVO\Desktop\PdM-Manager\venv\Lib\site-packages\starlette\routing.py", line 276, in handle
    await self.app(scope, receive, send)
  File "C:\Users\LENOVO\Desktop\PdM-Manager\venv\Lib\site-packages\starlette\routing.py", line 66, in app
    response = await func(request)
               ^^^^^^^^^^^^^^^^^^^
  File "C:\Users\LENOVO\Desktop\PdM-Manager\venv\Lib\site-packages\fastapi\routing.py", line 274, in app
    raw_response = await run_endpoint_function(
                   ^^^^^^^^^^^^^^^^^^^^^^^^^^^^
  File "C:\Users\LENOVO\Desktop\PdM-Manager\venv\Lib\site-packages\fastapi\routing.py", line 191, in run_endpoint_function
    return await dependant.call(**values)
           ^^^^^^^^^^^^^^^^^^^^^^^^^^^^^^
  File "C:\Users\LENOVO\Desktop\PdM-Manager\app\main.py", line 1939, in create_machine_endpoint
    raise HTTPException(status_code=500, detail=str(e))
fastapi.exceptions.HTTPException

[2025-03-31 16:38:53] [INFO] [logger:65] - Respuesta 500 para POST /api/machines procesada en 0.0082s
[2025-03-31 16:38:53] [INFO] [logger:65] - Solicitud POST /api/machines desde 127.0.0.1
[2025-03-31 16:38:53] [ERROR] [logger:50] - ERROR: name 'Machine' is not defined
CONTEXTO: Error al crear máquina
TRACEBACK: Traceback (most recent call last):
  File "C:\Users\LENOVO\Desktop\PdM-Manager\app\main.py", line 1922, in create_machine_endpoint
    machine = Machine(
              ^^^^^^^
NameError: name 'Machine' is not defined

[2025-03-31 16:38:53] [ERROR] [logger:50] - ERROR: 
CONTEXTO: {'endpoint': '/api/machines', 'método': 'POST'}
TRACEBACK: Traceback (most recent call last):
  File "C:\Users\LENOVO\Desktop\PdM-Manager\app\main.py", line 1922, in create_machine_endpoint
    machine = Machine(
              ^^^^^^^
NameError: name 'Machine' is not defined

During handling of the above exception, another exception occurred:

Traceback (most recent call last):
  File "C:\Users\LENOVO\Desktop\PdM-Manager\venv\Lib\site-packages\starlette\middleware\exceptions.py", line 68, in __call__
    await self.app(scope, receive, sender)
  File "C:\Users\LENOVO\Desktop\PdM-Manager\venv\Lib\site-packages\fastapi\middleware\asyncexitstack.py", line 20, in __call__
    raise e
  File "C:\Users\LENOVO\Desktop\PdM-Manager\venv\Lib\site-packages\fastapi\middleware\asyncexitstack.py", line 17, in __call__
    await self.app(scope, receive, send)
  File "C:\Users\LENOVO\Desktop\PdM-Manager\venv\Lib\site-packages\starlette\routing.py", line 718, in __call__
    await route.handle(scope, receive, send)
  File "C:\Users\LENOVO\Desktop\PdM-Manager\venv\Lib\site-packages\starlette\routing.py", line 276, in handle
    await self.app(scope, receive, send)
  File "C:\Users\LENOVO\Desktop\PdM-Manager\venv\Lib\site-packages\starlette\routing.py", line 66, in app
    response = await func(request)
               ^^^^^^^^^^^^^^^^^^^
  File "C:\Users\LENOVO\Desktop\PdM-Manager\venv\Lib\site-packages\fastapi\routing.py", line 274, in app
    raw_response = await run_endpoint_function(
                   ^^^^^^^^^^^^^^^^^^^^^^^^^^^^
  File "C:\Users\LENOVO\Desktop\PdM-Manager\venv\Lib\site-packages\fastapi\routing.py", line 191, in run_endpoint_function
    return await dependant.call(**values)
           ^^^^^^^^^^^^^^^^^^^^^^^^^^^^^^
  File "C:\Users\LENOVO\Desktop\PdM-Manager\app\main.py", line 1939, in create_machine_endpoint
    raise HTTPException(status_code=500, detail=str(e))
fastapi.exceptions.HTTPException

[2025-03-31 16:38:53] [INFO] [logger:65] - Respuesta 500 para POST /api/machines procesada en 0.0104s
[2025-03-31 16:38:53] [INFO] [logger:65] - Solicitud POST /api/machines desde 127.0.0.1
[2025-03-31 16:38:53] [ERROR] [logger:50] - ERROR: name 'Machine' is not defined
CONTEXTO: Error al crear máquina
TRACEBACK: Traceback (most recent call last):
  File "C:\Users\LENOVO\Desktop\PdM-Manager\app\main.py", line 1922, in create_machine_endpoint
    machine = Machine(
              ^^^^^^^
NameError: name 'Machine' is not defined

[2025-03-31 16:38:53] [ERROR] [logger:50] - ERROR: 
CONTEXTO: {'endpoint': '/api/machines', 'método': 'POST'}
TRACEBACK: Traceback (most recent call last):
  File "C:\Users\LENOVO\Desktop\PdM-Manager\app\main.py", line 1922, in create_machine_endpoint
    machine = Machine(
              ^^^^^^^
NameError: name 'Machine' is not defined

During handling of the above exception, another exception occurred:

Traceback (most recent call last):
  File "C:\Users\LENOVO\Desktop\PdM-Manager\venv\Lib\site-packages\starlette\middleware\exceptions.py", line 68, in __call__
    await self.app(scope, receive, sender)
  File "C:\Users\LENOVO\Desktop\PdM-Manager\venv\Lib\site-packages\fastapi\middleware\asyncexitstack.py", line 20, in __call__
    raise e
  File "C:\Users\LENOVO\Desktop\PdM-Manager\venv\Lib\site-packages\fastapi\middleware\asyncexitstack.py", line 17, in __call__
    await self.app(scope, receive, send)
  File "C:\Users\LENOVO\Desktop\PdM-Manager\venv\Lib\site-packages\starlette\routing.py", line 718, in __call__
    await route.handle(scope, receive, send)
  File "C:\Users\LENOVO\Desktop\PdM-Manager\venv\Lib\site-packages\starlette\routing.py", line 276, in handle
    await self.app(scope, receive, send)
  File "C:\Users\LENOVO\Desktop\PdM-Manager\venv\Lib\site-packages\starlette\routing.py", line 66, in app
    response = await func(request)
               ^^^^^^^^^^^^^^^^^^^
  File "C:\Users\LENOVO\Desktop\PdM-Manager\venv\Lib\site-packages\fastapi\routing.py", line 274, in app
    raw_response = await run_endpoint_function(
                   ^^^^^^^^^^^^^^^^^^^^^^^^^^^^
  File "C:\Users\LENOVO\Desktop\PdM-Manager\venv\Lib\site-packages\fastapi\routing.py", line 191, in run_endpoint_function
    return await dependant.call(**values)
           ^^^^^^^^^^^^^^^^^^^^^^^^^^^^^^
  File "C:\Users\LENOVO\Desktop\PdM-Manager\app\main.py", line 1939, in create_machine_endpoint
    raise HTTPException(status_code=500, detail=str(e))
fastapi.exceptions.HTTPException

[2025-03-31 16:38:53] [INFO] [logger:65] - Respuesta 500 para POST /api/machines procesada en 0.0083s
[2025-03-31 16:38:53] [INFO] [logger:65] - Solicitud POST /api/machines desde 127.0.0.1
[2025-03-31 16:38:53] [ERROR] [logger:50] - ERROR: name 'Machine' is not defined
CONTEXTO: Error al crear máquina
TRACEBACK: Traceback (most recent call last):
  File "C:\Users\LENOVO\Desktop\PdM-Manager\app\main.py", line 1922, in create_machine_endpoint
    machine = Machine(
              ^^^^^^^
NameError: name 'Machine' is not defined

[2025-03-31 16:38:53] [ERROR] [logger:50] - ERROR: 
CONTEXTO: {'endpoint': '/api/machines', 'método': 'POST'}
TRACEBACK: Traceback (most recent call last):
  File "C:\Users\LENOVO\Desktop\PdM-Manager\app\main.py", line 1922, in create_machine_endpoint
    machine = Machine(
              ^^^^^^^
NameError: name 'Machine' is not defined

During handling of the above exception, another exception occurred:

Traceback (most recent call last):
  File "C:\Users\LENOVO\Desktop\PdM-Manager\venv\Lib\site-packages\starlette\middleware\exceptions.py", line 68, in __call__
    await self.app(scope, receive, sender)
  File "C:\Users\LENOVO\Desktop\PdM-Manager\venv\Lib\site-packages\fastapi\middleware\asyncexitstack.py", line 20, in __call__
    raise e
  File "C:\Users\LENOVO\Desktop\PdM-Manager\venv\Lib\site-packages\fastapi\middleware\asyncexitstack.py", line 17, in __call__
    await self.app(scope, receive, send)
  File "C:\Users\LENOVO\Desktop\PdM-Manager\venv\Lib\site-packages\starlette\routing.py", line 718, in __call__
    await route.handle(scope, receive, send)
  File "C:\Users\LENOVO\Desktop\PdM-Manager\venv\Lib\site-packages\starlette\routing.py", line 276, in handle
    await self.app(scope, receive, send)
  File "C:\Users\LENOVO\Desktop\PdM-Manager\venv\Lib\site-packages\starlette\routing.py", line 66, in app
    response = await func(request)
               ^^^^^^^^^^^^^^^^^^^
  File "C:\Users\LENOVO\Desktop\PdM-Manager\venv\Lib\site-packages\fastapi\routing.py", line 274, in app
    raw_response = await run_endpoint_function(
                   ^^^^^^^^^^^^^^^^^^^^^^^^^^^^
  File "C:\Users\LENOVO\Desktop\PdM-Manager\venv\Lib\site-packages\fastapi\routing.py", line 191, in run_endpoint_function
    return await dependant.call(**values)
           ^^^^^^^^^^^^^^^^^^^^^^^^^^^^^^
  File "C:\Users\LENOVO\Desktop\PdM-Manager\app\main.py", line 1939, in create_machine_endpoint
    raise HTTPException(status_code=500, detail=str(e))
fastapi.exceptions.HTTPException

[2025-03-31 16:38:53] [INFO] [logger:65] - Respuesta 500 para POST /api/machines procesada en 0.0104s
[2025-03-31 16:38:53] [INFO] [logger:65] - Solicitud POST /api/machines desde 127.0.0.1
[2025-03-31 16:38:53] [ERROR] [logger:50] - ERROR: name 'Machine' is not defined
CONTEXTO: Error al crear máquina
TRACEBACK: Traceback (most recent call last):
  File "C:\Users\LENOVO\Desktop\PdM-Manager\app\main.py", line 1922, in create_machine_endpoint
    machine = Machine(
              ^^^^^^^
NameError: name 'Machine' is not defined

[2025-03-31 16:38:53] [ERROR] [logger:50] - ERROR: 
CONTEXTO: {'endpoint': '/api/machines', 'método': 'POST'}
TRACEBACK: Traceback (most recent call last):
  File "C:\Users\LENOVO\Desktop\PdM-Manager\app\main.py", line 1922, in create_machine_endpoint
    machine = Machine(
              ^^^^^^^
NameError: name 'Machine' is not defined

During handling of the above exception, another exception occurred:

Traceback (most recent call last):
  File "C:\Users\LENOVO\Desktop\PdM-Manager\venv\Lib\site-packages\starlette\middleware\exceptions.py", line 68, in __call__
    await self.app(scope, receive, sender)
  File "C:\Users\LENOVO\Desktop\PdM-Manager\venv\Lib\site-packages\fastapi\middleware\asyncexitstack.py", line 20, in __call__
    raise e
  File "C:\Users\LENOVO\Desktop\PdM-Manager\venv\Lib\site-packages\fastapi\middleware\asyncexitstack.py", line 17, in __call__
    await self.app(scope, receive, send)
  File "C:\Users\LENOVO\Desktop\PdM-Manager\venv\Lib\site-packages\starlette\routing.py", line 718, in __call__
    await route.handle(scope, receive, send)
  File "C:\Users\LENOVO\Desktop\PdM-Manager\venv\Lib\site-packages\starlette\routing.py", line 276, in handle
    await self.app(scope, receive, send)
  File "C:\Users\LENOVO\Desktop\PdM-Manager\venv\Lib\site-packages\starlette\routing.py", line 66, in app
    response = await func(request)
               ^^^^^^^^^^^^^^^^^^^
  File "C:\Users\LENOVO\Desktop\PdM-Manager\venv\Lib\site-packages\fastapi\routing.py", line 274, in app
    raw_response = await run_endpoint_function(
                   ^^^^^^^^^^^^^^^^^^^^^^^^^^^^
  File "C:\Users\LENOVO\Desktop\PdM-Manager\venv\Lib\site-packages\fastapi\routing.py", line 191, in run_endpoint_function
    return await dependant.call(**values)
           ^^^^^^^^^^^^^^^^^^^^^^^^^^^^^^
  File "C:\Users\LENOVO\Desktop\PdM-Manager\app\main.py", line 1939, in create_machine_endpoint
    raise HTTPException(status_code=500, detail=str(e))
fastapi.exceptions.HTTPException

[2025-03-31 16:38:53] [INFO] [logger:65] - Respuesta 500 para POST /api/machines procesada en 0.0057s
[2025-03-31 16:38:53] [INFO] [logger:65] - Solicitud POST /api/machines desde 127.0.0.1
[2025-03-31 16:38:53] [ERROR] [logger:50] - ERROR: name 'Machine' is not defined
CONTEXTO: Error al crear máquina
TRACEBACK: Traceback (most recent call last):
  File "C:\Users\LENOVO\Desktop\PdM-Manager\app\main.py", line 1922, in create_machine_endpoint
    machine = Machine(
              ^^^^^^^
NameError: name 'Machine' is not defined

[2025-03-31 16:38:53] [ERROR] [logger:50] - ERROR: 
CONTEXTO: {'endpoint': '/api/machines', 'método': 'POST'}
TRACEBACK: Traceback (most recent call last):
  File "C:\Users\LENOVO\Desktop\PdM-Manager\app\main.py", line 1922, in create_machine_endpoint
    machine = Machine(
              ^^^^^^^
NameError: name 'Machine' is not defined

During handling of the above exception, another exception occurred:

Traceback (most recent call last):
  File "C:\Users\LENOVO\Desktop\PdM-Manager\venv\Lib\site-packages\starlette\middleware\exceptions.py", line 68, in __call__
    await self.app(scope, receive, sender)
  File "C:\Users\LENOVO\Desktop\PdM-Manager\venv\Lib\site-packages\fastapi\middleware\asyncexitstack.py", line 20, in __call__
    raise e
  File "C:\Users\LENOVO\Desktop\PdM-Manager\venv\Lib\site-packages\fastapi\middleware\asyncexitstack.py", line 17, in __call__
    await self.app(scope, receive, send)
  File "C:\Users\LENOVO\Desktop\PdM-Manager\venv\Lib\site-packages\starlette\routing.py", line 718, in __call__
    await route.handle(scope, receive, send)
  File "C:\Users\LENOVO\Desktop\PdM-Manager\venv\Lib\site-packages\starlette\routing.py", line 276, in handle
    await self.app(scope, receive, send)
  File "C:\Users\LENOVO\Desktop\PdM-Manager\venv\Lib\site-packages\starlette\routing.py", line 66, in app
    response = await func(request)
               ^^^^^^^^^^^^^^^^^^^
  File "C:\Users\LENOVO\Desktop\PdM-Manager\venv\Lib\site-packages\fastapi\routing.py", line 274, in app
    raw_response = await run_endpoint_function(
                   ^^^^^^^^^^^^^^^^^^^^^^^^^^^^
  File "C:\Users\LENOVO\Desktop\PdM-Manager\venv\Lib\site-packages\fastapi\routing.py", line 191, in run_endpoint_function
    return await dependant.call(**values)
           ^^^^^^^^^^^^^^^^^^^^^^^^^^^^^^
  File "C:\Users\LENOVO\Desktop\PdM-Manager\app\main.py", line 1939, in create_machine_endpoint
    raise HTTPException(status_code=500, detail=str(e))
fastapi.exceptions.HTTPException

[2025-03-31 16:38:53] [INFO] [logger:65] - Respuesta 500 para POST /api/machines procesada en 0.0062s
[2025-03-31 16:38:54] [INFO] [logger:65] - Solicitud POST /api/machines desde 127.0.0.1
[2025-03-31 16:38:54] [ERROR] [logger:50] - ERROR: name 'Machine' is not defined
CONTEXTO: Error al crear máquina
TRACEBACK: Traceback (most recent call last):
  File "C:\Users\LENOVO\Desktop\PdM-Manager\app\main.py", line 1922, in create_machine_endpoint
    machine = Machine(
              ^^^^^^^
NameError: name 'Machine' is not defined

[2025-03-31 16:38:54] [ERROR] [logger:50] - ERROR: 
CONTEXTO: {'endpoint': '/api/machines', 'método': 'POST'}
TRACEBACK: Traceback (most recent call last):
  File "C:\Users\LENOVO\Desktop\PdM-Manager\app\main.py", line 1922, in create_machine_endpoint
    machine = Machine(
              ^^^^^^^
NameError: name 'Machine' is not defined

During handling of the above exception, another exception occurred:

Traceback (most recent call last):
  File "C:\Users\LENOVO\Desktop\PdM-Manager\venv\Lib\site-packages\starlette\middleware\exceptions.py", line 68, in __call__
    await self.app(scope, receive, sender)
  File "C:\Users\LENOVO\Desktop\PdM-Manager\venv\Lib\site-packages\fastapi\middleware\asyncexitstack.py", line 20, in __call__
    raise e
  File "C:\Users\LENOVO\Desktop\PdM-Manager\venv\Lib\site-packages\fastapi\middleware\asyncexitstack.py", line 17, in __call__
    await self.app(scope, receive, send)
  File "C:\Users\LENOVO\Desktop\PdM-Manager\venv\Lib\site-packages\starlette\routing.py", line 718, in __call__
    await route.handle(scope, receive, send)
  File "C:\Users\LENOVO\Desktop\PdM-Manager\venv\Lib\site-packages\starlette\routing.py", line 276, in handle
    await self.app(scope, receive, send)
  File "C:\Users\LENOVO\Desktop\PdM-Manager\venv\Lib\site-packages\starlette\routing.py", line 66, in app
    response = await func(request)
               ^^^^^^^^^^^^^^^^^^^
  File "C:\Users\LENOVO\Desktop\PdM-Manager\venv\Lib\site-packages\fastapi\routing.py", line 274, in app
    raw_response = await run_endpoint_function(
                   ^^^^^^^^^^^^^^^^^^^^^^^^^^^^
  File "C:\Users\LENOVO\Desktop\PdM-Manager\venv\Lib\site-packages\fastapi\routing.py", line 191, in run_endpoint_function
    return await dependant.call(**values)
           ^^^^^^^^^^^^^^^^^^^^^^^^^^^^^^
  File "C:\Users\LENOVO\Desktop\PdM-Manager\app\main.py", line 1939, in create_machine_endpoint
    raise HTTPException(status_code=500, detail=str(e))
fastapi.exceptions.HTTPException

[2025-03-31 16:38:54] [INFO] [logger:65] - Respuesta 500 para POST /api/machines procesada en 0.0094s
[2025-03-31 16:38:54] [INFO] [logger:65] - Solicitud POST /api/machines desde 127.0.0.1
[2025-03-31 16:38:54] [ERROR] [logger:50] - ERROR: name 'Machine' is not defined
CONTEXTO: Error al crear máquina
TRACEBACK: Traceback (most recent call last):
  File "C:\Users\LENOVO\Desktop\PdM-Manager\app\main.py", line 1922, in create_machine_endpoint
    machine = Machine(
              ^^^^^^^
NameError: name 'Machine' is not defined

[2025-03-31 16:38:54] [ERROR] [logger:50] - ERROR: 
CONTEXTO: {'endpoint': '/api/machines', 'método': 'POST'}
TRACEBACK: Traceback (most recent call last):
  File "C:\Users\LENOVO\Desktop\PdM-Manager\app\main.py", line 1922, in create_machine_endpoint
    machine = Machine(
              ^^^^^^^
NameError: name 'Machine' is not defined

During handling of the above exception, another exception occurred:

Traceback (most recent call last):
  File "C:\Users\LENOVO\Desktop\PdM-Manager\venv\Lib\site-packages\starlette\middleware\exceptions.py", line 68, in __call__
    await self.app(scope, receive, sender)
  File "C:\Users\LENOVO\Desktop\PdM-Manager\venv\Lib\site-packages\fastapi\middleware\asyncexitstack.py", line 20, in __call__
    raise e
  File "C:\Users\LENOVO\Desktop\PdM-Manager\venv\Lib\site-packages\fastapi\middleware\asyncexitstack.py", line 17, in __call__
    await self.app(scope, receive, send)
  File "C:\Users\LENOVO\Desktop\PdM-Manager\venv\Lib\site-packages\starlette\routing.py", line 718, in __call__
    await route.handle(scope, receive, send)
  File "C:\Users\LENOVO\Desktop\PdM-Manager\venv\Lib\site-packages\starlette\routing.py", line 276, in handle
    await self.app(scope, receive, send)
  File "C:\Users\LENOVO\Desktop\PdM-Manager\venv\Lib\site-packages\starlette\routing.py", line 66, in app
    response = await func(request)
               ^^^^^^^^^^^^^^^^^^^
  File "C:\Users\LENOVO\Desktop\PdM-Manager\venv\Lib\site-packages\fastapi\routing.py", line 274, in app
    raw_response = await run_endpoint_function(
                   ^^^^^^^^^^^^^^^^^^^^^^^^^^^^
  File "C:\Users\LENOVO\Desktop\PdM-Manager\venv\Lib\site-packages\fastapi\routing.py", line 191, in run_endpoint_function
    return await dependant.call(**values)
           ^^^^^^^^^^^^^^^^^^^^^^^^^^^^^^
  File "C:\Users\LENOVO\Desktop\PdM-Manager\app\main.py", line 1939, in create_machine_endpoint
    raise HTTPException(status_code=500, detail=str(e))
fastapi.exceptions.HTTPException

[2025-03-31 16:38:54] [INFO] [logger:65] - Respuesta 500 para POST /api/machines procesada en 0.0084s
[2025-03-31 16:38:54] [INFO] [logger:65] - Solicitud POST /api/machines desde 127.0.0.1
[2025-03-31 16:38:54] [ERROR] [logger:50] - ERROR: name 'Machine' is not defined
CONTEXTO: Error al crear máquina
TRACEBACK: Traceback (most recent call last):
  File "C:\Users\LENOVO\Desktop\PdM-Manager\app\main.py", line 1922, in create_machine_endpoint
    machine = Machine(
              ^^^^^^^
NameError: name 'Machine' is not defined

[2025-03-31 16:38:54] [ERROR] [logger:50] - ERROR: 
CONTEXTO: {'endpoint': '/api/machines', 'método': 'POST'}
TRACEBACK: Traceback (most recent call last):
  File "C:\Users\LENOVO\Desktop\PdM-Manager\app\main.py", line 1922, in create_machine_endpoint
    machine = Machine(
              ^^^^^^^
NameError: name 'Machine' is not defined

During handling of the above exception, another exception occurred:

Traceback (most recent call last):
  File "C:\Users\LENOVO\Desktop\PdM-Manager\venv\Lib\site-packages\starlette\middleware\exceptions.py", line 68, in __call__
    await self.app(scope, receive, sender)
  File "C:\Users\LENOVO\Desktop\PdM-Manager\venv\Lib\site-packages\fastapi\middleware\asyncexitstack.py", line 20, in __call__
    raise e
  File "C:\Users\LENOVO\Desktop\PdM-Manager\venv\Lib\site-packages\fastapi\middleware\asyncexitstack.py", line 17, in __call__
    await self.app(scope, receive, send)
  File "C:\Users\LENOVO\Desktop\PdM-Manager\venv\Lib\site-packages\starlette\routing.py", line 718, in __call__
    await route.handle(scope, receive, send)
  File "C:\Users\LENOVO\Desktop\PdM-Manager\venv\Lib\site-packages\starlette\routing.py", line 276, in handle
    await self.app(scope, receive, send)
  File "C:\Users\LENOVO\Desktop\PdM-Manager\venv\Lib\site-packages\starlette\routing.py", line 66, in app
    response = await func(request)
               ^^^^^^^^^^^^^^^^^^^
  File "C:\Users\LENOVO\Desktop\PdM-Manager\venv\Lib\site-packages\fastapi\routing.py", line 274, in app
    raw_response = await run_endpoint_function(
                   ^^^^^^^^^^^^^^^^^^^^^^^^^^^^
  File "C:\Users\LENOVO\Desktop\PdM-Manager\venv\Lib\site-packages\fastapi\routing.py", line 191, in run_endpoint_function
    return await dependant.call(**values)
           ^^^^^^^^^^^^^^^^^^^^^^^^^^^^^^
  File "C:\Users\LENOVO\Desktop\PdM-Manager\app\main.py", line 1939, in create_machine_endpoint
    raise HTTPException(status_code=500, detail=str(e))
fastapi.exceptions.HTTPException

[2025-03-31 16:38:54] [INFO] [logger:65] - Respuesta 500 para POST /api/machines procesada en 0.0073s
[2025-03-31 16:38:54] [INFO] [logger:65] - Solicitud POST /api/machines desde 127.0.0.1
[2025-03-31 16:38:54] [ERROR] [logger:50] - ERROR: name 'Machine' is not defined
CONTEXTO: Error al crear máquina
TRACEBACK: Traceback (most recent call last):
  File "C:\Users\LENOVO\Desktop\PdM-Manager\app\main.py", line 1922, in create_machine_endpoint
    machine = Machine(
              ^^^^^^^
NameError: name 'Machine' is not defined

[2025-03-31 16:38:54] [ERROR] [logger:50] - ERROR: 
CONTEXTO: {'endpoint': '/api/machines', 'método': 'POST'}
TRACEBACK: Traceback (most recent call last):
  File "C:\Users\LENOVO\Desktop\PdM-Manager\app\main.py", line 1922, in create_machine_endpoint
    machine = Machine(
              ^^^^^^^
NameError: name 'Machine' is not defined

During handling of the above exception, another exception occurred:

Traceback (most recent call last):
  File "C:\Users\LENOVO\Desktop\PdM-Manager\venv\Lib\site-packages\starlette\middleware\exceptions.py", line 68, in __call__
    await self.app(scope, receive, sender)
  File "C:\Users\LENOVO\Desktop\PdM-Manager\venv\Lib\site-packages\fastapi\middleware\asyncexitstack.py", line 20, in __call__
    raise e
  File "C:\Users\LENOVO\Desktop\PdM-Manager\venv\Lib\site-packages\fastapi\middleware\asyncexitstack.py", line 17, in __call__
    await self.app(scope, receive, send)
  File "C:\Users\LENOVO\Desktop\PdM-Manager\venv\Lib\site-packages\starlette\routing.py", line 718, in __call__
    await route.handle(scope, receive, send)
  File "C:\Users\LENOVO\Desktop\PdM-Manager\venv\Lib\site-packages\starlette\routing.py", line 276, in handle
    await self.app(scope, receive, send)
  File "C:\Users\LENOVO\Desktop\PdM-Manager\venv\Lib\site-packages\starlette\routing.py", line 66, in app
    response = await func(request)
               ^^^^^^^^^^^^^^^^^^^
  File "C:\Users\LENOVO\Desktop\PdM-Manager\venv\Lib\site-packages\fastapi\routing.py", line 274, in app
    raw_response = await run_endpoint_function(
                   ^^^^^^^^^^^^^^^^^^^^^^^^^^^^
  File "C:\Users\LENOVO\Desktop\PdM-Manager\venv\Lib\site-packages\fastapi\routing.py", line 191, in run_endpoint_function
    return await dependant.call(**values)
           ^^^^^^^^^^^^^^^^^^^^^^^^^^^^^^
  File "C:\Users\LENOVO\Desktop\PdM-Manager\app\main.py", line 1939, in create_machine_endpoint
    raise HTTPException(status_code=500, detail=str(e))
fastapi.exceptions.HTTPException

[2025-03-31 16:38:54] [INFO] [logger:65] - Respuesta 500 para POST /api/machines procesada en 0.0089s
[2025-03-31 16:38:54] [INFO] [logger:65] - Solicitud POST /api/machines desde 127.0.0.1
[2025-03-31 16:38:54] [ERROR] [logger:50] - ERROR: name 'Machine' is not defined
CONTEXTO: Error al crear máquina
TRACEBACK: Traceback (most recent call last):
  File "C:\Users\LENOVO\Desktop\PdM-Manager\app\main.py", line 1922, in create_machine_endpoint
    machine = Machine(
              ^^^^^^^
NameError: name 'Machine' is not defined

[2025-03-31 16:38:54] [ERROR] [logger:50] - ERROR: 
CONTEXTO: {'endpoint': '/api/machines', 'método': 'POST'}
TRACEBACK: Traceback (most recent call last):
  File "C:\Users\LENOVO\Desktop\PdM-Manager\app\main.py", line 1922, in create_machine_endpoint
    machine = Machine(
              ^^^^^^^
NameError: name 'Machine' is not defined

During handling of the above exception, another exception occurred:

Traceback (most recent call last):
  File "C:\Users\LENOVO\Desktop\PdM-Manager\venv\Lib\site-packages\starlette\middleware\exceptions.py", line 68, in __call__
    await self.app(scope, receive, sender)
  File "C:\Users\LENOVO\Desktop\PdM-Manager\venv\Lib\site-packages\fastapi\middleware\asyncexitstack.py", line 20, in __call__
    raise e
  File "C:\Users\LENOVO\Desktop\PdM-Manager\venv\Lib\site-packages\fastapi\middleware\asyncexitstack.py", line 17, in __call__
    await self.app(scope, receive, send)
  File "C:\Users\LENOVO\Desktop\PdM-Manager\venv\Lib\site-packages\starlette\routing.py", line 718, in __call__
    await route.handle(scope, receive, send)
  File "C:\Users\LENOVO\Desktop\PdM-Manager\venv\Lib\site-packages\starlette\routing.py", line 276, in handle
    await self.app(scope, receive, send)
  File "C:\Users\LENOVO\Desktop\PdM-Manager\venv\Lib\site-packages\starlette\routing.py", line 66, in app
    response = await func(request)
               ^^^^^^^^^^^^^^^^^^^
  File "C:\Users\LENOVO\Desktop\PdM-Manager\venv\Lib\site-packages\fastapi\routing.py", line 274, in app
    raw_response = await run_endpoint_function(
                   ^^^^^^^^^^^^^^^^^^^^^^^^^^^^
  File "C:\Users\LENOVO\Desktop\PdM-Manager\venv\Lib\site-packages\fastapi\routing.py", line 191, in run_endpoint_function
    return await dependant.call(**values)
           ^^^^^^^^^^^^^^^^^^^^^^^^^^^^^^
  File "C:\Users\LENOVO\Desktop\PdM-Manager\app\main.py", line 1939, in create_machine_endpoint
    raise HTTPException(status_code=500, detail=str(e))
fastapi.exceptions.HTTPException

[2025-03-31 16:38:54] [INFO] [logger:65] - Respuesta 500 para POST /api/machines procesada en 0.0063s
[2025-03-31 16:38:55] [INFO] [logger:65] - Solicitud POST /api/machines desde 127.0.0.1
[2025-03-31 16:38:55] [ERROR] [logger:50] - ERROR: name 'Machine' is not defined
CONTEXTO: Error al crear máquina
TRACEBACK: Traceback (most recent call last):
  File "C:\Users\LENOVO\Desktop\PdM-Manager\app\main.py", line 1922, in create_machine_endpoint
    machine = Machine(
              ^^^^^^^
NameError: name 'Machine' is not defined

[2025-03-31 16:38:55] [ERROR] [logger:50] - ERROR: 
CONTEXTO: {'endpoint': '/api/machines', 'método': 'POST'}
TRACEBACK: Traceback (most recent call last):
  File "C:\Users\LENOVO\Desktop\PdM-Manager\app\main.py", line 1922, in create_machine_endpoint
    machine = Machine(
              ^^^^^^^
NameError: name 'Machine' is not defined

During handling of the above exception, another exception occurred:

Traceback (most recent call last):
  File "C:\Users\LENOVO\Desktop\PdM-Manager\venv\Lib\site-packages\starlette\middleware\exceptions.py", line 68, in __call__
    await self.app(scope, receive, sender)
  File "C:\Users\LENOVO\Desktop\PdM-Manager\venv\Lib\site-packages\fastapi\middleware\asyncexitstack.py", line 20, in __call__
    raise e
  File "C:\Users\LENOVO\Desktop\PdM-Manager\venv\Lib\site-packages\fastapi\middleware\asyncexitstack.py", line 17, in __call__
    await self.app(scope, receive, send)
  File "C:\Users\LENOVO\Desktop\PdM-Manager\venv\Lib\site-packages\starlette\routing.py", line 718, in __call__
    await route.handle(scope, receive, send)
  File "C:\Users\LENOVO\Desktop\PdM-Manager\venv\Lib\site-packages\starlette\routing.py", line 276, in handle
    await self.app(scope, receive, send)
  File "C:\Users\LENOVO\Desktop\PdM-Manager\venv\Lib\site-packages\starlette\routing.py", line 66, in app
    response = await func(request)
               ^^^^^^^^^^^^^^^^^^^
  File "C:\Users\LENOVO\Desktop\PdM-Manager\venv\Lib\site-packages\fastapi\routing.py", line 274, in app
    raw_response = await run_endpoint_function(
                   ^^^^^^^^^^^^^^^^^^^^^^^^^^^^
  File "C:\Users\LENOVO\Desktop\PdM-Manager\venv\Lib\site-packages\fastapi\routing.py", line 191, in run_endpoint_function
    return await dependant.call(**values)
           ^^^^^^^^^^^^^^^^^^^^^^^^^^^^^^
  File "C:\Users\LENOVO\Desktop\PdM-Manager\app\main.py", line 1939, in create_machine_endpoint
    raise HTTPException(status_code=500, detail=str(e))
fastapi.exceptions.HTTPException

[2025-03-31 16:38:55] [INFO] [logger:65] - Respuesta 500 para POST /api/machines procesada en 0.0092s
[2025-03-31 16:38:55] [INFO] [logger:65] - Solicitud POST /api/machines desde 127.0.0.1
[2025-03-31 16:38:55] [ERROR] [logger:50] - ERROR: name 'Machine' is not defined
CONTEXTO: Error al crear máquina
TRACEBACK: Traceback (most recent call last):
  File "C:\Users\LENOVO\Desktop\PdM-Manager\app\main.py", line 1922, in create_machine_endpoint
    machine = Machine(
              ^^^^^^^
NameError: name 'Machine' is not defined

[2025-03-31 16:38:55] [ERROR] [logger:50] - ERROR: 
CONTEXTO: {'endpoint': '/api/machines', 'método': 'POST'}
TRACEBACK: Traceback (most recent call last):
  File "C:\Users\LENOVO\Desktop\PdM-Manager\app\main.py", line 1922, in create_machine_endpoint
    machine = Machine(
              ^^^^^^^
NameError: name 'Machine' is not defined

During handling of the above exception, another exception occurred:

Traceback (most recent call last):
  File "C:\Users\LENOVO\Desktop\PdM-Manager\venv\Lib\site-packages\starlette\middleware\exceptions.py", line 68, in __call__
    await self.app(scope, receive, sender)
  File "C:\Users\LENOVO\Desktop\PdM-Manager\venv\Lib\site-packages\fastapi\middleware\asyncexitstack.py", line 20, in __call__
    raise e
  File "C:\Users\LENOVO\Desktop\PdM-Manager\venv\Lib\site-packages\fastapi\middleware\asyncexitstack.py", line 17, in __call__
    await self.app(scope, receive, send)
  File "C:\Users\LENOVO\Desktop\PdM-Manager\venv\Lib\site-packages\starlette\routing.py", line 718, in __call__
    await route.handle(scope, receive, send)
  File "C:\Users\LENOVO\Desktop\PdM-Manager\venv\Lib\site-packages\starlette\routing.py", line 276, in handle
    await self.app(scope, receive, send)
  File "C:\Users\LENOVO\Desktop\PdM-Manager\venv\Lib\site-packages\starlette\routing.py", line 66, in app
    response = await func(request)
               ^^^^^^^^^^^^^^^^^^^
  File "C:\Users\LENOVO\Desktop\PdM-Manager\venv\Lib\site-packages\fastapi\routing.py", line 274, in app
    raw_response = await run_endpoint_function(
                   ^^^^^^^^^^^^^^^^^^^^^^^^^^^^
  File "C:\Users\LENOVO\Desktop\PdM-Manager\venv\Lib\site-packages\fastapi\routing.py", line 191, in run_endpoint_function
    return await dependant.call(**values)
           ^^^^^^^^^^^^^^^^^^^^^^^^^^^^^^
  File "C:\Users\LENOVO\Desktop\PdM-Manager\app\main.py", line 1939, in create_machine_endpoint
    raise HTTPException(status_code=500, detail=str(e))
fastapi.exceptions.HTTPException

[2025-03-31 16:38:55] [INFO] [logger:65] - Respuesta 500 para POST /api/machines procesada en 0.0328s
[2025-03-31 16:38:55] [INFO] [logger:65] - Solicitud POST /api/machines desde 127.0.0.1
[2025-03-31 16:38:55] [ERROR] [logger:50] - ERROR: name 'Machine' is not defined
CONTEXTO: Error al crear máquina
TRACEBACK: Traceback (most recent call last):
  File "C:\Users\LENOVO\Desktop\PdM-Manager\app\main.py", line 1922, in create_machine_endpoint
    machine = Machine(
              ^^^^^^^
NameError: name 'Machine' is not defined

[2025-03-31 16:38:55] [ERROR] [logger:50] - ERROR: 
CONTEXTO: {'endpoint': '/api/machines', 'método': 'POST'}
TRACEBACK: Traceback (most recent call last):
  File "C:\Users\LENOVO\Desktop\PdM-Manager\app\main.py", line 1922, in create_machine_endpoint
    machine = Machine(
              ^^^^^^^
NameError: name 'Machine' is not defined

During handling of the above exception, another exception occurred:

Traceback (most recent call last):
  File "C:\Users\LENOVO\Desktop\PdM-Manager\venv\Lib\site-packages\starlette\middleware\exceptions.py", line 68, in __call__
    await self.app(scope, receive, sender)
  File "C:\Users\LENOVO\Desktop\PdM-Manager\venv\Lib\site-packages\fastapi\middleware\asyncexitstack.py", line 20, in __call__
    raise e
  File "C:\Users\LENOVO\Desktop\PdM-Manager\venv\Lib\site-packages\fastapi\middleware\asyncexitstack.py", line 17, in __call__
    await self.app(scope, receive, send)
  File "C:\Users\LENOVO\Desktop\PdM-Manager\venv\Lib\site-packages\starlette\routing.py", line 718, in __call__
    await route.handle(scope, receive, send)
  File "C:\Users\LENOVO\Desktop\PdM-Manager\venv\Lib\site-packages\starlette\routing.py", line 276, in handle
    await self.app(scope, receive, send)
  File "C:\Users\LENOVO\Desktop\PdM-Manager\venv\Lib\site-packages\starlette\routing.py", line 66, in app
    response = await func(request)
               ^^^^^^^^^^^^^^^^^^^
  File "C:\Users\LENOVO\Desktop\PdM-Manager\venv\Lib\site-packages\fastapi\routing.py", line 274, in app
    raw_response = await run_endpoint_function(
                   ^^^^^^^^^^^^^^^^^^^^^^^^^^^^
  File "C:\Users\LENOVO\Desktop\PdM-Manager\venv\Lib\site-packages\fastapi\routing.py", line 191, in run_endpoint_function
    return await dependant.call(**values)
           ^^^^^^^^^^^^^^^^^^^^^^^^^^^^^^
  File "C:\Users\LENOVO\Desktop\PdM-Manager\app\main.py", line 1939, in create_machine_endpoint
    raise HTTPException(status_code=500, detail=str(e))
fastapi.exceptions.HTTPException

[2025-03-31 16:38:55] [INFO] [logger:65] - Respuesta 500 para POST /api/machines procesada en 0.0074s
[2025-03-31 16:43:15] [INFO] [logger:65] - Solicitud GET /static/css/style.css desde 127.0.0.1
[2025-03-31 16:43:15] [INFO] [logger:65] - Respuesta 304 para GET /static/css/style.css procesada en 0.0020s
[2025-03-31 16:43:15] [INFO] [logger:65] - Solicitud GET /static/js/realtime-updates.js desde 127.0.0.1
[2025-03-31 16:43:15] [INFO] [logger:65] - Solicitud GET /static/js/dashboard.js desde 127.0.0.1
[2025-03-31 16:43:15] [INFO] [logger:65] - Solicitud GET /static/js/config.js desde 127.0.0.1
[2025-03-31 16:43:15] [INFO] [logger:65] - Respuesta 200 para GET /static/js/realtime-updates.js procesada en 0.0076s
[2025-03-31 16:43:15] [INFO] [logger:65] - Respuesta 304 para GET /static/js/dashboard.js procesada en 0.0079s
[2025-03-31 16:43:15] [INFO] [logger:65] - Respuesta 200 para GET /static/js/config.js procesada en 0.0068s
[2025-03-31 16:43:15] [INFO] [logger:65] - Solicitud GET /static/js/app.js desde 127.0.0.1
[2025-03-31 16:43:15] [INFO] [logger:65] - Respuesta 200 para GET /static/js/app.js procesada en 0.0046s
[2025-03-31 16:43:22] [INFO] [logger:65] - Solicitud GET /api/sensors desde 127.0.0.1
[2025-03-31 16:43:22] [INFO] [logger:65] - Solicitud GET /api/config/limits desde 127.0.0.1
[2025-03-31 16:43:22] [INFO] [logger:65] - Solicitud GET /api/models desde 127.0.0.1
[2025-03-31 16:43:22] [INFO] [logger:65] - Obteniendo lista de sensores: skip=0, limit=100
[2025-03-31 16:43:22] [INFO] [logger:65] - Respuesta 404 para GET /api/config/limits procesada en 0.0027s
[2025-03-31 16:43:22] [INFO] [logger:65] - Respuesta 200 para GET /api/sensors procesada en 0.0089s
[2025-03-31 16:43:22] [INFO] [logger:65] - Respuesta 200 para GET /api/models procesada en 0.0070s
[2025-03-31 16:43:22] [INFO] [logger:65] - Solicitud GET /api/sensors desde 127.0.0.1
[2025-03-31 16:43:22] [INFO] [logger:65] - Solicitud GET /api/models desde 127.0.0.1
[2025-03-31 16:43:22] [INFO] [logger:65] - Obteniendo lista de sensores: skip=0, limit=100
[2025-03-31 16:43:22] [INFO] [logger:65] - Solicitud GET /api/machines desde 127.0.0.1
[2025-03-31 16:43:22] [INFO] [logger:65] - Respuesta 200 para GET /api/sensors procesada en 0.0088s
[2025-03-31 16:43:22] [INFO] [logger:65] - Respuesta 200 para GET /api/models procesada en 0.0096s
[2025-03-31 16:43:22] [INFO] [logger:65] - Respuesta 200 para GET /api/machines procesada en 0.0076s
[2025-03-31 16:43:22] [INFO] [logger:65] - Solicitud GET /api/sensors desde 127.0.0.1
[2025-03-31 16:43:22] [INFO] [logger:65] - Solicitud GET /api/models desde 127.0.0.1
[2025-03-31 16:43:22] [INFO] [logger:65] - Obteniendo lista de sensores: skip=0, limit=100
[2025-03-31 16:43:22] [INFO] [logger:65] - Respuesta 200 para GET /api/models procesada en 0.0054s
[2025-03-31 16:43:22] [INFO] [logger:65] - Respuesta 200 para GET /api/sensors procesada en 0.0075s
[2025-03-31 16:43:58] [INFO] [logger:65] - Solicitud POST /api/machines desde 127.0.0.1
[2025-03-31 16:43:58] [ERROR] [logger:50] - ERROR: name 'Machine' is not defined
CONTEXTO: Error al crear máquina
TRACEBACK: Traceback (most recent call last):
  File "C:\Users\LENOVO\Desktop\PdM-Manager\app\main.py", line 1922, in create_machine_endpoint
    machine = Machine(
              ^^^^^^^
NameError: name 'Machine' is not defined

[2025-03-31 16:43:58] [ERROR] [logger:50] - ERROR: 
CONTEXTO: {'endpoint': '/api/machines', 'método': 'POST'}
TRACEBACK: Traceback (most recent call last):
  File "C:\Users\LENOVO\Desktop\PdM-Manager\app\main.py", line 1922, in create_machine_endpoint
    machine = Machine(
              ^^^^^^^
NameError: name 'Machine' is not defined

During handling of the above exception, another exception occurred:

Traceback (most recent call last):
  File "C:\Users\LENOVO\Desktop\PdM-Manager\venv\Lib\site-packages\starlette\middleware\exceptions.py", line 68, in __call__
    await self.app(scope, receive, sender)
  File "C:\Users\LENOVO\Desktop\PdM-Manager\venv\Lib\site-packages\fastapi\middleware\asyncexitstack.py", line 20, in __call__
    raise e
  File "C:\Users\LENOVO\Desktop\PdM-Manager\venv\Lib\site-packages\fastapi\middleware\asyncexitstack.py", line 17, in __call__
    await self.app(scope, receive, send)
  File "C:\Users\LENOVO\Desktop\PdM-Manager\venv\Lib\site-packages\starlette\routing.py", line 718, in __call__
    await route.handle(scope, receive, send)
  File "C:\Users\LENOVO\Desktop\PdM-Manager\venv\Lib\site-packages\starlette\routing.py", line 276, in handle
    await self.app(scope, receive, send)
  File "C:\Users\LENOVO\Desktop\PdM-Manager\venv\Lib\site-packages\starlette\routing.py", line 66, in app
    response = await func(request)
               ^^^^^^^^^^^^^^^^^^^
  File "C:\Users\LENOVO\Desktop\PdM-Manager\venv\Lib\site-packages\fastapi\routing.py", line 274, in app
    raw_response = await run_endpoint_function(
                   ^^^^^^^^^^^^^^^^^^^^^^^^^^^^
  File "C:\Users\LENOVO\Desktop\PdM-Manager\venv\Lib\site-packages\fastapi\routing.py", line 191, in run_endpoint_function
    return await dependant.call(**values)
           ^^^^^^^^^^^^^^^^^^^^^^^^^^^^^^
  File "C:\Users\LENOVO\Desktop\PdM-Manager\app\main.py", line 1939, in create_machine_endpoint
    raise HTTPException(status_code=500, detail=str(e))
fastapi.exceptions.HTTPException

[2025-03-31 16:43:58] [INFO] [logger:65] - Respuesta 500 para POST /api/machines procesada en 0.0102s
[2025-03-31 16:43:59] [INFO] [logger:65] - Solicitud POST /api/machines desde 127.0.0.1
[2025-03-31 16:43:59] [ERROR] [logger:50] - ERROR: name 'Machine' is not defined
CONTEXTO: Error al crear máquina
TRACEBACK: Traceback (most recent call last):
  File "C:\Users\LENOVO\Desktop\PdM-Manager\app\main.py", line 1922, in create_machine_endpoint
    machine = Machine(
              ^^^^^^^
NameError: name 'Machine' is not defined

[2025-03-31 16:43:59] [ERROR] [logger:50] - ERROR: 
CONTEXTO: {'endpoint': '/api/machines', 'método': 'POST'}
TRACEBACK: Traceback (most recent call last):
  File "C:\Users\LENOVO\Desktop\PdM-Manager\app\main.py", line 1922, in create_machine_endpoint
    machine = Machine(
              ^^^^^^^
NameError: name 'Machine' is not defined

During handling of the above exception, another exception occurred:

Traceback (most recent call last):
  File "C:\Users\LENOVO\Desktop\PdM-Manager\venv\Lib\site-packages\starlette\middleware\exceptions.py", line 68, in __call__
    await self.app(scope, receive, sender)
  File "C:\Users\LENOVO\Desktop\PdM-Manager\venv\Lib\site-packages\fastapi\middleware\asyncexitstack.py", line 20, in __call__
    raise e
  File "C:\Users\LENOVO\Desktop\PdM-Manager\venv\Lib\site-packages\fastapi\middleware\asyncexitstack.py", line 17, in __call__
    await self.app(scope, receive, send)
  File "C:\Users\LENOVO\Desktop\PdM-Manager\venv\Lib\site-packages\starlette\routing.py", line 718, in __call__
    await route.handle(scope, receive, send)
  File "C:\Users\LENOVO\Desktop\PdM-Manager\venv\Lib\site-packages\starlette\routing.py", line 276, in handle
    await self.app(scope, receive, send)
  File "C:\Users\LENOVO\Desktop\PdM-Manager\venv\Lib\site-packages\starlette\routing.py", line 66, in app
    response = await func(request)
               ^^^^^^^^^^^^^^^^^^^
  File "C:\Users\LENOVO\Desktop\PdM-Manager\venv\Lib\site-packages\fastapi\routing.py", line 274, in app
    raw_response = await run_endpoint_function(
                   ^^^^^^^^^^^^^^^^^^^^^^^^^^^^
  File "C:\Users\LENOVO\Desktop\PdM-Manager\venv\Lib\site-packages\fastapi\routing.py", line 191, in run_endpoint_function
    return await dependant.call(**values)
           ^^^^^^^^^^^^^^^^^^^^^^^^^^^^^^
  File "C:\Users\LENOVO\Desktop\PdM-Manager\app\main.py", line 1939, in create_machine_endpoint
    raise HTTPException(status_code=500, detail=str(e))
fastapi.exceptions.HTTPException

[2025-03-31 16:43:59] [INFO] [logger:65] - Respuesta 500 para POST /api/machines procesada en 0.0091s
[2025-03-31 16:43:59] [INFO] [logger:65] - Solicitud POST /api/machines desde 127.0.0.1
[2025-03-31 16:43:59] [ERROR] [logger:50] - ERROR: name 'Machine' is not defined
CONTEXTO: Error al crear máquina
TRACEBACK: Traceback (most recent call last):
  File "C:\Users\LENOVO\Desktop\PdM-Manager\app\main.py", line 1922, in create_machine_endpoint
    machine = Machine(
              ^^^^^^^
NameError: name 'Machine' is not defined

[2025-03-31 16:43:59] [ERROR] [logger:50] - ERROR: 
CONTEXTO: {'endpoint': '/api/machines', 'método': 'POST'}
TRACEBACK: Traceback (most recent call last):
  File "C:\Users\LENOVO\Desktop\PdM-Manager\app\main.py", line 1922, in create_machine_endpoint
    machine = Machine(
              ^^^^^^^
NameError: name 'Machine' is not defined

During handling of the above exception, another exception occurred:

Traceback (most recent call last):
  File "C:\Users\LENOVO\Desktop\PdM-Manager\venv\Lib\site-packages\starlette\middleware\exceptions.py", line 68, in __call__
    await self.app(scope, receive, sender)
  File "C:\Users\LENOVO\Desktop\PdM-Manager\venv\Lib\site-packages\fastapi\middleware\asyncexitstack.py", line 20, in __call__
    raise e
  File "C:\Users\LENOVO\Desktop\PdM-Manager\venv\Lib\site-packages\fastapi\middleware\asyncexitstack.py", line 17, in __call__
    await self.app(scope, receive, send)
  File "C:\Users\LENOVO\Desktop\PdM-Manager\venv\Lib\site-packages\starlette\routing.py", line 718, in __call__
    await route.handle(scope, receive, send)
  File "C:\Users\LENOVO\Desktop\PdM-Manager\venv\Lib\site-packages\starlette\routing.py", line 276, in handle
    await self.app(scope, receive, send)
  File "C:\Users\LENOVO\Desktop\PdM-Manager\venv\Lib\site-packages\starlette\routing.py", line 66, in app
    response = await func(request)
               ^^^^^^^^^^^^^^^^^^^
  File "C:\Users\LENOVO\Desktop\PdM-Manager\venv\Lib\site-packages\fastapi\routing.py", line 274, in app
    raw_response = await run_endpoint_function(
                   ^^^^^^^^^^^^^^^^^^^^^^^^^^^^
  File "C:\Users\LENOVO\Desktop\PdM-Manager\venv\Lib\site-packages\fastapi\routing.py", line 191, in run_endpoint_function
    return await dependant.call(**values)
           ^^^^^^^^^^^^^^^^^^^^^^^^^^^^^^
  File "C:\Users\LENOVO\Desktop\PdM-Manager\app\main.py", line 1939, in create_machine_endpoint
    raise HTTPException(status_code=500, detail=str(e))
fastapi.exceptions.HTTPException

[2025-03-31 16:43:59] [INFO] [logger:65] - Respuesta 500 para POST /api/machines procesada en 0.0071s
[2025-03-31 16:43:59] [INFO] [logger:65] - Solicitud POST /api/machines desde 127.0.0.1
[2025-03-31 16:43:59] [ERROR] [logger:50] - ERROR: name 'Machine' is not defined
CONTEXTO: Error al crear máquina
TRACEBACK: Traceback (most recent call last):
  File "C:\Users\LENOVO\Desktop\PdM-Manager\app\main.py", line 1922, in create_machine_endpoint
    machine = Machine(
              ^^^^^^^
NameError: name 'Machine' is not defined

[2025-03-31 16:43:59] [ERROR] [logger:50] - ERROR: 
CONTEXTO: {'endpoint': '/api/machines', 'método': 'POST'}
TRACEBACK: Traceback (most recent call last):
  File "C:\Users\LENOVO\Desktop\PdM-Manager\app\main.py", line 1922, in create_machine_endpoint
    machine = Machine(
              ^^^^^^^
NameError: name 'Machine' is not defined

During handling of the above exception, another exception occurred:

Traceback (most recent call last):
  File "C:\Users\LENOVO\Desktop\PdM-Manager\venv\Lib\site-packages\starlette\middleware\exceptions.py", line 68, in __call__
    await self.app(scope, receive, sender)
  File "C:\Users\LENOVO\Desktop\PdM-Manager\venv\Lib\site-packages\fastapi\middleware\asyncexitstack.py", line 20, in __call__
    raise e
  File "C:\Users\LENOVO\Desktop\PdM-Manager\venv\Lib\site-packages\fastapi\middleware\asyncexitstack.py", line 17, in __call__
    await self.app(scope, receive, send)
  File "C:\Users\LENOVO\Desktop\PdM-Manager\venv\Lib\site-packages\starlette\routing.py", line 718, in __call__
    await route.handle(scope, receive, send)
  File "C:\Users\LENOVO\Desktop\PdM-Manager\venv\Lib\site-packages\starlette\routing.py", line 276, in handle
    await self.app(scope, receive, send)
  File "C:\Users\LENOVO\Desktop\PdM-Manager\venv\Lib\site-packages\starlette\routing.py", line 66, in app
    response = await func(request)
               ^^^^^^^^^^^^^^^^^^^
  File "C:\Users\LENOVO\Desktop\PdM-Manager\venv\Lib\site-packages\fastapi\routing.py", line 274, in app
    raw_response = await run_endpoint_function(
                   ^^^^^^^^^^^^^^^^^^^^^^^^^^^^
  File "C:\Users\LENOVO\Desktop\PdM-Manager\venv\Lib\site-packages\fastapi\routing.py", line 191, in run_endpoint_function
    return await dependant.call(**values)
           ^^^^^^^^^^^^^^^^^^^^^^^^^^^^^^
  File "C:\Users\LENOVO\Desktop\PdM-Manager\app\main.py", line 1939, in create_machine_endpoint
    raise HTTPException(status_code=500, detail=str(e))
fastapi.exceptions.HTTPException

[2025-03-31 16:43:59] [INFO] [logger:65] - Respuesta 500 para POST /api/machines procesada en 0.0065s
[2025-03-31 16:43:59] [INFO] [logger:65] - Solicitud POST /api/machines desde 127.0.0.1
[2025-03-31 16:43:59] [ERROR] [logger:50] - ERROR: name 'Machine' is not defined
CONTEXTO: Error al crear máquina
TRACEBACK: Traceback (most recent call last):
  File "C:\Users\LENOVO\Desktop\PdM-Manager\app\main.py", line 1922, in create_machine_endpoint
    machine = Machine(
              ^^^^^^^
NameError: name 'Machine' is not defined

[2025-03-31 16:43:59] [ERROR] [logger:50] - ERROR: 
CONTEXTO: {'endpoint': '/api/machines', 'método': 'POST'}
TRACEBACK: Traceback (most recent call last):
  File "C:\Users\LENOVO\Desktop\PdM-Manager\app\main.py", line 1922, in create_machine_endpoint
    machine = Machine(
              ^^^^^^^
NameError: name 'Machine' is not defined

During handling of the above exception, another exception occurred:

Traceback (most recent call last):
  File "C:\Users\LENOVO\Desktop\PdM-Manager\venv\Lib\site-packages\starlette\middleware\exceptions.py", line 68, in __call__
    await self.app(scope, receive, sender)
  File "C:\Users\LENOVO\Desktop\PdM-Manager\venv\Lib\site-packages\fastapi\middleware\asyncexitstack.py", line 20, in __call__
    raise e
  File "C:\Users\LENOVO\Desktop\PdM-Manager\venv\Lib\site-packages\fastapi\middleware\asyncexitstack.py", line 17, in __call__
    await self.app(scope, receive, send)
  File "C:\Users\LENOVO\Desktop\PdM-Manager\venv\Lib\site-packages\starlette\routing.py", line 718, in __call__
    await route.handle(scope, receive, send)
  File "C:\Users\LENOVO\Desktop\PdM-Manager\venv\Lib\site-packages\starlette\routing.py", line 276, in handle
    await self.app(scope, receive, send)
  File "C:\Users\LENOVO\Desktop\PdM-Manager\venv\Lib\site-packages\starlette\routing.py", line 66, in app
    response = await func(request)
               ^^^^^^^^^^^^^^^^^^^
  File "C:\Users\LENOVO\Desktop\PdM-Manager\venv\Lib\site-packages\fastapi\routing.py", line 274, in app
    raw_response = await run_endpoint_function(
                   ^^^^^^^^^^^^^^^^^^^^^^^^^^^^
  File "C:\Users\LENOVO\Desktop\PdM-Manager\venv\Lib\site-packages\fastapi\routing.py", line 191, in run_endpoint_function
    return await dependant.call(**values)
           ^^^^^^^^^^^^^^^^^^^^^^^^^^^^^^
  File "C:\Users\LENOVO\Desktop\PdM-Manager\app\main.py", line 1939, in create_machine_endpoint
    raise HTTPException(status_code=500, detail=str(e))
fastapi.exceptions.HTTPException

[2025-03-31 16:43:59] [INFO] [logger:65] - Respuesta 500 para POST /api/machines procesada en 0.0085s
[2025-03-31 16:44:00] [INFO] [logger:65] - Solicitud POST /api/machines desde 127.0.0.1
[2025-03-31 16:44:00] [ERROR] [logger:50] - ERROR: name 'Machine' is not defined
CONTEXTO: Error al crear máquina
TRACEBACK: Traceback (most recent call last):
  File "C:\Users\LENOVO\Desktop\PdM-Manager\app\main.py", line 1922, in create_machine_endpoint
    machine = Machine(
              ^^^^^^^
NameError: name 'Machine' is not defined

[2025-03-31 16:44:00] [ERROR] [logger:50] - ERROR: 
CONTEXTO: {'endpoint': '/api/machines', 'método': 'POST'}
TRACEBACK: Traceback (most recent call last):
  File "C:\Users\LENOVO\Desktop\PdM-Manager\app\main.py", line 1922, in create_machine_endpoint
    machine = Machine(
              ^^^^^^^
NameError: name 'Machine' is not defined

During handling of the above exception, another exception occurred:

Traceback (most recent call last):
  File "C:\Users\LENOVO\Desktop\PdM-Manager\venv\Lib\site-packages\starlette\middleware\exceptions.py", line 68, in __call__
    await self.app(scope, receive, sender)
  File "C:\Users\LENOVO\Desktop\PdM-Manager\venv\Lib\site-packages\fastapi\middleware\asyncexitstack.py", line 20, in __call__
    raise e
  File "C:\Users\LENOVO\Desktop\PdM-Manager\venv\Lib\site-packages\fastapi\middleware\asyncexitstack.py", line 17, in __call__
    await self.app(scope, receive, send)
  File "C:\Users\LENOVO\Desktop\PdM-Manager\venv\Lib\site-packages\starlette\routing.py", line 718, in __call__
    await route.handle(scope, receive, send)
  File "C:\Users\LENOVO\Desktop\PdM-Manager\venv\Lib\site-packages\starlette\routing.py", line 276, in handle
    await self.app(scope, receive, send)
  File "C:\Users\LENOVO\Desktop\PdM-Manager\venv\Lib\site-packages\starlette\routing.py", line 66, in app
    response = await func(request)
               ^^^^^^^^^^^^^^^^^^^
  File "C:\Users\LENOVO\Desktop\PdM-Manager\venv\Lib\site-packages\fastapi\routing.py", line 274, in app
    raw_response = await run_endpoint_function(
                   ^^^^^^^^^^^^^^^^^^^^^^^^^^^^
  File "C:\Users\LENOVO\Desktop\PdM-Manager\venv\Lib\site-packages\fastapi\routing.py", line 191, in run_endpoint_function
    return await dependant.call(**values)
           ^^^^^^^^^^^^^^^^^^^^^^^^^^^^^^
  File "C:\Users\LENOVO\Desktop\PdM-Manager\app\main.py", line 1939, in create_machine_endpoint
    raise HTTPException(status_code=500, detail=str(e))
fastapi.exceptions.HTTPException

[2025-03-31 16:44:00] [INFO] [logger:65] - Respuesta 500 para POST /api/machines procesada en 0.0100s
[2025-03-31 16:44:00] [INFO] [logger:65] - Solicitud POST /api/machines desde 127.0.0.1
[2025-03-31 16:44:00] [ERROR] [logger:50] - ERROR: name 'Machine' is not defined
CONTEXTO: Error al crear máquina
TRACEBACK: Traceback (most recent call last):
  File "C:\Users\LENOVO\Desktop\PdM-Manager\app\main.py", line 1922, in create_machine_endpoint
    machine = Machine(
              ^^^^^^^
NameError: name 'Machine' is not defined

[2025-03-31 16:44:00] [ERROR] [logger:50] - ERROR: 
CONTEXTO: {'endpoint': '/api/machines', 'método': 'POST'}
TRACEBACK: Traceback (most recent call last):
  File "C:\Users\LENOVO\Desktop\PdM-Manager\app\main.py", line 1922, in create_machine_endpoint
    machine = Machine(
              ^^^^^^^
NameError: name 'Machine' is not defined

During handling of the above exception, another exception occurred:

Traceback (most recent call last):
  File "C:\Users\LENOVO\Desktop\PdM-Manager\venv\Lib\site-packages\starlette\middleware\exceptions.py", line 68, in __call__
    await self.app(scope, receive, sender)
  File "C:\Users\LENOVO\Desktop\PdM-Manager\venv\Lib\site-packages\fastapi\middleware\asyncexitstack.py", line 20, in __call__
    raise e
  File "C:\Users\LENOVO\Desktop\PdM-Manager\venv\Lib\site-packages\fastapi\middleware\asyncexitstack.py", line 17, in __call__
    await self.app(scope, receive, send)
  File "C:\Users\LENOVO\Desktop\PdM-Manager\venv\Lib\site-packages\starlette\routing.py", line 718, in __call__
    await route.handle(scope, receive, send)
  File "C:\Users\LENOVO\Desktop\PdM-Manager\venv\Lib\site-packages\starlette\routing.py", line 276, in handle
    await self.app(scope, receive, send)
  File "C:\Users\LENOVO\Desktop\PdM-Manager\venv\Lib\site-packages\starlette\routing.py", line 66, in app
    response = await func(request)
               ^^^^^^^^^^^^^^^^^^^
  File "C:\Users\LENOVO\Desktop\PdM-Manager\venv\Lib\site-packages\fastapi\routing.py", line 274, in app
    raw_response = await run_endpoint_function(
                   ^^^^^^^^^^^^^^^^^^^^^^^^^^^^
  File "C:\Users\LENOVO\Desktop\PdM-Manager\venv\Lib\site-packages\fastapi\routing.py", line 191, in run_endpoint_function
    return await dependant.call(**values)
           ^^^^^^^^^^^^^^^^^^^^^^^^^^^^^^
  File "C:\Users\LENOVO\Desktop\PdM-Manager\app\main.py", line 1939, in create_machine_endpoint
    raise HTTPException(status_code=500, detail=str(e))
fastapi.exceptions.HTTPException

[2025-03-31 16:44:00] [INFO] [logger:65] - Respuesta 500 para POST /api/machines procesada en 0.0071s
[2025-03-31 16:44:00] [INFO] [logger:65] - Solicitud POST /api/machines desde 127.0.0.1
[2025-03-31 16:44:00] [ERROR] [logger:50] - ERROR: name 'Machine' is not defined
CONTEXTO: Error al crear máquina
TRACEBACK: Traceback (most recent call last):
  File "C:\Users\LENOVO\Desktop\PdM-Manager\app\main.py", line 1922, in create_machine_endpoint
    machine = Machine(
              ^^^^^^^
NameError: name 'Machine' is not defined

[2025-03-31 16:44:00] [ERROR] [logger:50] - ERROR: 
CONTEXTO: {'endpoint': '/api/machines', 'método': 'POST'}
TRACEBACK: Traceback (most recent call last):
  File "C:\Users\LENOVO\Desktop\PdM-Manager\app\main.py", line 1922, in create_machine_endpoint
    machine = Machine(
              ^^^^^^^
NameError: name 'Machine' is not defined

During handling of the above exception, another exception occurred:

Traceback (most recent call last):
  File "C:\Users\LENOVO\Desktop\PdM-Manager\venv\Lib\site-packages\starlette\middleware\exceptions.py", line 68, in __call__
    await self.app(scope, receive, sender)
  File "C:\Users\LENOVO\Desktop\PdM-Manager\venv\Lib\site-packages\fastapi\middleware\asyncexitstack.py", line 20, in __call__
    raise e
  File "C:\Users\LENOVO\Desktop\PdM-Manager\venv\Lib\site-packages\fastapi\middleware\asyncexitstack.py", line 17, in __call__
    await self.app(scope, receive, send)
  File "C:\Users\LENOVO\Desktop\PdM-Manager\venv\Lib\site-packages\starlette\routing.py", line 718, in __call__
    await route.handle(scope, receive, send)
  File "C:\Users\LENOVO\Desktop\PdM-Manager\venv\Lib\site-packages\starlette\routing.py", line 276, in handle
    await self.app(scope, receive, send)
  File "C:\Users\LENOVO\Desktop\PdM-Manager\venv\Lib\site-packages\starlette\routing.py", line 66, in app
    response = await func(request)
               ^^^^^^^^^^^^^^^^^^^
  File "C:\Users\LENOVO\Desktop\PdM-Manager\venv\Lib\site-packages\fastapi\routing.py", line 274, in app
    raw_response = await run_endpoint_function(
                   ^^^^^^^^^^^^^^^^^^^^^^^^^^^^
  File "C:\Users\LENOVO\Desktop\PdM-Manager\venv\Lib\site-packages\fastapi\routing.py", line 191, in run_endpoint_function
    return await dependant.call(**values)
           ^^^^^^^^^^^^^^^^^^^^^^^^^^^^^^
  File "C:\Users\LENOVO\Desktop\PdM-Manager\app\main.py", line 1939, in create_machine_endpoint
    raise HTTPException(status_code=500, detail=str(e))
fastapi.exceptions.HTTPException

[2025-03-31 16:44:00] [INFO] [logger:65] - Respuesta 500 para POST /api/machines procesada en 0.0095s
[2025-03-31 16:49:30] [INFO] [logger:65] - Solicitud GET / desde 127.0.0.1
[2025-03-31 16:49:30] [INFO] [logger:65] - Respuesta 200 para GET / procesada en 0.0031s
[2025-03-31 16:49:30] [INFO] [logger:65] - Solicitud GET /static/css/style.css desde 127.0.0.1
[2025-03-31 16:49:30] [INFO] [logger:65] - Solicitud GET /static/js/utils.js desde 127.0.0.1
[2025-03-31 16:49:30] [INFO] [logger:65] - Respuesta 304 para GET /static/css/style.css procesada en 0.0032s
[2025-03-31 16:49:30] [INFO] [logger:65] - Respuesta 304 para GET /static/js/utils.js procesada en 0.0050s
[2025-03-31 16:49:30] [INFO] [logger:65] - Solicitud GET /static/js/app-logger.js desde 127.0.0.1
[2025-03-31 16:49:30] [INFO] [logger:65] - Respuesta 304 para GET /static/js/app-logger.js procesada en 0.0029s
[2025-03-31 16:49:30] [INFO] [logger:65] - Solicitud GET /static/js/navigation.js desde 127.0.0.1
[2025-03-31 16:49:30] [INFO] [logger:65] - Solicitud GET /static/js/realtime-updates.js desde 127.0.0.1
[2025-03-31 16:49:30] [INFO] [logger:65] - Solicitud GET /static/js/config.js desde 127.0.0.1
[2025-03-31 16:49:30] [INFO] [logger:65] - Solicitud GET /static/js/dashboard.js desde 127.0.0.1
[2025-03-31 16:49:30] [INFO] [logger:65] - Respuesta 304 para GET /static/js/navigation.js procesada en 0.0097s
[2025-03-31 16:49:30] [INFO] [logger:65] - Solicitud GET /static/js/charts.js desde 127.0.0.1
[2025-03-31 16:49:30] [INFO] [logger:65] - Solicitud GET /static/js/logs-ui.js desde 127.0.0.1
[2025-03-31 16:49:30] [INFO] [logger:65] - Respuesta 304 para GET /static/js/realtime-updates.js procesada en 0.0145s
[2025-03-31 16:49:30] [INFO] [logger:65] - Respuesta 200 para GET /static/js/config.js procesada en 0.0115s
[2025-03-31 16:49:30] [INFO] [logger:65] - Respuesta 304 para GET /static/js/dashboard.js procesada en 0.0120s
[2025-03-31 16:49:30] [INFO] [logger:65] - Solicitud GET /static/js/app.js desde 127.0.0.1
[2025-03-31 16:49:30] [INFO] [logger:65] - Respuesta 304 para GET /static/js/logs-ui.js procesada en 0.0130s
[2025-03-31 16:49:30] [INFO] [logger:65] - Respuesta 304 para GET /static/js/charts.js procesada en 0.0156s
[2025-03-31 16:49:30] [INFO] [logger:65] - Respuesta 200 para GET /static/js/app.js procesada en 0.0102s
[2025-03-31 16:49:32] [INFO] [logger:65] - Solicitud GET /static/js/config.js desde 127.0.0.1
[2025-03-31 16:49:32] [INFO] [logger:65] - Respuesta 304 para GET /static/js/config.js procesada en 0.0025s
[2025-03-31 16:49:37] [INFO] [logger:65] - Solicitud GET /api/sensors desde 127.0.0.1
[2025-03-31 16:49:37] [INFO] [logger:65] - Obteniendo lista de sensores: skip=0, limit=100
[2025-03-31 16:49:37] [INFO] [logger:65] - Respuesta 200 para GET /api/sensors procesada en 0.0038s
[2025-03-31 16:49:37] [INFO] [logger:65] - Solicitud GET /api/models desde 127.0.0.1
[2025-03-31 16:49:37] [INFO] [logger:65] - Solicitud GET /api/config/limits desde 127.0.0.1
[2025-03-31 16:49:37] [INFO] [logger:65] - Solicitud GET /api/sensors desde 127.0.0.1
[2025-03-31 16:49:37] [INFO] [logger:65] - Respuesta 404 para GET /api/config/limits procesada en 0.0042s
[2025-03-31 16:49:37] [INFO] [logger:65] - Solicitud GET /api/machines desde 127.0.0.1
[2025-03-31 16:49:37] [INFO] [logger:65] - Obteniendo lista de sensores: skip=0, limit=100
[2025-03-31 16:49:37] [INFO] [logger:65] - Respuesta 200 para GET /api/models procesada en 0.0119s
[2025-03-31 16:49:37] [INFO] [logger:65] - Respuesta 200 para GET /api/sensors procesada en 0.0114s
[2025-03-31 16:49:37] [INFO] [logger:65] - Solicitud GET /api/models desde 127.0.0.1
[2025-03-31 16:49:37] [INFO] [logger:65] - Respuesta 200 para GET /api/machines procesada en 0.0105s
[2025-03-31 16:49:37] [INFO] [logger:65] - Solicitud GET /api/sensors desde 127.0.0.1
[2025-03-31 16:49:37] [INFO] [logger:65] - Respuesta 200 para GET /api/models procesada en 0.0122s
[2025-03-31 16:49:37] [INFO] [logger:65] - Obteniendo lista de sensores: skip=0, limit=100
[2025-03-31 16:49:37] [INFO] [logger:65] - Solicitud GET /api/models desde 127.0.0.1
[2025-03-31 16:49:37] [INFO] [logger:65] - Respuesta 200 para GET /api/sensors procesada en 0.0100s
[2025-03-31 16:49:37] [INFO] [logger:65] - Respuesta 200 para GET /api/models procesada en 0.0067s
[2025-03-31 16:49:37] [INFO] [logger:65] - Solicitud GET /api/sensors desde 127.0.0.1
[2025-03-31 16:49:37] [INFO] [logger:65] - Obteniendo lista de sensores: skip=0, limit=100
[2025-03-31 16:49:37] [INFO] [logger:65] - Respuesta 200 para GET /api/sensors procesada en 0.0041s
[2025-03-31 16:49:57] [INFO] [logger:65] - Solicitud POST /api/machines desde 127.0.0.1
[2025-03-31 16:49:57] [ERROR] [logger:50] - ERROR: name 'Machine' is not defined
CONTEXTO: Error al crear máquina
TRACEBACK: Traceback (most recent call last):
  File "C:\Users\LENOVO\Desktop\PdM-Manager\app\main.py", line 1922, in create_machine_endpoint
    machine = Machine(
              ^^^^^^^
NameError: name 'Machine' is not defined

[2025-03-31 16:49:57] [ERROR] [logger:50] - ERROR: 
CONTEXTO: {'endpoint': '/api/machines', 'método': 'POST'}
TRACEBACK: Traceback (most recent call last):
  File "C:\Users\LENOVO\Desktop\PdM-Manager\app\main.py", line 1922, in create_machine_endpoint
    machine = Machine(
              ^^^^^^^
NameError: name 'Machine' is not defined

During handling of the above exception, another exception occurred:

Traceback (most recent call last):
  File "C:\Users\LENOVO\Desktop\PdM-Manager\venv\Lib\site-packages\starlette\middleware\exceptions.py", line 68, in __call__
    await self.app(scope, receive, sender)
  File "C:\Users\LENOVO\Desktop\PdM-Manager\venv\Lib\site-packages\fastapi\middleware\asyncexitstack.py", line 20, in __call__
    raise e
  File "C:\Users\LENOVO\Desktop\PdM-Manager\venv\Lib\site-packages\fastapi\middleware\asyncexitstack.py", line 17, in __call__
    await self.app(scope, receive, send)
  File "C:\Users\LENOVO\Desktop\PdM-Manager\venv\Lib\site-packages\starlette\routing.py", line 718, in __call__
    await route.handle(scope, receive, send)
  File "C:\Users\LENOVO\Desktop\PdM-Manager\venv\Lib\site-packages\starlette\routing.py", line 276, in handle
    await self.app(scope, receive, send)
  File "C:\Users\LENOVO\Desktop\PdM-Manager\venv\Lib\site-packages\starlette\routing.py", line 66, in app
    response = await func(request)
               ^^^^^^^^^^^^^^^^^^^
  File "C:\Users\LENOVO\Desktop\PdM-Manager\venv\Lib\site-packages\fastapi\routing.py", line 274, in app
    raw_response = await run_endpoint_function(
                   ^^^^^^^^^^^^^^^^^^^^^^^^^^^^
  File "C:\Users\LENOVO\Desktop\PdM-Manager\venv\Lib\site-packages\fastapi\routing.py", line 191, in run_endpoint_function
    return await dependant.call(**values)
           ^^^^^^^^^^^^^^^^^^^^^^^^^^^^^^
  File "C:\Users\LENOVO\Desktop\PdM-Manager\app\main.py", line 1939, in create_machine_endpoint
    raise HTTPException(status_code=500, detail=str(e))
fastapi.exceptions.HTTPException

[2025-03-31 16:49:57] [INFO] [logger:65] - Respuesta 500 para POST /api/machines procesada en 0.0086s
[2025-03-31 16:49:58] [INFO] [logger:65] - Solicitud POST /api/machines desde 127.0.0.1
[2025-03-31 16:49:58] [ERROR] [logger:50] - ERROR: name 'Machine' is not defined
CONTEXTO: Error al crear máquina
TRACEBACK: Traceback (most recent call last):
  File "C:\Users\LENOVO\Desktop\PdM-Manager\app\main.py", line 1922, in create_machine_endpoint
    machine = Machine(
              ^^^^^^^
NameError: name 'Machine' is not defined

[2025-03-31 16:49:58] [ERROR] [logger:50] - ERROR: 
CONTEXTO: {'endpoint': '/api/machines', 'método': 'POST'}
TRACEBACK: Traceback (most recent call last):
  File "C:\Users\LENOVO\Desktop\PdM-Manager\app\main.py", line 1922, in create_machine_endpoint
    machine = Machine(
              ^^^^^^^
NameError: name 'Machine' is not defined

During handling of the above exception, another exception occurred:

Traceback (most recent call last):
  File "C:\Users\LENOVO\Desktop\PdM-Manager\venv\Lib\site-packages\starlette\middleware\exceptions.py", line 68, in __call__
    await self.app(scope, receive, sender)
  File "C:\Users\LENOVO\Desktop\PdM-Manager\venv\Lib\site-packages\fastapi\middleware\asyncexitstack.py", line 20, in __call__
    raise e
  File "C:\Users\LENOVO\Desktop\PdM-Manager\venv\Lib\site-packages\fastapi\middleware\asyncexitstack.py", line 17, in __call__
    await self.app(scope, receive, send)
  File "C:\Users\LENOVO\Desktop\PdM-Manager\venv\Lib\site-packages\starlette\routing.py", line 718, in __call__
    await route.handle(scope, receive, send)
  File "C:\Users\LENOVO\Desktop\PdM-Manager\venv\Lib\site-packages\starlette\routing.py", line 276, in handle
    await self.app(scope, receive, send)
  File "C:\Users\LENOVO\Desktop\PdM-Manager\venv\Lib\site-packages\starlette\routing.py", line 66, in app
    response = await func(request)
               ^^^^^^^^^^^^^^^^^^^
  File "C:\Users\LENOVO\Desktop\PdM-Manager\venv\Lib\site-packages\fastapi\routing.py", line 274, in app
    raw_response = await run_endpoint_function(
                   ^^^^^^^^^^^^^^^^^^^^^^^^^^^^
  File "C:\Users\LENOVO\Desktop\PdM-Manager\venv\Lib\site-packages\fastapi\routing.py", line 191, in run_endpoint_function
    return await dependant.call(**values)
           ^^^^^^^^^^^^^^^^^^^^^^^^^^^^^^
  File "C:\Users\LENOVO\Desktop\PdM-Manager\app\main.py", line 1939, in create_machine_endpoint
    raise HTTPException(status_code=500, detail=str(e))
fastapi.exceptions.HTTPException

[2025-03-31 16:49:58] [INFO] [logger:65] - Respuesta 500 para POST /api/machines procesada en 0.0069s
[2025-03-31 16:49:59] [INFO] [logger:65] - Solicitud POST /api/machines desde 127.0.0.1
[2025-03-31 16:49:59] [ERROR] [logger:50] - ERROR: name 'Machine' is not defined
CONTEXTO: Error al crear máquina
TRACEBACK: Traceback (most recent call last):
  File "C:\Users\LENOVO\Desktop\PdM-Manager\app\main.py", line 1922, in create_machine_endpoint
    machine = Machine(
              ^^^^^^^
NameError: name 'Machine' is not defined

[2025-03-31 16:49:59] [ERROR] [logger:50] - ERROR: 
CONTEXTO: {'endpoint': '/api/machines', 'método': 'POST'}
TRACEBACK: Traceback (most recent call last):
  File "C:\Users\LENOVO\Desktop\PdM-Manager\app\main.py", line 1922, in create_machine_endpoint
    machine = Machine(
              ^^^^^^^
NameError: name 'Machine' is not defined

During handling of the above exception, another exception occurred:

Traceback (most recent call last):
  File "C:\Users\LENOVO\Desktop\PdM-Manager\venv\Lib\site-packages\starlette\middleware\exceptions.py", line 68, in __call__
    await self.app(scope, receive, sender)
  File "C:\Users\LENOVO\Desktop\PdM-Manager\venv\Lib\site-packages\fastapi\middleware\asyncexitstack.py", line 20, in __call__
    raise e
  File "C:\Users\LENOVO\Desktop\PdM-Manager\venv\Lib\site-packages\fastapi\middleware\asyncexitstack.py", line 17, in __call__
    await self.app(scope, receive, send)
  File "C:\Users\LENOVO\Desktop\PdM-Manager\venv\Lib\site-packages\starlette\routing.py", line 718, in __call__
    await route.handle(scope, receive, send)
  File "C:\Users\LENOVO\Desktop\PdM-Manager\venv\Lib\site-packages\starlette\routing.py", line 276, in handle
    await self.app(scope, receive, send)
  File "C:\Users\LENOVO\Desktop\PdM-Manager\venv\Lib\site-packages\starlette\routing.py", line 66, in app
    response = await func(request)
               ^^^^^^^^^^^^^^^^^^^
  File "C:\Users\LENOVO\Desktop\PdM-Manager\venv\Lib\site-packages\fastapi\routing.py", line 274, in app
    raw_response = await run_endpoint_function(
                   ^^^^^^^^^^^^^^^^^^^^^^^^^^^^
  File "C:\Users\LENOVO\Desktop\PdM-Manager\venv\Lib\site-packages\fastapi\routing.py", line 191, in run_endpoint_function
    return await dependant.call(**values)
           ^^^^^^^^^^^^^^^^^^^^^^^^^^^^^^
  File "C:\Users\LENOVO\Desktop\PdM-Manager\app\main.py", line 1939, in create_machine_endpoint
    raise HTTPException(status_code=500, detail=str(e))
fastapi.exceptions.HTTPException

[2025-03-31 16:49:59] [INFO] [logger:65] - Respuesta 500 para POST /api/machines procesada en 0.0104s
[2025-03-31 16:49:59] [INFO] [logger:65] - Solicitud POST /api/machines desde 127.0.0.1
[2025-03-31 16:49:59] [ERROR] [logger:50] - ERROR: name 'Machine' is not defined
CONTEXTO: Error al crear máquina
TRACEBACK: Traceback (most recent call last):
  File "C:\Users\LENOVO\Desktop\PdM-Manager\app\main.py", line 1922, in create_machine_endpoint
    machine = Machine(
              ^^^^^^^
NameError: name 'Machine' is not defined

[2025-03-31 16:49:59] [ERROR] [logger:50] - ERROR: 
CONTEXTO: {'endpoint': '/api/machines', 'método': 'POST'}
TRACEBACK: Traceback (most recent call last):
  File "C:\Users\LENOVO\Desktop\PdM-Manager\app\main.py", line 1922, in create_machine_endpoint
    machine = Machine(
              ^^^^^^^
NameError: name 'Machine' is not defined

During handling of the above exception, another exception occurred:

Traceback (most recent call last):
  File "C:\Users\LENOVO\Desktop\PdM-Manager\venv\Lib\site-packages\starlette\middleware\exceptions.py", line 68, in __call__
    await self.app(scope, receive, sender)
  File "C:\Users\LENOVO\Desktop\PdM-Manager\venv\Lib\site-packages\fastapi\middleware\asyncexitstack.py", line 20, in __call__
    raise e
  File "C:\Users\LENOVO\Desktop\PdM-Manager\venv\Lib\site-packages\fastapi\middleware\asyncexitstack.py", line 17, in __call__
    await self.app(scope, receive, send)
  File "C:\Users\LENOVO\Desktop\PdM-Manager\venv\Lib\site-packages\starlette\routing.py", line 718, in __call__
    await route.handle(scope, receive, send)
  File "C:\Users\LENOVO\Desktop\PdM-Manager\venv\Lib\site-packages\starlette\routing.py", line 276, in handle
    await self.app(scope, receive, send)
  File "C:\Users\LENOVO\Desktop\PdM-Manager\venv\Lib\site-packages\starlette\routing.py", line 66, in app
    response = await func(request)
               ^^^^^^^^^^^^^^^^^^^
  File "C:\Users\LENOVO\Desktop\PdM-Manager\venv\Lib\site-packages\fastapi\routing.py", line 274, in app
    raw_response = await run_endpoint_function(
                   ^^^^^^^^^^^^^^^^^^^^^^^^^^^^
  File "C:\Users\LENOVO\Desktop\PdM-Manager\venv\Lib\site-packages\fastapi\routing.py", line 191, in run_endpoint_function
    return await dependant.call(**values)
           ^^^^^^^^^^^^^^^^^^^^^^^^^^^^^^
  File "C:\Users\LENOVO\Desktop\PdM-Manager\app\main.py", line 1939, in create_machine_endpoint
    raise HTTPException(status_code=500, detail=str(e))
fastapi.exceptions.HTTPException

[2025-03-31 16:49:59] [INFO] [logger:65] - Respuesta 500 para POST /api/machines procesada en 0.0101s
