[2025-04-04 17:08:59] [INFO] [logger:65] - Modelo cargado correctamente desde: C:\Users\nicol\Documentos\GitHub\PdM-Manager\Modelo\modeloRNN_multiclase_v3_finetuned.h5
[2025-04-04 17:08:59] [INFO] [logger:65] - Escalador cargado correctamente con joblib desde: C:\Users\nicol\Documentos\GitHub\PdM-Manager\Scaler\scaler_RNN_joblib.pkl
[2025-04-04 17:08:59] [INFO] [logger:65] - Límites de vibración ya existentes en la base de datos
[2025-04-04 17:08:59] [INFO] [logger:65] - Valores actuales X: -2.36/2.18/-3.5/3.32
[2025-04-04 17:08:59] [INFO] [logger:65] - Valores actuales Y: 7.18/12.09/5.95/13.32
[2025-04-04 17:08:59] [INFO] [logger:65] - Valores actuales Z: -2.39/1.11/-3.26/1.98
[2025-04-04 17:08:59] [INFO] [logger:65] - Iniciando aplicación PdM-Manager API
[2025-04-04 17:09:26] [INFO] [logger:65] - Solicitud GET / desde 127.0.0.1
[2025-04-04 17:09:26] [INFO] [logger:65] - Respuesta 200 para GET / procesada en 0.2190s
[2025-04-04 17:09:26] [INFO] [logger:65] - Solicitud GET /static/css/style.css desde 127.0.0.1
[2025-04-04 17:09:26] [INFO] [logger:65] - Respuesta 304 para GET /static/css/style.css procesada en 0.0020s
[2025-04-04 17:09:26] [INFO] [logger:65] - Solicitud GET /static/js/utils.js desde 127.0.0.1
[2025-04-04 17:09:26] [INFO] [logger:65] - Respuesta 304 para GET /static/js/utils.js procesada en 0.0020s
[2025-04-04 17:09:26] [INFO] [logger:65] - Solicitud GET /static/js/app-logger.js desde 127.0.0.1
[2025-04-04 17:09:26] [INFO] [logger:65] - Respuesta 304 para GET /static/js/app-logger.js procesada en 0.0030s
[2025-04-04 17:09:26] [INFO] [logger:65] - Solicitud GET /static/js/navigation.js desde 127.0.0.1
[2025-04-04 17:09:26] [INFO] [logger:65] - Respuesta 304 para GET /static/js/navigation.js procesada en 0.0030s
[2025-04-04 17:09:26] [INFO] [logger:65] - Solicitud GET /static/js/realtime-updates.js desde 127.0.0.1
[2025-04-04 17:09:26] [INFO] [logger:65] - Solicitud GET /static/js/charts.js desde 127.0.0.1
[2025-04-04 17:09:26] [INFO] [logger:65] - Solicitud GET /static/js/logs-ui.js desde 127.0.0.1
[2025-04-04 17:09:26] [INFO] [logger:65] - Solicitud GET /static/js/config.js desde 127.0.0.1
[2025-04-04 17:09:26] [INFO] [logger:65] - Solicitud GET /static/js/app.js desde 127.0.0.1
[2025-04-04 17:09:26] [INFO] [logger:65] - Solicitud GET /static/js/dashboard.js desde 127.0.0.1
[2025-04-04 17:09:26] [INFO] [logger:65] - Respuesta 200 para GET /static/js/realtime-updates.js procesada en 0.0150s
[2025-04-04 17:09:26] [INFO] [logger:65] - Respuesta 304 para GET /static/js/charts.js procesada en 0.0130s
[2025-04-04 17:09:26] [INFO] [logger:65] - Respuesta 200 para GET /static/js/config.js procesada en 0.0110s
[2025-04-04 17:09:26] [INFO] [logger:65] - Respuesta 304 para GET /static/js/logs-ui.js procesada en 0.0140s
[2025-04-04 17:09:26] [INFO] [logger:65] - Respuesta 200 para GET /static/js/app.js procesada en 0.0150s
[2025-04-04 17:09:26] [INFO] [logger:65] - Respuesta 200 para GET /static/js/dashboard.js procesada en 0.0150s
[2025-04-04 17:09:27] [INFO] [logger:65] - Solicitud GET /static/favicon.ico desde 127.0.0.1
[2025-04-04 17:09:27] [INFO] [logger:65] - Respuesta 304 para GET /static/favicon.ico procesada en 0.0030s
[2025-04-04 17:09:31] [INFO] [logger:65] - Solicitud GET /api/sensors desde 127.0.0.1
[2025-04-04 17:09:31] [INFO] [logger:65] - Solicitud GET /api/config/limits desde 127.0.0.1
[2025-04-04 17:09:31] [INFO] [logger:65] - Solicitud GET /api/models desde 127.0.0.1
[2025-04-04 17:09:31] [INFO] [logger:65] - Respuesta 404 para GET /api/config/limits procesada en 0.0030s
[2025-04-04 17:09:31] [INFO] [logger:65] - Obteniendo lista de sensores: skip=0, limit=100
[2025-04-04 17:09:31] [INFO] [logger:65] - Respuesta 200 para GET /api/sensors procesada en 0.0250s
[2025-04-04 17:09:31] [INFO] [logger:65] - Solicitud GET /api/sensors desde 127.0.0.1
[2025-04-04 17:09:31] [INFO] [logger:65] - Obteniendo lista de sensores: skip=0, limit=100
[2025-04-04 17:09:31] [INFO] [logger:65] - Respuesta 200 para GET /api/sensors procesada en 0.0060s
[2025-04-04 17:09:31] [INFO] [logger:65] - Solicitud GET /api/machines desde 127.0.0.1
[2025-04-04 17:09:31] [INFO] [logger:65] - Respuesta 200 para GET /api/machines procesada en 0.0030s
[2025-04-04 17:09:31] [INFO] [logger:65] - Respuesta 200 para GET /api/models procesada en 0.1580s
[2025-04-04 17:09:31] [INFO] [logger:65] - Solicitud GET /api/models desde 127.0.0.1
[2025-04-04 17:09:31] [INFO] [logger:65] - Solicitud GET /api/sensors desde 127.0.0.1
[2025-04-04 17:09:31] [INFO] [logger:65] - Respuesta 200 para GET /api/models procesada en 0.0080s
[2025-04-04 17:09:31] [INFO] [logger:65] - Obteniendo lista de sensores: skip=0, limit=100
[2025-04-04 17:09:31] [INFO] [logger:65] - Respuesta 200 para GET /api/sensors procesada en 0.0110s
[2025-04-04 17:09:31] [INFO] [logger:65] - Solicitud GET /api/models desde 127.0.0.1
[2025-04-04 17:09:31] [INFO] [logger:65] - Respuesta 200 para GET /api/models procesada en 0.0100s
[2025-04-04 17:16:32] [INFO] [logger:65] - Modelo cargado correctamente desde: C:\Users\nicol\Documentos\GitHub\PdM-Manager\Modelo\modeloRNN_multiclase_v3_finetuned.h5
[2025-04-04 17:16:32] [INFO] [logger:65] - Escalador cargado correctamente con joblib desde: C:\Users\nicol\Documentos\GitHub\PdM-Manager\Scaler\scaler_RNN_joblib.pkl
[2025-04-04 17:16:32] [INFO] [logger:65] - Límites de vibración ya existentes en la base de datos
[2025-04-04 17:16:32] [INFO] [logger:65] - Valores actuales X: -2.36/2.18/-3.5/3.32
[2025-04-04 17:16:32] [INFO] [logger:65] - Valores actuales Y: 7.18/12.09/5.95/13.32
[2025-04-04 17:16:32] [INFO] [logger:65] - Valores actuales Z: -2.39/1.11/-3.26/1.98
[2025-04-04 17:16:32] [INFO] [logger:65] - Iniciando aplicación PdM-Manager API
[2025-04-04 17:16:38] [INFO] [logger:65] - Modelo cargado correctamente desde: C:\Users\nicol\Documentos\GitHub\PdM-Manager\Modelo\modeloRNN_multiclase_v3_finetuned.h5
[2025-04-04 17:16:38] [INFO] [logger:65] - Escalador cargado correctamente con joblib desde: C:\Users\nicol\Documentos\GitHub\PdM-Manager\Scaler\scaler_RNN_joblib.pkl
[2025-04-04 17:16:38] [INFO] [logger:65] - Límites de vibración ya existentes en la base de datos
[2025-04-04 17:16:38] [INFO] [logger:65] - Valores actuales X: -2.36/2.18/-3.5/3.32
[2025-04-04 17:16:38] [INFO] [logger:65] - Valores actuales Y: 7.18/12.09/5.95/13.32
[2025-04-04 17:16:38] [INFO] [logger:65] - Valores actuales Z: -2.39/1.11/-3.26/1.98
[2025-04-04 17:16:38] [INFO] [logger:65] - Iniciando aplicación PdM-Manager API
[2025-04-04 17:16:52] [INFO] [logger:65] - Modelo cargado correctamente desde: C:\Users\nicol\Documentos\GitHub\PdM-Manager\Modelo\modeloRNN_multiclase_v3_finetuned.h5
[2025-04-04 17:16:52] [INFO] [logger:65] - Escalador cargado correctamente con joblib desde: C:\Users\nicol\Documentos\GitHub\PdM-Manager\Scaler\scaler_RNN_joblib.pkl
[2025-04-04 17:16:52] [INFO] [logger:65] - Límites de vibración ya existentes en la base de datos
[2025-04-04 17:16:52] [INFO] [logger:65] - Valores actuales X: -2.36/2.18/-3.5/3.32
[2025-04-04 17:16:52] [INFO] [logger:65] - Valores actuales Y: 7.18/12.09/5.95/13.32
[2025-04-04 17:16:52] [INFO] [logger:65] - Valores actuales Z: -2.39/1.11/-3.26/1.98
[2025-04-04 17:16:52] [INFO] [logger:65] - Iniciando aplicación PdM-Manager API
[2025-04-04 17:17:39] [INFO] [logger:65] - Modelo cargado correctamente desde: C:\Users\nicol\Documentos\GitHub\PdM-Manager\Modelo\modeloRNN_multiclase_v3_finetuned.h5
[2025-04-04 17:17:39] [INFO] [logger:65] - Escalador cargado correctamente con joblib desde: C:\Users\nicol\Documentos\GitHub\PdM-Manager\Scaler\scaler_RNN_joblib.pkl
[2025-04-04 17:17:39] [INFO] [logger:65] - Límites de vibración ya existentes en la base de datos
[2025-04-04 17:17:39] [INFO] [logger:65] - Valores actuales X: -2.36/2.18/-3.5/3.32
[2025-04-04 17:17:39] [INFO] [logger:65] - Valores actuales Y: 7.18/12.09/5.95/13.32
[2025-04-04 17:17:39] [INFO] [logger:65] - Valores actuales Z: -2.39/1.11/-3.26/1.98
[2025-04-04 17:17:39] [INFO] [logger:65] - Iniciando aplicación PdM-Manager API
[2025-04-04 17:18:34] [INFO] [logger:65] - Modelo cargado correctamente desde: C:\Users\nicol\Documentos\GitHub\PdM-Manager\Modelo\modeloRNN_multiclase_v3_finetuned.h5
[2025-04-04 17:18:34] [INFO] [logger:65] - Escalador cargado correctamente con joblib desde: C:\Users\nicol\Documentos\GitHub\PdM-Manager\Scaler\scaler_RNN_joblib.pkl
[2025-04-04 17:18:34] [INFO] [logger:65] - Límites de vibración ya existentes en la base de datos
[2025-04-04 17:18:34] [INFO] [logger:65] - Valores actuales X: -2.36/2.18/-3.5/3.32
[2025-04-04 17:18:34] [INFO] [logger:65] - Valores actuales Y: 7.18/12.09/5.95/13.32
[2025-04-04 17:18:34] [INFO] [logger:65] - Valores actuales Z: -2.39/1.11/-3.26/1.98
[2025-04-04 17:18:34] [INFO] [logger:65] - Iniciando aplicación PdM-Manager API
[2025-04-04 17:19:17] [INFO] [logger:65] - Modelo cargado correctamente desde: C:\Users\nicol\Documentos\GitHub\PdM-Manager\Modelo\modeloRNN_multiclase_v3_finetuned.h5
[2025-04-04 17:19:17] [INFO] [logger:65] - Escalador cargado correctamente con joblib desde: C:\Users\nicol\Documentos\GitHub\PdM-Manager\Scaler\scaler_RNN_joblib.pkl
[2025-04-04 17:19:17] [INFO] [logger:65] - Límites de vibración ya existentes en la base de datos
[2025-04-04 17:19:17] [INFO] [logger:65] - Valores actuales X: -2.36/2.18/-3.5/3.32
[2025-04-04 17:19:17] [INFO] [logger:65] - Valores actuales Y: 7.18/12.09/5.95/13.32
[2025-04-04 17:19:17] [INFO] [logger:65] - Valores actuales Z: -2.39/1.11/-3.26/1.98
[2025-04-04 17:19:17] [INFO] [logger:65] - Iniciando aplicación PdM-Manager API
[2025-04-04 17:19:42] [INFO] [logger:65] - Modelo cargado correctamente desde: C:\Users\nicol\Documentos\GitHub\PdM-Manager\Modelo\modeloRNN_multiclase_v3_finetuned.h5
[2025-04-04 17:19:42] [INFO] [logger:65] - Escalador cargado correctamente con joblib desde: C:\Users\nicol\Documentos\GitHub\PdM-Manager\Scaler\scaler_RNN_joblib.pkl
[2025-04-04 17:19:42] [INFO] [logger:65] - Límites de vibración ya existentes en la base de datos
[2025-04-04 17:19:42] [INFO] [logger:65] - Valores actuales X: -2.36/2.18/-3.5/3.32
[2025-04-04 17:19:42] [INFO] [logger:65] - Valores actuales Y: 7.18/12.09/5.95/13.32
[2025-04-04 17:19:42] [INFO] [logger:65] - Valores actuales Z: -2.39/1.11/-3.26/1.98
[2025-04-04 17:19:42] [INFO] [logger:65] - Iniciando aplicación PdM-Manager API
[2025-04-04 17:20:13] [INFO] [logger:78] - Modelo cargado correctamente desde: C:\Users\nicol\Documentos\GitHub\PdM-Manager\Modelo\modeloRNN_multiclase_v3_finetuned.h5
[2025-04-04 17:20:13] [INFO] [logger:78] - Escalador cargado correctamente con joblib desde: C:\Users\nicol\Documentos\GitHub\PdM-Manager\Scaler\scaler_RNN_joblib.pkl
[2025-04-04 17:20:13] [INFO] [logger:78] - Límites de vibración ya existentes en la base de datos
[2025-04-04 17:20:13] [INFO] [logger:78] - Valores actuales X: -2.36/2.18/-3.5/3.32
[2025-04-04 17:20:13] [INFO] [logger:78] - Valores actuales Y: 7.18/12.09/5.95/13.32
[2025-04-04 17:20:13] [INFO] [logger:78] - Valores actuales Z: -2.39/1.11/-3.26/1.98
[2025-04-04 17:20:13] [INFO] [logger:78] - Iniciando aplicación PdM-Manager API
[2025-04-04 17:20:57] [INFO] [logger:78] - Modelo cargado correctamente desde: C:\Users\nicol\Documentos\GitHub\PdM-Manager\Modelo\modeloRNN_multiclase_v3_finetuned.h5
[2025-04-04 17:20:57] [INFO] [logger:78] - Escalador cargado correctamente con joblib desde: C:\Users\nicol\Documentos\GitHub\PdM-Manager\Scaler\scaler_RNN_joblib.pkl
[2025-04-04 17:20:57] [INFO] [logger:78] - Límites de vibración ya existentes en la base de datos
[2025-04-04 17:20:57] [INFO] [logger:78] - Valores actuales X: -2.36/2.18/-3.5/3.32
[2025-04-04 17:20:57] [INFO] [logger:78] - Valores actuales Y: 7.18/12.09/5.95/13.32
[2025-04-04 17:20:57] [INFO] [logger:78] - Valores actuales Z: -2.39/1.11/-3.26/1.98
[2025-04-04 17:20:57] [INFO] [logger:78] - Iniciando aplicación PdM-Manager API
[2025-04-04 17:21:30] [INFO] [logger:78] - Modelo cargado correctamente desde: C:\Users\nicol\Documentos\GitHub\PdM-Manager\Modelo\modeloRNN_multiclase_v3_finetuned.h5
[2025-04-04 17:21:30] [INFO] [logger:78] - Escalador cargado correctamente con joblib desde: C:\Users\nicol\Documentos\GitHub\PdM-Manager\Scaler\scaler_RNN_joblib.pkl
[2025-04-04 17:21:30] [INFO] [logger:78] - Límites de vibración ya existentes en la base de datos
[2025-04-04 17:21:30] [INFO] [logger:78] - Valores actuales X: -2.36/2.18/-3.5/3.32
[2025-04-04 17:21:30] [INFO] [logger:78] - Valores actuales Y: 7.18/12.09/5.95/13.32
[2025-04-04 17:21:30] [INFO] [logger:78] - Valores actuales Z: -2.39/1.11/-3.26/1.98
[2025-04-04 17:21:30] [INFO] [logger:78] - Iniciando aplicación PdM-Manager API
[2025-04-04 17:22:40] [INFO] [logger:78] - Solicitud GET / desde 127.0.0.1
[2025-04-04 17:22:40] [INFO] [logger:78] - Respuesta 200 para GET / procesada en 0.0601s
[2025-04-04 17:22:41] [INFO] [logger:78] - Solicitud GET /static/js/dashboard.js desde 127.0.0.1
[2025-04-04 17:22:41] [INFO] [logger:78] - Respuesta 304 para GET /static/js/dashboard.js procesada en 0.0030s
[2025-04-04 17:25:20] [INFO] [logger:78] - Modelo cargado correctamente desde: C:\Users\nicol\Documentos\GitHub\PdM-Manager\Modelo\modeloRNN_multiclase_v3_finetuned.h5
[2025-04-04 17:25:20] [INFO] [logger:78] - Escalador cargado correctamente con joblib desde: C:\Users\nicol\Documentos\GitHub\PdM-Manager\Scaler\scaler_RNN_joblib.pkl
[2025-04-04 17:25:20] [INFO] [logger:78] - Límites de vibración ya existentes en la base de datos
[2025-04-04 17:25:20] [INFO] [logger:78] - Valores actuales X: -2.36/2.18/-3.5/3.32
[2025-04-04 17:25:20] [INFO] [logger:78] - Valores actuales Y: 7.18/12.09/5.95/13.32
[2025-04-04 17:25:20] [INFO] [logger:78] - Valores actuales Z: -2.39/1.11/-3.26/1.98
[2025-04-04 17:25:20] [INFO] [logger:78] - Iniciando aplicación PdM-Manager API
[2025-04-04 17:26:06] [INFO] [logger:78] - Modelo cargado correctamente desde: C:\Users\nicol\Documentos\GitHub\PdM-Manager\Modelo\modeloRNN_multiclase_v3_finetuned.h5
[2025-04-04 17:26:06] [INFO] [logger:78] - Escalador cargado correctamente con joblib desde: C:\Users\nicol\Documentos\GitHub\PdM-Manager\Scaler\scaler_RNN_joblib.pkl
[2025-04-04 17:26:06] [INFO] [logger:78] - Límites de vibración ya existentes en la base de datos
[2025-04-04 17:26:06] [INFO] [logger:78] - Valores actuales X: -2.36/2.18/-3.5/3.32
[2025-04-04 17:26:06] [INFO] [logger:78] - Valores actuales Y: 7.18/12.09/5.95/13.32
[2025-04-04 17:26:06] [INFO] [logger:78] - Valores actuales Z: -2.39/1.11/-3.26/1.98
[2025-04-04 17:26:06] [INFO] [logger:78] - Iniciando aplicación PdM-Manager API
[2025-04-04 17:26:32] [INFO] [logger:78] - Modelo cargado correctamente desde: C:\Users\nicol\Documentos\GitHub\PdM-Manager\Modelo\modeloRNN_multiclase_v3_finetuned.h5
[2025-04-04 17:26:32] [INFO] [logger:78] - Escalador cargado correctamente con joblib desde: C:\Users\nicol\Documentos\GitHub\PdM-Manager\Scaler\scaler_RNN_joblib.pkl
[2025-04-04 17:26:32] [INFO] [logger:78] - Límites de vibración ya existentes en la base de datos
[2025-04-04 17:26:32] [INFO] [logger:78] - Valores actuales X: -2.36/2.18/-3.5/3.32
[2025-04-04 17:26:32] [INFO] [logger:78] - Valores actuales Y: 7.18/12.09/5.95/13.32
[2025-04-04 17:26:32] [INFO] [logger:78] - Valores actuales Z: -2.39/1.11/-3.26/1.98
[2025-04-04 17:26:32] [INFO] [logger:78] - Iniciando aplicación PdM-Manager API
[2025-04-04 17:26:35] [INFO] [logger:78] - Solicitud GET /api/sensors desde 127.0.0.1
[2025-04-04 17:26:35] [INFO] [logger:78] - Solicitud GET /api/models desde 127.0.0.1
[2025-04-04 17:26:35] [INFO] [logger:78] - Solicitud GET /api/config/limits desde 127.0.0.1
[2025-04-04 17:26:35] [INFO] [logger:78] - Obteniendo lista de sensores: skip=0, limit=100
[2025-04-04 17:26:35] [INFO] [logger:78] - Respuesta 404 para GET /api/config/limits procesada en 0.0050s
[2025-04-04 17:26:35] [INFO] [logger:78] - Respuesta 200 para GET /api/sensors procesada en 0.0130s
[2025-04-04 17:26:35] [INFO] [logger:78] - Solicitud GET /api/sensors desde 127.0.0.1
[2025-04-04 17:26:35] [INFO] [logger:78] - Obteniendo lista de sensores: skip=0, limit=100
[2025-04-04 17:26:35] [INFO] [logger:78] - Solicitud GET /api/machines desde 127.0.0.1
[2025-04-04 17:26:35] [INFO] [logger:78] - Respuesta 200 para GET /api/sensors procesada en 0.0050s
[2025-04-04 17:26:35] [INFO] [logger:78] - Respuesta 200 para GET /api/machines procesada en 0.0060s
[2025-04-04 17:26:35] [INFO] [logger:78] - Respuesta 200 para GET /api/models procesada en 0.0719s
[2025-04-04 17:26:35] [INFO] [logger:78] - Solicitud GET /api/models desde 127.0.0.1
[2025-04-04 17:26:35] [INFO] [logger:78] - Solicitud GET /api/sensors desde 127.0.0.1
[2025-04-04 17:26:35] [INFO] [logger:78] - Obteniendo lista de sensores: skip=0, limit=100
[2025-04-04 17:26:35] [INFO] [logger:78] - Respuesta 200 para GET /api/sensors procesada en 0.0030s
[2025-04-04 17:26:35] [INFO] [logger:78] - Respuesta 200 para GET /api/models procesada en 0.0060s
[2025-04-04 17:26:35] [INFO] [logger:78] - Solicitud GET /api/models desde 127.0.0.1
[2025-04-04 17:26:35] [INFO] [logger:78] - Respuesta 200 para GET /api/models procesada en 0.0050s
[2025-04-04 17:31:22] [INFO] [logger:78] - Modelo cargado correctamente desde: C:\Users\nicol\Documentos\GitHub\PdM-Manager\Modelo\modeloRNN_multiclase_v3_finetuned.h5
[2025-04-04 17:31:22] [INFO] [logger:78] - Escalador cargado correctamente con joblib desde: C:\Users\nicol\Documentos\GitHub\PdM-Manager\Scaler\scaler_RNN_joblib.pkl
[2025-04-04 17:31:23] [INFO] [logger:78] - Límites de vibración ya existentes en la base de datos
[2025-04-04 17:31:23] [INFO] [logger:78] - Valores actuales X: -2.36/2.18/-3.5/3.32
[2025-04-04 17:31:23] [INFO] [logger:78] - Valores actuales Y: 7.18/12.09/5.95/13.32
[2025-04-04 17:31:23] [INFO] [logger:78] - Valores actuales Z: -2.39/1.11/-3.26/1.98
[2025-04-04 17:31:23] [INFO] [logger:78] - Iniciando aplicación PdM-Manager API
[2025-04-04 17:39:55] [INFO] [logger:78] - Modelo cargado correctamente desde: C:\Users\nicol\Documentos\GitHub\PdM-Manager\Modelo\modeloRNN_multiclase_v3_finetuned.h5
[2025-04-04 17:39:55] [INFO] [logger:78] - Escalador cargado correctamente con joblib desde: C:\Users\nicol\Documentos\GitHub\PdM-Manager\Scaler\scaler_RNN_joblib.pkl
[2025-04-04 17:39:55] [INFO] [logger:78] - Límites de vibración ya existentes en la base de datos
[2025-04-04 17:39:55] [INFO] [logger:78] - Valores actuales X: -2.36/2.18/-3.5/3.32
[2025-04-04 17:39:55] [INFO] [logger:78] - Valores actuales Y: 7.18/12.09/5.95/13.32
[2025-04-04 17:39:55] [INFO] [logger:78] - Valores actuales Z: -2.39/1.11/-3.26/1.98
[2025-04-04 17:39:55] [INFO] [logger:78] - Iniciando aplicación PdM-Manager API
[2025-04-04 17:47:52] [INFO] [logger:78] - Modelo cargado correctamente desde: C:\Users\nicol\Documentos\GitHub\PdM-Manager\Modelo\modeloRNN_multiclase_v3_finetuned.h5
[2025-04-04 17:47:52] [INFO] [logger:78] - Escalador cargado correctamente con joblib desde: C:\Users\nicol\Documentos\GitHub\PdM-Manager\Scaler\scaler_RNN_joblib.pkl
[2025-04-04 17:47:53] [INFO] [logger:78] - Límites de vibración ya existentes en la base de datos
[2025-04-04 17:47:53] [INFO] [logger:78] - Valores actuales X: -2.36/2.18/-3.5/3.32
[2025-04-04 17:47:53] [INFO] [logger:78] - Valores actuales Y: 7.18/12.09/5.95/13.32
[2025-04-04 17:47:53] [INFO] [logger:78] - Valores actuales Z: -2.39/1.11/-3.26/1.98
[2025-04-04 17:47:53] [INFO] [logger:78] - Iniciando aplicación PdM-Manager API
[2025-04-04 17:47:58] [INFO] [logger:78] - Modelo cargado correctamente desde: C:\Users\nicol\Documentos\GitHub\PdM-Manager\Modelo\modeloRNN_multiclase_v3_finetuned.h5
[2025-04-04 17:47:58] [INFO] [logger:78] - Escalador cargado correctamente con joblib desde: C:\Users\nicol\Documentos\GitHub\PdM-Manager\Scaler\scaler_RNN_joblib.pkl
[2025-04-04 17:47:58] [INFO] [logger:78] - Límites de vibración ya existentes en la base de datos
[2025-04-04 17:47:58] [INFO] [logger:78] - Valores actuales X: -2.36/2.18/-3.5/3.32
[2025-04-04 17:47:58] [INFO] [logger:78] - Valores actuales Y: 7.18/12.09/5.95/13.32
[2025-04-04 17:47:58] [INFO] [logger:78] - Valores actuales Z: -2.39/1.11/-3.26/1.98
[2025-04-04 17:47:58] [INFO] [logger:78] - Iniciando aplicación PdM-Manager API
[2025-04-04 17:48:24] [INFO] [logger:78] - Modelo cargado correctamente desde: C:\Users\nicol\Documentos\GitHub\PdM-Manager\Modelo\modeloRNN_multiclase_v3_finetuned.h5
[2025-04-04 17:48:24] [INFO] [logger:78] - Escalador cargado correctamente con joblib desde: C:\Users\nicol\Documentos\GitHub\PdM-Manager\Scaler\scaler_RNN_joblib.pkl
[2025-04-04 17:48:24] [INFO] [logger:78] - Límites de vibración ya existentes en la base de datos
[2025-04-04 17:48:24] [INFO] [logger:78] - Valores actuales X: -2.36/2.18/-3.5/3.32
[2025-04-04 17:48:24] [INFO] [logger:78] - Valores actuales Y: 7.18/12.09/5.95/13.32
[2025-04-04 17:48:24] [INFO] [logger:78] - Valores actuales Z: -2.39/1.11/-3.26/1.98
[2025-04-04 17:48:24] [INFO] [logger:78] - Iniciando aplicación PdM-Manager API
[2025-04-04 17:49:45] [INFO] [logger:78] - Modelo cargado correctamente desde: C:\Users\nicol\Documentos\GitHub\PdM-Manager\Modelo\modeloRNN_multiclase_v3_finetuned.h5
[2025-04-04 17:49:45] [INFO] [logger:78] - Escalador cargado correctamente con joblib desde: C:\Users\nicol\Documentos\GitHub\PdM-Manager\Scaler\scaler_RNN_joblib.pkl
[2025-04-04 17:49:45] [INFO] [logger:78] - Límites de vibración ya existentes en la base de datos
[2025-04-04 17:49:45] [INFO] [logger:78] - Valores actuales X: -2.36/2.18/-3.5/3.32
[2025-04-04 17:49:45] [INFO] [logger:78] - Valores actuales Y: 7.18/12.09/5.95/13.32
[2025-04-04 17:49:45] [INFO] [logger:78] - Valores actuales Z: -2.39/1.11/-3.26/1.98
[2025-04-04 17:49:45] [INFO] [logger:78] - Iniciando aplicación PdM-Manager API
[2025-04-04 18:10:05] [INFO] [logger:78] - Iniciando aplicación...
[2025-04-04 18:10:05] [INFO] [logger:78] - Modelo cargado correctamente desde: C:\Users\nicol\Documentos\GitHub\PdM-Manager\Modelo\modeloRNN_multiclase_v3_finetuned.h5
[2025-04-04 18:10:05] [INFO] [logger:78] - Escalador cargado correctamente con joblib desde: C:\Users\nicol\Documentos\GitHub\PdM-Manager\Scaler\scaler_RNN_joblib.pkl
[2025-04-04 18:12:33] [INFO] [logger:78] - Archivo de modelo guardado en: C:\Users\nicol\Documentos\GitHub\PdM-Manager\Modelo\modeloRNN_multiclase_v3_finetuned_7025d4a5.h5
[2025-04-04 18:12:33] [INFO] [logger:78] - Archivo de escalador guardado en: C:\Users\nicol\Documentos\GitHub\PdM-Manager\Scaler\scaler_RNN_joblib_303f7396.pkl
[2025-04-04 18:12:33] [INFO] [logger:78] - Archivo de modelo guardado en: C:\Users\nicol\Documentos\GitHub\PdM-Manager\Modelo\modeloRNN_multiclase_v3_finetuned_7025d4a5.h5
[2025-04-04 18:12:33] [INFO] [logger:78] - Archivo de escalador guardado en: C:\Users\nicol\Documentos\GitHub\PdM-Manager\Scaler\scaler_RNN_joblib_303f7396.pkl
[2025-04-04 18:18:30] [ERROR] [logger:63] - ERROR: 'sensor_id'
CONTEXTO: Error al obtener máquinas
TRACEBACK: Traceback (most recent call last):
  File "C:\Users\nicol\Documentos\GitHub\PdM-Manager\app\routers\machines.py", line 29, in get_machines_endpoint
    machines = crud.get_machines_with_status(db, skip=skip, limit=limit)
               ^^^^^^^^^^^^^^^^^^^^^^^^^^^^^^^^^^^^^^^^^^^^^^^^^^^^^^^^^
  File "C:\Users\nicol\Documentos\GitHub\PdM-Manager\app\crud.py", line 272, in get_machines_with_status
    sensor = db.query(Sensor).filter(Sensor.sensor_id == machine["sensor_id"]).first()
                                                         ~~~~~~~^^^^^^^^^^^^^
KeyError: 'sensor_id'

[2025-04-04 18:18:31] [ERROR] [logger:63] - ERROR: 
CONTEXTO: {'endpoint': '/api/machines/', 'método': 'GET'}
TRACEBACK: Traceback (most recent call last):
  File "C:\Users\nicol\Documentos\GitHub\PdM-Manager\app\routers\machines.py", line 29, in get_machines_endpoint
    machines = crud.get_machines_with_status(db, skip=skip, limit=limit)
               ^^^^^^^^^^^^^^^^^^^^^^^^^^^^^^^^^^^^^^^^^^^^^^^^^^^^^^^^^
  File "C:\Users\nicol\Documentos\GitHub\PdM-Manager\app\crud.py", line 272, in get_machines_with_status
    sensor = db.query(Sensor).filter(Sensor.sensor_id == machine["sensor_id"]).first()
                                                         ~~~~~~~^^^^^^^^^^^^^
KeyError: 'sensor_id'

During handling of the above exception, another exception occurred:

Traceback (most recent call last):
  File "C:\Users\nicol\AppData\Local\Packages\PythonSoftwareFoundation.Python.3.12_qbz5n2kfra8p0\LocalCache\local-packages\Python312\site-packages\starlette\middleware\exceptions.py", line 68, in __call__
    await self.app(scope, receive, sender)
  File "C:\Users\nicol\AppData\Local\Packages\PythonSoftwareFoundation.Python.3.12_qbz5n2kfra8p0\LocalCache\local-packages\Python312\site-packages\fastapi\middleware\asyncexitstack.py", line 20, in __call__
    raise e
  File "C:\Users\nicol\AppData\Local\Packages\PythonSoftwareFoundation.Python.3.12_qbz5n2kfra8p0\LocalCache\local-packages\Python312\site-packages\fastapi\middleware\asyncexitstack.py", line 17, in __call__
    await self.app(scope, receive, send)
  File "C:\Users\nicol\AppData\Local\Packages\PythonSoftwareFoundation.Python.3.12_qbz5n2kfra8p0\LocalCache\local-packages\Python312\site-packages\starlette\routing.py", line 718, in __call__
    await route.handle(scope, receive, send)
  File "C:\Users\nicol\AppData\Local\Packages\PythonSoftwareFoundation.Python.3.12_qbz5n2kfra8p0\LocalCache\local-packages\Python312\site-packages\starlette\routing.py", line 276, in handle
    await self.app(scope, receive, send)
  File "C:\Users\nicol\AppData\Local\Packages\PythonSoftwareFoundation.Python.3.12_qbz5n2kfra8p0\LocalCache\local-packages\Python312\site-packages\starlette\routing.py", line 66, in app
    response = await func(request)
               ^^^^^^^^^^^^^^^^^^^
  File "C:\Users\nicol\AppData\Local\Packages\PythonSoftwareFoundation.Python.3.12_qbz5n2kfra8p0\LocalCache\local-packages\Python312\site-packages\fastapi\routing.py", line 274, in app
    raw_response = await run_endpoint_function(
                   ^^^^^^^^^^^^^^^^^^^^^^^^^^^^
  File "C:\Users\nicol\AppData\Local\Packages\PythonSoftwareFoundation.Python.3.12_qbz5n2kfra8p0\LocalCache\local-packages\Python312\site-packages\fastapi\routing.py", line 193, in run_endpoint_function
    return await run_in_threadpool(dependant.call, **values)
           ^^^^^^^^^^^^^^^^^^^^^^^^^^^^^^^^^^^^^^^^^^^^^^^^^
  File "C:\Users\nicol\AppData\Local\Packages\PythonSoftwareFoundation.Python.3.12_qbz5n2kfra8p0\LocalCache\local-packages\Python312\site-packages\starlette\concurrency.py", line 41, in run_in_threadpool
    return await anyio.to_thread.run_sync(func, *args)
           ^^^^^^^^^^^^^^^^^^^^^^^^^^^^^^^^^^^^^^^^^^^
  File "C:\Users\nicol\AppData\Local\Packages\PythonSoftwareFoundation.Python.3.12_qbz5n2kfra8p0\LocalCache\local-packages\Python312\site-packages\anyio\to_thread.py", line 33, in run_sync
    return await get_asynclib().run_sync_in_worker_thread(
           ^^^^^^^^^^^^^^^^^^^^^^^^^^^^^^^^^^^^^^^^^^^^^^^
  File "C:\Users\nicol\AppData\Local\Packages\PythonSoftwareFoundation.Python.3.12_qbz5n2kfra8p0\LocalCache\local-packages\Python312\site-packages\anyio\_backends\_asyncio.py", line 877, in run_sync_in_worker_thread
    return await future
           ^^^^^^^^^^^^
  File "C:\Users\nicol\AppData\Local\Packages\PythonSoftwareFoundation.Python.3.12_qbz5n2kfra8p0\LocalCache\local-packages\Python312\site-packages\anyio\_backends\_asyncio.py", line 807, in run
    result = context.run(func, *args)
             ^^^^^^^^^^^^^^^^^^^^^^^^
  File "C:\Users\nicol\Documentos\GitHub\PdM-Manager\app\routers\machines.py", line 37, in get_machines_endpoint
    raise HTTPException(status_code=500, detail=str(e))
fastapi.exceptions.HTTPException

[2025-04-04 18:18:31] [ERROR] [logger:63] - ERROR: create_response() got an unexpected keyword argument 'error'
CONTEXTO: {'endpoint': '/api/machines/', 'método': 'GET', 'query_params': '', 'client': '127.0.0.1'}
TRACEBACK: Traceback (most recent call last):
  File "C:\Users\nicol\Documentos\GitHub\PdM-Manager\app\routers\machines.py", line 29, in get_machines_endpoint
    machines = crud.get_machines_with_status(db, skip=skip, limit=limit)
               ^^^^^^^^^^^^^^^^^^^^^^^^^^^^^^^^^^^^^^^^^^^^^^^^^^^^^^^^^
  File "C:\Users\nicol\Documentos\GitHub\PdM-Manager\app\crud.py", line 272, in get_machines_with_status
    sensor = db.query(Sensor).filter(Sensor.sensor_id == machine["sensor_id"]).first()
                                                         ~~~~~~~^^^^^^^^^^^^^
KeyError: 'sensor_id'

During handling of the above exception, another exception occurred:

Traceback (most recent call last):
  File "C:\Users\nicol\AppData\Local\Packages\PythonSoftwareFoundation.Python.3.12_qbz5n2kfra8p0\LocalCache\local-packages\Python312\site-packages\starlette\middleware\exceptions.py", line 68, in __call__
    await self.app(scope, receive, sender)
  File "C:\Users\nicol\AppData\Local\Packages\PythonSoftwareFoundation.Python.3.12_qbz5n2kfra8p0\LocalCache\local-packages\Python312\site-packages\fastapi\middleware\asyncexitstack.py", line 20, in __call__
    raise e
  File "C:\Users\nicol\AppData\Local\Packages\PythonSoftwareFoundation.Python.3.12_qbz5n2kfra8p0\LocalCache\local-packages\Python312\site-packages\fastapi\middleware\asyncexitstack.py", line 17, in __call__
    await self.app(scope, receive, send)
  File "C:\Users\nicol\AppData\Local\Packages\PythonSoftwareFoundation.Python.3.12_qbz5n2kfra8p0\LocalCache\local-packages\Python312\site-packages\starlette\routing.py", line 718, in __call__
    await route.handle(scope, receive, send)
  File "C:\Users\nicol\AppData\Local\Packages\PythonSoftwareFoundation.Python.3.12_qbz5n2kfra8p0\LocalCache\local-packages\Python312\site-packages\starlette\routing.py", line 276, in handle
    await self.app(scope, receive, send)
  File "C:\Users\nicol\AppData\Local\Packages\PythonSoftwareFoundation.Python.3.12_qbz5n2kfra8p0\LocalCache\local-packages\Python312\site-packages\starlette\routing.py", line 66, in app
    response = await func(request)
               ^^^^^^^^^^^^^^^^^^^
  File "C:\Users\nicol\AppData\Local\Packages\PythonSoftwareFoundation.Python.3.12_qbz5n2kfra8p0\LocalCache\local-packages\Python312\site-packages\fastapi\routing.py", line 274, in app
    raw_response = await run_endpoint_function(
                   ^^^^^^^^^^^^^^^^^^^^^^^^^^^^
  File "C:\Users\nicol\AppData\Local\Packages\PythonSoftwareFoundation.Python.3.12_qbz5n2kfra8p0\LocalCache\local-packages\Python312\site-packages\fastapi\routing.py", line 193, in run_endpoint_function
    return await run_in_threadpool(dependant.call, **values)
           ^^^^^^^^^^^^^^^^^^^^^^^^^^^^^^^^^^^^^^^^^^^^^^^^^
  File "C:\Users\nicol\AppData\Local\Packages\PythonSoftwareFoundation.Python.3.12_qbz5n2kfra8p0\LocalCache\local-packages\Python312\site-packages\starlette\concurrency.py", line 41, in run_in_threadpool
    return await anyio.to_thread.run_sync(func, *args)
           ^^^^^^^^^^^^^^^^^^^^^^^^^^^^^^^^^^^^^^^^^^^
  File "C:\Users\nicol\AppData\Local\Packages\PythonSoftwareFoundation.Python.3.12_qbz5n2kfra8p0\LocalCache\local-packages\Python312\site-packages\anyio\to_thread.py", line 33, in run_sync
    return await get_asynclib().run_sync_in_worker_thread(
           ^^^^^^^^^^^^^^^^^^^^^^^^^^^^^^^^^^^^^^^^^^^^^^^
  File "C:\Users\nicol\AppData\Local\Packages\PythonSoftwareFoundation.Python.3.12_qbz5n2kfra8p0\LocalCache\local-packages\Python312\site-packages\anyio\_backends\_asyncio.py", line 877, in run_sync_in_worker_thread
    return await future
           ^^^^^^^^^^^^
  File "C:\Users\nicol\AppData\Local\Packages\PythonSoftwareFoundation.Python.3.12_qbz5n2kfra8p0\LocalCache\local-packages\Python312\site-packages\anyio\_backends\_asyncio.py", line 807, in run
    result = context.run(func, *args)
             ^^^^^^^^^^^^^^^^^^^^^^^^
  File "C:\Users\nicol\Documentos\GitHub\PdM-Manager\app\routers\machines.py", line 37, in get_machines_endpoint
    raise HTTPException(status_code=500, detail=str(e))
fastapi.exceptions.HTTPException

During handling of the above exception, another exception occurred:

Traceback (most recent call last):
  File "C:\Users\nicol\AppData\Local\Packages\PythonSoftwareFoundation.Python.3.12_qbz5n2kfra8p0\LocalCache\local-packages\Python312\site-packages\starlette\middleware\errors.py", line 162, in __call__
    await self.app(scope, receive, _send)
  File "C:\Users\nicol\AppData\Local\Packages\PythonSoftwareFoundation.Python.3.12_qbz5n2kfra8p0\LocalCache\local-packages\Python312\site-packages\starlette\middleware\cors.py", line 83, in __call__
    await self.app(scope, receive, send)
  File "C:\Users\nicol\AppData\Local\Packages\PythonSoftwareFoundation.Python.3.12_qbz5n2kfra8p0\LocalCache\local-packages\Python312\site-packages\starlette\middleware\exceptions.py", line 88, in __call__
    response = await handler(request, exc)
               ^^^^^^^^^^^^^^^^^^^^^^^^^^^
  File "C:\Users\nicol\Documentos\GitHub\PdM-Manager\app\error_handlers.py", line 92, in http_exception_handler
    content=create_response(
            ^^^^^^^^^^^^^^^^
TypeError: create_response() got an unexpected keyword argument 'error'

[2025-04-04 18:18:41] [ERROR] [logger:63] - ERROR: [{'type': 'int_parsing', 'loc': ('path', 'sensor_id'), 'msg': 'Input should be a valid integer, unable to parse string as an integer', 'input': 'undefined', 'url': 'https://errors.pydantic.dev/2.5/v/int_parsing'}]
CONTEXTO: {'endpoint': '/api/sensors/undefined', 'método': 'DELETE', 'errores': [{'type': 'int_parsing', 'loc': ('path', 'sensor_id'), 'msg': 'Input should be a valid integer, unable to parse string as an integer', 'input': 'undefined', 'url': 'https://errors.pydantic.dev/2.5/v/int_parsing'}]}
TRACEBACK: Traceback (most recent call last):
  File "C:\Users\nicol\AppData\Local\Packages\PythonSoftwareFoundation.Python.3.12_qbz5n2kfra8p0\LocalCache\local-packages\Python312\site-packages\starlette\middleware\exceptions.py", line 68, in __call__
    await self.app(scope, receive, sender)
  File "C:\Users\nicol\AppData\Local\Packages\PythonSoftwareFoundation.Python.3.12_qbz5n2kfra8p0\LocalCache\local-packages\Python312\site-packages\fastapi\middleware\asyncexitstack.py", line 20, in __call__
    raise e
  File "C:\Users\nicol\AppData\Local\Packages\PythonSoftwareFoundation.Python.3.12_qbz5n2kfra8p0\LocalCache\local-packages\Python312\site-packages\fastapi\middleware\asyncexitstack.py", line 17, in __call__
    await self.app(scope, receive, send)
  File "C:\Users\nicol\AppData\Local\Packages\PythonSoftwareFoundation.Python.3.12_qbz5n2kfra8p0\LocalCache\local-packages\Python312\site-packages\starlette\routing.py", line 718, in __call__
    await route.handle(scope, receive, send)
  File "C:\Users\nicol\AppData\Local\Packages\PythonSoftwareFoundation.Python.3.12_qbz5n2kfra8p0\LocalCache\local-packages\Python312\site-packages\starlette\routing.py", line 276, in handle
    await self.app(scope, receive, send)
  File "C:\Users\nicol\AppData\Local\Packages\PythonSoftwareFoundation.Python.3.12_qbz5n2kfra8p0\LocalCache\local-packages\Python312\site-packages\starlette\routing.py", line 66, in app
    response = await func(request)
               ^^^^^^^^^^^^^^^^^^^
  File "C:\Users\nicol\AppData\Local\Packages\PythonSoftwareFoundation.Python.3.12_qbz5n2kfra8p0\LocalCache\local-packages\Python312\site-packages\fastapi\routing.py", line 272, in app
    raise RequestValidationError(_normalize_errors(errors), body=body)
fastapi.exceptions.RequestValidationError: [{'type': 'int_parsing', 'loc': ('path', 'sensor_id'), 'msg': 'Input should be a valid integer, unable to parse string as an integer', 'input': 'undefined', 'url': 'https://errors.pydantic.dev/2.5/v/int_parsing'}]

[2025-04-04 18:18:41] [ERROR] [logger:63] - ERROR: create_response() got an unexpected keyword argument 'error'
CONTEXTO: {'endpoint': '/api/sensors/undefined', 'método': 'DELETE', 'query_params': '', 'client': '127.0.0.1'}
TRACEBACK: Traceback (most recent call last):
  File "C:\Users\nicol\AppData\Local\Packages\PythonSoftwareFoundation.Python.3.12_qbz5n2kfra8p0\LocalCache\local-packages\Python312\site-packages\starlette\middleware\exceptions.py", line 68, in __call__
    await self.app(scope, receive, sender)
  File "C:\Users\nicol\AppData\Local\Packages\PythonSoftwareFoundation.Python.3.12_qbz5n2kfra8p0\LocalCache\local-packages\Python312\site-packages\fastapi\middleware\asyncexitstack.py", line 20, in __call__
    raise e
  File "C:\Users\nicol\AppData\Local\Packages\PythonSoftwareFoundation.Python.3.12_qbz5n2kfra8p0\LocalCache\local-packages\Python312\site-packages\fastapi\middleware\asyncexitstack.py", line 17, in __call__
    await self.app(scope, receive, send)
  File "C:\Users\nicol\AppData\Local\Packages\PythonSoftwareFoundation.Python.3.12_qbz5n2kfra8p0\LocalCache\local-packages\Python312\site-packages\starlette\routing.py", line 718, in __call__
    await route.handle(scope, receive, send)
  File "C:\Users\nicol\AppData\Local\Packages\PythonSoftwareFoundation.Python.3.12_qbz5n2kfra8p0\LocalCache\local-packages\Python312\site-packages\starlette\routing.py", line 276, in handle
    await self.app(scope, receive, send)
  File "C:\Users\nicol\AppData\Local\Packages\PythonSoftwareFoundation.Python.3.12_qbz5n2kfra8p0\LocalCache\local-packages\Python312\site-packages\starlette\routing.py", line 66, in app
    response = await func(request)
               ^^^^^^^^^^^^^^^^^^^
  File "C:\Users\nicol\AppData\Local\Packages\PythonSoftwareFoundation.Python.3.12_qbz5n2kfra8p0\LocalCache\local-packages\Python312\site-packages\fastapi\routing.py", line 272, in app
    raise RequestValidationError(_normalize_errors(errors), body=body)
fastapi.exceptions.RequestValidationError: [{'type': 'int_parsing', 'loc': ('path', 'sensor_id'), 'msg': 'Input should be a valid integer, unable to parse string as an integer', 'input': 'undefined', 'url': 'https://errors.pydantic.dev/2.5/v/int_parsing'}]

During handling of the above exception, another exception occurred:

Traceback (most recent call last):
  File "C:\Users\nicol\AppData\Local\Packages\PythonSoftwareFoundation.Python.3.12_qbz5n2kfra8p0\LocalCache\local-packages\Python312\site-packages\starlette\middleware\errors.py", line 162, in __call__
    await self.app(scope, receive, _send)
  File "C:\Users\nicol\AppData\Local\Packages\PythonSoftwareFoundation.Python.3.12_qbz5n2kfra8p0\LocalCache\local-packages\Python312\site-packages\starlette\middleware\cors.py", line 91, in __call__
    await self.simple_response(scope, receive, send, request_headers=headers)
  File "C:\Users\nicol\AppData\Local\Packages\PythonSoftwareFoundation.Python.3.12_qbz5n2kfra8p0\LocalCache\local-packages\Python312\site-packages\starlette\middleware\cors.py", line 146, in simple_response
    await self.app(scope, receive, send)
  File "C:\Users\nicol\AppData\Local\Packages\PythonSoftwareFoundation.Python.3.12_qbz5n2kfra8p0\LocalCache\local-packages\Python312\site-packages\starlette\middleware\exceptions.py", line 88, in __call__
    response = await handler(request, exc)
               ^^^^^^^^^^^^^^^^^^^^^^^^^^^
  File "C:\Users\nicol\Documentos\GitHub\PdM-Manager\app\error_handlers.py", line 35, in validation_exception_handler
    content=create_response(
            ^^^^^^^^^^^^^^^^
TypeError: create_response() got an unexpected keyword argument 'error'

[2025-04-04 18:18:43] [ERROR] [logger:63] - ERROR: [{'type': 'int_parsing', 'loc': ('path', 'sensor_id'), 'msg': 'Input should be a valid integer, unable to parse string as an integer', 'input': 'undefined', 'url': 'https://errors.pydantic.dev/2.5/v/int_parsing'}]
CONTEXTO: {'endpoint': '/api/sensors/undefined', 'método': 'DELETE', 'errores': [{'type': 'int_parsing', 'loc': ('path', 'sensor_id'), 'msg': 'Input should be a valid integer, unable to parse string as an integer', 'input': 'undefined', 'url': 'https://errors.pydantic.dev/2.5/v/int_parsing'}]}
TRACEBACK: Traceback (most recent call last):
  File "C:\Users\nicol\AppData\Local\Packages\PythonSoftwareFoundation.Python.3.12_qbz5n2kfra8p0\LocalCache\local-packages\Python312\site-packages\starlette\middleware\exceptions.py", line 68, in __call__
    await self.app(scope, receive, sender)
  File "C:\Users\nicol\AppData\Local\Packages\PythonSoftwareFoundation.Python.3.12_qbz5n2kfra8p0\LocalCache\local-packages\Python312\site-packages\fastapi\middleware\asyncexitstack.py", line 20, in __call__
    raise e
  File "C:\Users\nicol\AppData\Local\Packages\PythonSoftwareFoundation.Python.3.12_qbz5n2kfra8p0\LocalCache\local-packages\Python312\site-packages\fastapi\middleware\asyncexitstack.py", line 17, in __call__
    await self.app(scope, receive, send)
  File "C:\Users\nicol\AppData\Local\Packages\PythonSoftwareFoundation.Python.3.12_qbz5n2kfra8p0\LocalCache\local-packages\Python312\site-packages\starlette\routing.py", line 718, in __call__
    await route.handle(scope, receive, send)
  File "C:\Users\nicol\AppData\Local\Packages\PythonSoftwareFoundation.Python.3.12_qbz5n2kfra8p0\LocalCache\local-packages\Python312\site-packages\starlette\routing.py", line 276, in handle
    await self.app(scope, receive, send)
  File "C:\Users\nicol\AppData\Local\Packages\PythonSoftwareFoundation.Python.3.12_qbz5n2kfra8p0\LocalCache\local-packages\Python312\site-packages\starlette\routing.py", line 66, in app
    response = await func(request)
               ^^^^^^^^^^^^^^^^^^^
  File "C:\Users\nicol\AppData\Local\Packages\PythonSoftwareFoundation.Python.3.12_qbz5n2kfra8p0\LocalCache\local-packages\Python312\site-packages\fastapi\routing.py", line 272, in app
    raise RequestValidationError(_normalize_errors(errors), body=body)
fastapi.exceptions.RequestValidationError: [{'type': 'int_parsing', 'loc': ('path', 'sensor_id'), 'msg': 'Input should be a valid integer, unable to parse string as an integer', 'input': 'undefined', 'url': 'https://errors.pydantic.dev/2.5/v/int_parsing'}]

[2025-04-04 18:18:43] [ERROR] [logger:63] - ERROR: create_response() got an unexpected keyword argument 'error'
CONTEXTO: {'endpoint': '/api/sensors/undefined', 'método': 'DELETE', 'query_params': '', 'client': '127.0.0.1'}
TRACEBACK: Traceback (most recent call last):
  File "C:\Users\nicol\AppData\Local\Packages\PythonSoftwareFoundation.Python.3.12_qbz5n2kfra8p0\LocalCache\local-packages\Python312\site-packages\starlette\middleware\exceptions.py", line 68, in __call__
    await self.app(scope, receive, sender)
  File "C:\Users\nicol\AppData\Local\Packages\PythonSoftwareFoundation.Python.3.12_qbz5n2kfra8p0\LocalCache\local-packages\Python312\site-packages\fastapi\middleware\asyncexitstack.py", line 20, in __call__
    raise e
  File "C:\Users\nicol\AppData\Local\Packages\PythonSoftwareFoundation.Python.3.12_qbz5n2kfra8p0\LocalCache\local-packages\Python312\site-packages\fastapi\middleware\asyncexitstack.py", line 17, in __call__
    await self.app(scope, receive, send)
  File "C:\Users\nicol\AppData\Local\Packages\PythonSoftwareFoundation.Python.3.12_qbz5n2kfra8p0\LocalCache\local-packages\Python312\site-packages\starlette\routing.py", line 718, in __call__
    await route.handle(scope, receive, send)
  File "C:\Users\nicol\AppData\Local\Packages\PythonSoftwareFoundation.Python.3.12_qbz5n2kfra8p0\LocalCache\local-packages\Python312\site-packages\starlette\routing.py", line 276, in handle
    await self.app(scope, receive, send)
  File "C:\Users\nicol\AppData\Local\Packages\PythonSoftwareFoundation.Python.3.12_qbz5n2kfra8p0\LocalCache\local-packages\Python312\site-packages\starlette\routing.py", line 66, in app
    response = await func(request)
               ^^^^^^^^^^^^^^^^^^^
  File "C:\Users\nicol\AppData\Local\Packages\PythonSoftwareFoundation.Python.3.12_qbz5n2kfra8p0\LocalCache\local-packages\Python312\site-packages\fastapi\routing.py", line 272, in app
    raise RequestValidationError(_normalize_errors(errors), body=body)
fastapi.exceptions.RequestValidationError: [{'type': 'int_parsing', 'loc': ('path', 'sensor_id'), 'msg': 'Input should be a valid integer, unable to parse string as an integer', 'input': 'undefined', 'url': 'https://errors.pydantic.dev/2.5/v/int_parsing'}]

During handling of the above exception, another exception occurred:

Traceback (most recent call last):
  File "C:\Users\nicol\AppData\Local\Packages\PythonSoftwareFoundation.Python.3.12_qbz5n2kfra8p0\LocalCache\local-packages\Python312\site-packages\starlette\middleware\errors.py", line 162, in __call__
    await self.app(scope, receive, _send)
  File "C:\Users\nicol\AppData\Local\Packages\PythonSoftwareFoundation.Python.3.12_qbz5n2kfra8p0\LocalCache\local-packages\Python312\site-packages\starlette\middleware\cors.py", line 91, in __call__
    await self.simple_response(scope, receive, send, request_headers=headers)
  File "C:\Users\nicol\AppData\Local\Packages\PythonSoftwareFoundation.Python.3.12_qbz5n2kfra8p0\LocalCache\local-packages\Python312\site-packages\starlette\middleware\cors.py", line 146, in simple_response
    await self.app(scope, receive, send)
  File "C:\Users\nicol\AppData\Local\Packages\PythonSoftwareFoundation.Python.3.12_qbz5n2kfra8p0\LocalCache\local-packages\Python312\site-packages\starlette\middleware\exceptions.py", line 88, in __call__
    response = await handler(request, exc)
               ^^^^^^^^^^^^^^^^^^^^^^^^^^^
  File "C:\Users\nicol\Documentos\GitHub\PdM-Manager\app\error_handlers.py", line 35, in validation_exception_handler
    content=create_response(
            ^^^^^^^^^^^^^^^^
TypeError: create_response() got an unexpected keyword argument 'error'

[2025-04-04 18:18:45] [ERROR] [logger:63] - ERROR: [{'type': 'int_parsing', 'loc': ('path', 'sensor_id'), 'msg': 'Input should be a valid integer, unable to parse string as an integer', 'input': 'undefined', 'url': 'https://errors.pydantic.dev/2.5/v/int_parsing'}]
CONTEXTO: {'endpoint': '/api/sensors/undefined', 'método': 'DELETE', 'errores': [{'type': 'int_parsing', 'loc': ('path', 'sensor_id'), 'msg': 'Input should be a valid integer, unable to parse string as an integer', 'input': 'undefined', 'url': 'https://errors.pydantic.dev/2.5/v/int_parsing'}]}
TRACEBACK: Traceback (most recent call last):
  File "C:\Users\nicol\AppData\Local\Packages\PythonSoftwareFoundation.Python.3.12_qbz5n2kfra8p0\LocalCache\local-packages\Python312\site-packages\starlette\middleware\exceptions.py", line 68, in __call__
    await self.app(scope, receive, sender)
  File "C:\Users\nicol\AppData\Local\Packages\PythonSoftwareFoundation.Python.3.12_qbz5n2kfra8p0\LocalCache\local-packages\Python312\site-packages\fastapi\middleware\asyncexitstack.py", line 20, in __call__
    raise e
  File "C:\Users\nicol\AppData\Local\Packages\PythonSoftwareFoundation.Python.3.12_qbz5n2kfra8p0\LocalCache\local-packages\Python312\site-packages\fastapi\middleware\asyncexitstack.py", line 17, in __call__
    await self.app(scope, receive, send)
  File "C:\Users\nicol\AppData\Local\Packages\PythonSoftwareFoundation.Python.3.12_qbz5n2kfra8p0\LocalCache\local-packages\Python312\site-packages\starlette\routing.py", line 718, in __call__
    await route.handle(scope, receive, send)
  File "C:\Users\nicol\AppData\Local\Packages\PythonSoftwareFoundation.Python.3.12_qbz5n2kfra8p0\LocalCache\local-packages\Python312\site-packages\starlette\routing.py", line 276, in handle
    await self.app(scope, receive, send)
  File "C:\Users\nicol\AppData\Local\Packages\PythonSoftwareFoundation.Python.3.12_qbz5n2kfra8p0\LocalCache\local-packages\Python312\site-packages\starlette\routing.py", line 66, in app
    response = await func(request)
               ^^^^^^^^^^^^^^^^^^^
  File "C:\Users\nicol\AppData\Local\Packages\PythonSoftwareFoundation.Python.3.12_qbz5n2kfra8p0\LocalCache\local-packages\Python312\site-packages\fastapi\routing.py", line 272, in app
    raise RequestValidationError(_normalize_errors(errors), body=body)
fastapi.exceptions.RequestValidationError: [{'type': 'int_parsing', 'loc': ('path', 'sensor_id'), 'msg': 'Input should be a valid integer, unable to parse string as an integer', 'input': 'undefined', 'url': 'https://errors.pydantic.dev/2.5/v/int_parsing'}]

[2025-04-04 18:18:45] [ERROR] [logger:63] - ERROR: create_response() got an unexpected keyword argument 'error'
CONTEXTO: {'endpoint': '/api/sensors/undefined', 'método': 'DELETE', 'query_params': '', 'client': '127.0.0.1'}
TRACEBACK: Traceback (most recent call last):
  File "C:\Users\nicol\AppData\Local\Packages\PythonSoftwareFoundation.Python.3.12_qbz5n2kfra8p0\LocalCache\local-packages\Python312\site-packages\starlette\middleware\exceptions.py", line 68, in __call__
    await self.app(scope, receive, sender)
  File "C:\Users\nicol\AppData\Local\Packages\PythonSoftwareFoundation.Python.3.12_qbz5n2kfra8p0\LocalCache\local-packages\Python312\site-packages\fastapi\middleware\asyncexitstack.py", line 20, in __call__
    raise e
  File "C:\Users\nicol\AppData\Local\Packages\PythonSoftwareFoundation.Python.3.12_qbz5n2kfra8p0\LocalCache\local-packages\Python312\site-packages\fastapi\middleware\asyncexitstack.py", line 17, in __call__
    await self.app(scope, receive, send)
  File "C:\Users\nicol\AppData\Local\Packages\PythonSoftwareFoundation.Python.3.12_qbz5n2kfra8p0\LocalCache\local-packages\Python312\site-packages\starlette\routing.py", line 718, in __call__
    await route.handle(scope, receive, send)
  File "C:\Users\nicol\AppData\Local\Packages\PythonSoftwareFoundation.Python.3.12_qbz5n2kfra8p0\LocalCache\local-packages\Python312\site-packages\starlette\routing.py", line 276, in handle
    await self.app(scope, receive, send)
  File "C:\Users\nicol\AppData\Local\Packages\PythonSoftwareFoundation.Python.3.12_qbz5n2kfra8p0\LocalCache\local-packages\Python312\site-packages\starlette\routing.py", line 66, in app
    response = await func(request)
               ^^^^^^^^^^^^^^^^^^^
  File "C:\Users\nicol\AppData\Local\Packages\PythonSoftwareFoundation.Python.3.12_qbz5n2kfra8p0\LocalCache\local-packages\Python312\site-packages\fastapi\routing.py", line 272, in app
    raise RequestValidationError(_normalize_errors(errors), body=body)
fastapi.exceptions.RequestValidationError: [{'type': 'int_parsing', 'loc': ('path', 'sensor_id'), 'msg': 'Input should be a valid integer, unable to parse string as an integer', 'input': 'undefined', 'url': 'https://errors.pydantic.dev/2.5/v/int_parsing'}]

During handling of the above exception, another exception occurred:

Traceback (most recent call last):
  File "C:\Users\nicol\AppData\Local\Packages\PythonSoftwareFoundation.Python.3.12_qbz5n2kfra8p0\LocalCache\local-packages\Python312\site-packages\starlette\middleware\errors.py", line 162, in __call__
    await self.app(scope, receive, _send)
  File "C:\Users\nicol\AppData\Local\Packages\PythonSoftwareFoundation.Python.3.12_qbz5n2kfra8p0\LocalCache\local-packages\Python312\site-packages\starlette\middleware\cors.py", line 91, in __call__
    await self.simple_response(scope, receive, send, request_headers=headers)
  File "C:\Users\nicol\AppData\Local\Packages\PythonSoftwareFoundation.Python.3.12_qbz5n2kfra8p0\LocalCache\local-packages\Python312\site-packages\starlette\middleware\cors.py", line 146, in simple_response
    await self.app(scope, receive, send)
  File "C:\Users\nicol\AppData\Local\Packages\PythonSoftwareFoundation.Python.3.12_qbz5n2kfra8p0\LocalCache\local-packages\Python312\site-packages\starlette\middleware\exceptions.py", line 88, in __call__
    response = await handler(request, exc)
               ^^^^^^^^^^^^^^^^^^^^^^^^^^^
  File "C:\Users\nicol\Documentos\GitHub\PdM-Manager\app\error_handlers.py", line 35, in validation_exception_handler
    content=create_response(
            ^^^^^^^^^^^^^^^^
TypeError: create_response() got an unexpected keyword argument 'error'

[2025-04-04 18:22:47] [INFO] [logger:78] - Archivo de modelo guardado en: C:\Users\nicol\Documentos\GitHub\PdM-Manager\Modelo\modeloRNN_multiclase_v3_finetuned_7025d4a5.h5
[2025-04-04 18:22:47] [INFO] [logger:78] - Archivo de escalador guardado en: C:\Users\nicol\Documentos\GitHub\PdM-Manager\Scaler\scaler_RNN_joblib_303f7396.pkl
[2025-04-04 18:40:00] [INFO] [logger:78] - Archivo de modelo guardado en: C:\Users\nicol\Documentos\GitHub\PdM-Manager\Modelo\modeloRNN_multiclase_v3_finetuned_7025d4a5.h5
[2025-04-04 18:40:00] [INFO] [logger:78] - Archivo de escalador guardado en: C:\Users\nicol\Documentos\GitHub\PdM-Manager\Scaler\scaler_RNN_joblib_303f7396.pkl
[2025-04-04 18:54:17] [ERROR] [logger:63] - ERROR: [{'type': 'int_parsing', 'loc': ('path', 'sensor_id'), 'msg': 'Input should be a valid integer, unable to parse string as an integer', 'input': 'undefined', 'url': 'https://errors.pydantic.dev/2.5/v/int_parsing'}]
CONTEXTO: {'endpoint': '/api/sensors/undefined', 'método': 'DELETE', 'errores': [{'type': 'int_parsing', 'loc': ('path', 'sensor_id'), 'msg': 'Input should be a valid integer, unable to parse string as an integer', 'input': 'undefined', 'url': 'https://errors.pydantic.dev/2.5/v/int_parsing'}]}
TRACEBACK: Traceback (most recent call last):
  File "C:\Users\nicol\Documentos\GitHub\PdM-Manager\venv\Lib\site-packages\starlette\middleware\exceptions.py", line 68, in __call__
    await self.app(scope, receive, sender)
  File "C:\Users\nicol\Documentos\GitHub\PdM-Manager\venv\Lib\site-packages\fastapi\middleware\asyncexitstack.py", line 20, in __call__
    raise e
  File "C:\Users\nicol\Documentos\GitHub\PdM-Manager\venv\Lib\site-packages\fastapi\middleware\asyncexitstack.py", line 17, in __call__
    await self.app(scope, receive, send)
  File "C:\Users\nicol\Documentos\GitHub\PdM-Manager\venv\Lib\site-packages\starlette\routing.py", line 718, in __call__
    await route.handle(scope, receive, send)
  File "C:\Users\nicol\Documentos\GitHub\PdM-Manager\venv\Lib\site-packages\starlette\routing.py", line 276, in handle
    await self.app(scope, receive, send)
  File "C:\Users\nicol\Documentos\GitHub\PdM-Manager\venv\Lib\site-packages\starlette\routing.py", line 66, in app
    response = await func(request)
               ^^^^^^^^^^^^^^^^^^^
  File "C:\Users\nicol\Documentos\GitHub\PdM-Manager\venv\Lib\site-packages\fastapi\routing.py", line 272, in app
    raise RequestValidationError(_normalize_errors(errors), body=body)
fastapi.exceptions.RequestValidationError: [{'type': 'int_parsing', 'loc': ('path', 'sensor_id'), 'msg': 'Input should be a valid integer, unable to parse string as an integer', 'input': 'undefined', 'url': 'https://errors.pydantic.dev/2.5/v/int_parsing'}]

[2025-04-04 18:54:19] [ERROR] [logger:63] - ERROR: [{'type': 'int_parsing', 'loc': ('path', 'sensor_id'), 'msg': 'Input should be a valid integer, unable to parse string as an integer', 'input': 'undefined', 'url': 'https://errors.pydantic.dev/2.5/v/int_parsing'}]
CONTEXTO: {'endpoint': '/api/sensors/undefined', 'método': 'DELETE', 'errores': [{'type': 'int_parsing', 'loc': ('path', 'sensor_id'), 'msg': 'Input should be a valid integer, unable to parse string as an integer', 'input': 'undefined', 'url': 'https://errors.pydantic.dev/2.5/v/int_parsing'}]}
TRACEBACK: Traceback (most recent call last):
  File "C:\Users\nicol\Documentos\GitHub\PdM-Manager\venv\Lib\site-packages\starlette\middleware\exceptions.py", line 68, in __call__
    await self.app(scope, receive, sender)
  File "C:\Users\nicol\Documentos\GitHub\PdM-Manager\venv\Lib\site-packages\fastapi\middleware\asyncexitstack.py", line 20, in __call__
    raise e
  File "C:\Users\nicol\Documentos\GitHub\PdM-Manager\venv\Lib\site-packages\fastapi\middleware\asyncexitstack.py", line 17, in __call__
    await self.app(scope, receive, send)
  File "C:\Users\nicol\Documentos\GitHub\PdM-Manager\venv\Lib\site-packages\starlette\routing.py", line 718, in __call__
    await route.handle(scope, receive, send)
  File "C:\Users\nicol\Documentos\GitHub\PdM-Manager\venv\Lib\site-packages\starlette\routing.py", line 276, in handle
    await self.app(scope, receive, send)
  File "C:\Users\nicol\Documentos\GitHub\PdM-Manager\venv\Lib\site-packages\starlette\routing.py", line 66, in app
    response = await func(request)
               ^^^^^^^^^^^^^^^^^^^
  File "C:\Users\nicol\Documentos\GitHub\PdM-Manager\venv\Lib\site-packages\fastapi\routing.py", line 272, in app
    raise RequestValidationError(_normalize_errors(errors), body=body)
fastapi.exceptions.RequestValidationError: [{'type': 'int_parsing', 'loc': ('path', 'sensor_id'), 'msg': 'Input should be a valid integer, unable to parse string as an integer', 'input': 'undefined', 'url': 'https://errors.pydantic.dev/2.5/v/int_parsing'}]

[2025-04-04 18:54:21] [ERROR] [logger:63] - ERROR: [{'type': 'int_parsing', 'loc': ('path', 'sensor_id'), 'msg': 'Input should be a valid integer, unable to parse string as an integer', 'input': 'undefined', 'url': 'https://errors.pydantic.dev/2.5/v/int_parsing'}]
CONTEXTO: {'endpoint': '/api/sensors/undefined', 'método': 'DELETE', 'errores': [{'type': 'int_parsing', 'loc': ('path', 'sensor_id'), 'msg': 'Input should be a valid integer, unable to parse string as an integer', 'input': 'undefined', 'url': 'https://errors.pydantic.dev/2.5/v/int_parsing'}]}
TRACEBACK: Traceback (most recent call last):
  File "C:\Users\nicol\Documentos\GitHub\PdM-Manager\venv\Lib\site-packages\starlette\middleware\exceptions.py", line 68, in __call__
    await self.app(scope, receive, sender)
  File "C:\Users\nicol\Documentos\GitHub\PdM-Manager\venv\Lib\site-packages\fastapi\middleware\asyncexitstack.py", line 20, in __call__
    raise e
  File "C:\Users\nicol\Documentos\GitHub\PdM-Manager\venv\Lib\site-packages\fastapi\middleware\asyncexitstack.py", line 17, in __call__
    await self.app(scope, receive, send)
  File "C:\Users\nicol\Documentos\GitHub\PdM-Manager\venv\Lib\site-packages\starlette\routing.py", line 718, in __call__
    await route.handle(scope, receive, send)
  File "C:\Users\nicol\Documentos\GitHub\PdM-Manager\venv\Lib\site-packages\starlette\routing.py", line 276, in handle
    await self.app(scope, receive, send)
  File "C:\Users\nicol\Documentos\GitHub\PdM-Manager\venv\Lib\site-packages\starlette\routing.py", line 66, in app
    response = await func(request)
               ^^^^^^^^^^^^^^^^^^^
  File "C:\Users\nicol\Documentos\GitHub\PdM-Manager\venv\Lib\site-packages\fastapi\routing.py", line 272, in app
    raise RequestValidationError(_normalize_errors(errors), body=body)
fastapi.exceptions.RequestValidationError: [{'type': 'int_parsing', 'loc': ('path', 'sensor_id'), 'msg': 'Input should be a valid integer, unable to parse string as an integer', 'input': 'undefined', 'url': 'https://errors.pydantic.dev/2.5/v/int_parsing'}]

[2025-04-04 18:54:24] [ERROR] [logger:63] - ERROR: [{'type': 'int_parsing', 'loc': ('path', 'sensor_id'), 'msg': 'Input should be a valid integer, unable to parse string as an integer', 'input': 'undefined', 'url': 'https://errors.pydantic.dev/2.5/v/int_parsing'}]
CONTEXTO: {'endpoint': '/api/sensors/undefined', 'método': 'DELETE', 'errores': [{'type': 'int_parsing', 'loc': ('path', 'sensor_id'), 'msg': 'Input should be a valid integer, unable to parse string as an integer', 'input': 'undefined', 'url': 'https://errors.pydantic.dev/2.5/v/int_parsing'}]}
TRACEBACK: Traceback (most recent call last):
  File "C:\Users\nicol\Documentos\GitHub\PdM-Manager\venv\Lib\site-packages\starlette\middleware\exceptions.py", line 68, in __call__
    await self.app(scope, receive, sender)
  File "C:\Users\nicol\Documentos\GitHub\PdM-Manager\venv\Lib\site-packages\fastapi\middleware\asyncexitstack.py", line 20, in __call__
    raise e
  File "C:\Users\nicol\Documentos\GitHub\PdM-Manager\venv\Lib\site-packages\fastapi\middleware\asyncexitstack.py", line 17, in __call__
    await self.app(scope, receive, send)
  File "C:\Users\nicol\Documentos\GitHub\PdM-Manager\venv\Lib\site-packages\starlette\routing.py", line 718, in __call__
    await route.handle(scope, receive, send)
  File "C:\Users\nicol\Documentos\GitHub\PdM-Manager\venv\Lib\site-packages\starlette\routing.py", line 276, in handle
    await self.app(scope, receive, send)
  File "C:\Users\nicol\Documentos\GitHub\PdM-Manager\venv\Lib\site-packages\starlette\routing.py", line 66, in app
    response = await func(request)
               ^^^^^^^^^^^^^^^^^^^
  File "C:\Users\nicol\Documentos\GitHub\PdM-Manager\venv\Lib\site-packages\fastapi\routing.py", line 272, in app
    raise RequestValidationError(_normalize_errors(errors), body=body)
fastapi.exceptions.RequestValidationError: [{'type': 'int_parsing', 'loc': ('path', 'sensor_id'), 'msg': 'Input should be a valid integer, unable to parse string as an integer', 'input': 'undefined', 'url': 'https://errors.pydantic.dev/2.5/v/int_parsing'}]

[2025-04-04 18:54:25] [ERROR] [logger:63] - ERROR: [{'type': 'int_parsing', 'loc': ('path', 'sensor_id'), 'msg': 'Input should be a valid integer, unable to parse string as an integer', 'input': 'undefined', 'url': 'https://errors.pydantic.dev/2.5/v/int_parsing'}]
CONTEXTO: {'endpoint': '/api/sensors/undefined', 'método': 'GET', 'errores': [{'type': 'int_parsing', 'loc': ('path', 'sensor_id'), 'msg': 'Input should be a valid integer, unable to parse string as an integer', 'input': 'undefined', 'url': 'https://errors.pydantic.dev/2.5/v/int_parsing'}]}
TRACEBACK: Traceback (most recent call last):
  File "C:\Users\nicol\Documentos\GitHub\PdM-Manager\venv\Lib\site-packages\starlette\middleware\exceptions.py", line 68, in __call__
    await self.app(scope, receive, sender)
  File "C:\Users\nicol\Documentos\GitHub\PdM-Manager\venv\Lib\site-packages\fastapi\middleware\asyncexitstack.py", line 20, in __call__
    raise e
  File "C:\Users\nicol\Documentos\GitHub\PdM-Manager\venv\Lib\site-packages\fastapi\middleware\asyncexitstack.py", line 17, in __call__
    await self.app(scope, receive, send)
  File "C:\Users\nicol\Documentos\GitHub\PdM-Manager\venv\Lib\site-packages\starlette\routing.py", line 718, in __call__
    await route.handle(scope, receive, send)
  File "C:\Users\nicol\Documentos\GitHub\PdM-Manager\venv\Lib\site-packages\starlette\routing.py", line 276, in handle
    await self.app(scope, receive, send)
  File "C:\Users\nicol\Documentos\GitHub\PdM-Manager\venv\Lib\site-packages\starlette\routing.py", line 66, in app
    response = await func(request)
               ^^^^^^^^^^^^^^^^^^^
  File "C:\Users\nicol\Documentos\GitHub\PdM-Manager\venv\Lib\site-packages\fastapi\routing.py", line 272, in app
    raise RequestValidationError(_normalize_errors(errors), body=body)
fastapi.exceptions.RequestValidationError: [{'type': 'int_parsing', 'loc': ('path', 'sensor_id'), 'msg': 'Input should be a valid integer, unable to parse string as an integer', 'input': 'undefined', 'url': 'https://errors.pydantic.dev/2.5/v/int_parsing'}]

[2025-04-04 18:54:26] [ERROR] [logger:63] - ERROR: [{'type': 'int_parsing', 'loc': ('path', 'sensor_id'), 'msg': 'Input should be a valid integer, unable to parse string as an integer', 'input': 'undefined', 'url': 'https://errors.pydantic.dev/2.5/v/int_parsing'}]
CONTEXTO: {'endpoint': '/api/sensors/undefined', 'método': 'GET', 'errores': [{'type': 'int_parsing', 'loc': ('path', 'sensor_id'), 'msg': 'Input should be a valid integer, unable to parse string as an integer', 'input': 'undefined', 'url': 'https://errors.pydantic.dev/2.5/v/int_parsing'}]}
TRACEBACK: Traceback (most recent call last):
  File "C:\Users\nicol\Documentos\GitHub\PdM-Manager\venv\Lib\site-packages\starlette\middleware\exceptions.py", line 68, in __call__
    await self.app(scope, receive, sender)
  File "C:\Users\nicol\Documentos\GitHub\PdM-Manager\venv\Lib\site-packages\fastapi\middleware\asyncexitstack.py", line 20, in __call__
    raise e
  File "C:\Users\nicol\Documentos\GitHub\PdM-Manager\venv\Lib\site-packages\fastapi\middleware\asyncexitstack.py", line 17, in __call__
    await self.app(scope, receive, send)
  File "C:\Users\nicol\Documentos\GitHub\PdM-Manager\venv\Lib\site-packages\starlette\routing.py", line 718, in __call__
    await route.handle(scope, receive, send)
  File "C:\Users\nicol\Documentos\GitHub\PdM-Manager\venv\Lib\site-packages\starlette\routing.py", line 276, in handle
    await self.app(scope, receive, send)
  File "C:\Users\nicol\Documentos\GitHub\PdM-Manager\venv\Lib\site-packages\starlette\routing.py", line 66, in app
    response = await func(request)
               ^^^^^^^^^^^^^^^^^^^
  File "C:\Users\nicol\Documentos\GitHub\PdM-Manager\venv\Lib\site-packages\fastapi\routing.py", line 272, in app
    raise RequestValidationError(_normalize_errors(errors), body=body)
fastapi.exceptions.RequestValidationError: [{'type': 'int_parsing', 'loc': ('path', 'sensor_id'), 'msg': 'Input should be a valid integer, unable to parse string as an integer', 'input': 'undefined', 'url': 'https://errors.pydantic.dev/2.5/v/int_parsing'}]

[2025-04-04 18:54:26] [ERROR] [logger:63] - ERROR: [{'type': 'int_parsing', 'loc': ('path', 'sensor_id'), 'msg': 'Input should be a valid integer, unable to parse string as an integer', 'input': 'undefined', 'url': 'https://errors.pydantic.dev/2.5/v/int_parsing'}]
CONTEXTO: {'endpoint': '/api/sensors/undefined', 'método': 'GET', 'errores': [{'type': 'int_parsing', 'loc': ('path', 'sensor_id'), 'msg': 'Input should be a valid integer, unable to parse string as an integer', 'input': 'undefined', 'url': 'https://errors.pydantic.dev/2.5/v/int_parsing'}]}
TRACEBACK: Traceback (most recent call last):
  File "C:\Users\nicol\Documentos\GitHub\PdM-Manager\venv\Lib\site-packages\starlette\middleware\exceptions.py", line 68, in __call__
    await self.app(scope, receive, sender)
  File "C:\Users\nicol\Documentos\GitHub\PdM-Manager\venv\Lib\site-packages\fastapi\middleware\asyncexitstack.py", line 20, in __call__
    raise e
  File "C:\Users\nicol\Documentos\GitHub\PdM-Manager\venv\Lib\site-packages\fastapi\middleware\asyncexitstack.py", line 17, in __call__
    await self.app(scope, receive, send)
  File "C:\Users\nicol\Documentos\GitHub\PdM-Manager\venv\Lib\site-packages\starlette\routing.py", line 718, in __call__
    await route.handle(scope, receive, send)
  File "C:\Users\nicol\Documentos\GitHub\PdM-Manager\venv\Lib\site-packages\starlette\routing.py", line 276, in handle
    await self.app(scope, receive, send)
  File "C:\Users\nicol\Documentos\GitHub\PdM-Manager\venv\Lib\site-packages\starlette\routing.py", line 66, in app
    response = await func(request)
               ^^^^^^^^^^^^^^^^^^^
  File "C:\Users\nicol\Documentos\GitHub\PdM-Manager\venv\Lib\site-packages\fastapi\routing.py", line 272, in app
    raise RequestValidationError(_normalize_errors(errors), body=body)
fastapi.exceptions.RequestValidationError: [{'type': 'int_parsing', 'loc': ('path', 'sensor_id'), 'msg': 'Input should be a valid integer, unable to parse string as an integer', 'input': 'undefined', 'url': 'https://errors.pydantic.dev/2.5/v/int_parsing'}]

[2025-04-04 18:54:26] [ERROR] [logger:63] - ERROR: [{'type': 'int_parsing', 'loc': ('path', 'sensor_id'), 'msg': 'Input should be a valid integer, unable to parse string as an integer', 'input': 'undefined', 'url': 'https://errors.pydantic.dev/2.5/v/int_parsing'}]
CONTEXTO: {'endpoint': '/api/sensors/undefined', 'método': 'GET', 'errores': [{'type': 'int_parsing', 'loc': ('path', 'sensor_id'), 'msg': 'Input should be a valid integer, unable to parse string as an integer', 'input': 'undefined', 'url': 'https://errors.pydantic.dev/2.5/v/int_parsing'}]}
TRACEBACK: Traceback (most recent call last):
  File "C:\Users\nicol\Documentos\GitHub\PdM-Manager\venv\Lib\site-packages\starlette\middleware\exceptions.py", line 68, in __call__
    await self.app(scope, receive, sender)
  File "C:\Users\nicol\Documentos\GitHub\PdM-Manager\venv\Lib\site-packages\fastapi\middleware\asyncexitstack.py", line 20, in __call__
    raise e
  File "C:\Users\nicol\Documentos\GitHub\PdM-Manager\venv\Lib\site-packages\fastapi\middleware\asyncexitstack.py", line 17, in __call__
    await self.app(scope, receive, send)
  File "C:\Users\nicol\Documentos\GitHub\PdM-Manager\venv\Lib\site-packages\starlette\routing.py", line 718, in __call__
    await route.handle(scope, receive, send)
  File "C:\Users\nicol\Documentos\GitHub\PdM-Manager\venv\Lib\site-packages\starlette\routing.py", line 276, in handle
    await self.app(scope, receive, send)
  File "C:\Users\nicol\Documentos\GitHub\PdM-Manager\venv\Lib\site-packages\starlette\routing.py", line 66, in app
    response = await func(request)
               ^^^^^^^^^^^^^^^^^^^
  File "C:\Users\nicol\Documentos\GitHub\PdM-Manager\venv\Lib\site-packages\fastapi\routing.py", line 272, in app
    raise RequestValidationError(_normalize_errors(errors), body=body)
fastapi.exceptions.RequestValidationError: [{'type': 'int_parsing', 'loc': ('path', 'sensor_id'), 'msg': 'Input should be a valid integer, unable to parse string as an integer', 'input': 'undefined', 'url': 'https://errors.pydantic.dev/2.5/v/int_parsing'}]

[2025-04-04 18:54:26] [ERROR] [logger:63] - ERROR: [{'type': 'int_parsing', 'loc': ('path', 'sensor_id'), 'msg': 'Input should be a valid integer, unable to parse string as an integer', 'input': 'undefined', 'url': 'https://errors.pydantic.dev/2.5/v/int_parsing'}]
CONTEXTO: {'endpoint': '/api/sensors/undefined', 'método': 'GET', 'errores': [{'type': 'int_parsing', 'loc': ('path', 'sensor_id'), 'msg': 'Input should be a valid integer, unable to parse string as an integer', 'input': 'undefined', 'url': 'https://errors.pydantic.dev/2.5/v/int_parsing'}]}
TRACEBACK: Traceback (most recent call last):
  File "C:\Users\nicol\Documentos\GitHub\PdM-Manager\venv\Lib\site-packages\starlette\middleware\exceptions.py", line 68, in __call__
    await self.app(scope, receive, sender)
  File "C:\Users\nicol\Documentos\GitHub\PdM-Manager\venv\Lib\site-packages\fastapi\middleware\asyncexitstack.py", line 20, in __call__
    raise e
  File "C:\Users\nicol\Documentos\GitHub\PdM-Manager\venv\Lib\site-packages\fastapi\middleware\asyncexitstack.py", line 17, in __call__
    await self.app(scope, receive, send)
  File "C:\Users\nicol\Documentos\GitHub\PdM-Manager\venv\Lib\site-packages\starlette\routing.py", line 718, in __call__
    await route.handle(scope, receive, send)
  File "C:\Users\nicol\Documentos\GitHub\PdM-Manager\venv\Lib\site-packages\starlette\routing.py", line 276, in handle
    await self.app(scope, receive, send)
  File "C:\Users\nicol\Documentos\GitHub\PdM-Manager\venv\Lib\site-packages\starlette\routing.py", line 66, in app
    response = await func(request)
               ^^^^^^^^^^^^^^^^^^^
  File "C:\Users\nicol\Documentos\GitHub\PdM-Manager\venv\Lib\site-packages\fastapi\routing.py", line 272, in app
    raise RequestValidationError(_normalize_errors(errors), body=body)
fastapi.exceptions.RequestValidationError: [{'type': 'int_parsing', 'loc': ('path', 'sensor_id'), 'msg': 'Input should be a valid integer, unable to parse string as an integer', 'input': 'undefined', 'url': 'https://errors.pydantic.dev/2.5/v/int_parsing'}]

[2025-04-04 18:54:26] [ERROR] [logger:63] - ERROR: [{'type': 'int_parsing', 'loc': ('path', 'sensor_id'), 'msg': 'Input should be a valid integer, unable to parse string as an integer', 'input': 'undefined', 'url': 'https://errors.pydantic.dev/2.5/v/int_parsing'}]
CONTEXTO: {'endpoint': '/api/sensors/undefined', 'método': 'GET', 'errores': [{'type': 'int_parsing', 'loc': ('path', 'sensor_id'), 'msg': 'Input should be a valid integer, unable to parse string as an integer', 'input': 'undefined', 'url': 'https://errors.pydantic.dev/2.5/v/int_parsing'}]}
TRACEBACK: Traceback (most recent call last):
  File "C:\Users\nicol\Documentos\GitHub\PdM-Manager\venv\Lib\site-packages\starlette\middleware\exceptions.py", line 68, in __call__
    await self.app(scope, receive, sender)
  File "C:\Users\nicol\Documentos\GitHub\PdM-Manager\venv\Lib\site-packages\fastapi\middleware\asyncexitstack.py", line 20, in __call__
    raise e
  File "C:\Users\nicol\Documentos\GitHub\PdM-Manager\venv\Lib\site-packages\fastapi\middleware\asyncexitstack.py", line 17, in __call__
    await self.app(scope, receive, send)
  File "C:\Users\nicol\Documentos\GitHub\PdM-Manager\venv\Lib\site-packages\starlette\routing.py", line 718, in __call__
    await route.handle(scope, receive, send)
  File "C:\Users\nicol\Documentos\GitHub\PdM-Manager\venv\Lib\site-packages\starlette\routing.py", line 276, in handle
    await self.app(scope, receive, send)
  File "C:\Users\nicol\Documentos\GitHub\PdM-Manager\venv\Lib\site-packages\starlette\routing.py", line 66, in app
    response = await func(request)
               ^^^^^^^^^^^^^^^^^^^
  File "C:\Users\nicol\Documentos\GitHub\PdM-Manager\venv\Lib\site-packages\fastapi\routing.py", line 272, in app
    raise RequestValidationError(_normalize_errors(errors), body=body)
fastapi.exceptions.RequestValidationError: [{'type': 'int_parsing', 'loc': ('path', 'sensor_id'), 'msg': 'Input should be a valid integer, unable to parse string as an integer', 'input': 'undefined', 'url': 'https://errors.pydantic.dev/2.5/v/int_parsing'}]

[2025-04-04 18:54:27] [ERROR] [logger:63] - ERROR: [{'type': 'int_parsing', 'loc': ('path', 'sensor_id'), 'msg': 'Input should be a valid integer, unable to parse string as an integer', 'input': 'undefined', 'url': 'https://errors.pydantic.dev/2.5/v/int_parsing'}]
CONTEXTO: {'endpoint': '/api/sensors/undefined', 'método': 'GET', 'errores': [{'type': 'int_parsing', 'loc': ('path', 'sensor_id'), 'msg': 'Input should be a valid integer, unable to parse string as an integer', 'input': 'undefined', 'url': 'https://errors.pydantic.dev/2.5/v/int_parsing'}]}
TRACEBACK: Traceback (most recent call last):
  File "C:\Users\nicol\Documentos\GitHub\PdM-Manager\venv\Lib\site-packages\starlette\middleware\exceptions.py", line 68, in __call__
    await self.app(scope, receive, sender)
  File "C:\Users\nicol\Documentos\GitHub\PdM-Manager\venv\Lib\site-packages\fastapi\middleware\asyncexitstack.py", line 20, in __call__
    raise e
  File "C:\Users\nicol\Documentos\GitHub\PdM-Manager\venv\Lib\site-packages\fastapi\middleware\asyncexitstack.py", line 17, in __call__
    await self.app(scope, receive, send)
  File "C:\Users\nicol\Documentos\GitHub\PdM-Manager\venv\Lib\site-packages\starlette\routing.py", line 718, in __call__
    await route.handle(scope, receive, send)
  File "C:\Users\nicol\Documentos\GitHub\PdM-Manager\venv\Lib\site-packages\starlette\routing.py", line 276, in handle
    await self.app(scope, receive, send)
  File "C:\Users\nicol\Documentos\GitHub\PdM-Manager\venv\Lib\site-packages\starlette\routing.py", line 66, in app
    response = await func(request)
               ^^^^^^^^^^^^^^^^^^^
  File "C:\Users\nicol\Documentos\GitHub\PdM-Manager\venv\Lib\site-packages\fastapi\routing.py", line 272, in app
    raise RequestValidationError(_normalize_errors(errors), body=body)
fastapi.exceptions.RequestValidationError: [{'type': 'int_parsing', 'loc': ('path', 'sensor_id'), 'msg': 'Input should be a valid integer, unable to parse string as an integer', 'input': 'undefined', 'url': 'https://errors.pydantic.dev/2.5/v/int_parsing'}]

